Workbook

Sheet 说明与概览
A1: 智慧园区一期项目 · 功能需求与技术要求清单
A3: 序号 | B3: 内容板块 | C3: 说明 | D3: 对应工作表 / 章节 | E3: 小计 | F3: 标品 | G3: 二开
A4: 1 | B4: 项目定位 | C4: 以产业园（约60万㎡）为试点，补齐五大子系统、打通数据、预留集团化复制接口，构建统一可扩展的智慧园区运营底座 | D4: 本表 | E4: /
A5: 2 | B5: 智慧物流【重点】 | C5: 预约-进园-月台-卸货-出园全流程线上化，含车辆预约、排队叫号、入园、停靠引导、月台可视化、出园、评价、跨园区调度 | D5: 智慧物流功能清单 | E5: =智慧物流功能清单!K49 -> 330100 | F5: =智慧物流功能清单!D53 -> 35000 | G5: =智慧物流功能清单!D52 -> 295100
A6: 3 | B6: 智慧消防 | C6: 整合消火栓/喷淋/电气火灾等系统，构建安消一体平台，实现设施监测、火灾预警、应急联动、日常巡检 | D6: 智慧消防功能清单 | E6: =智慧消防功能清单!K32 -> 313500 | F6: =智慧消防功能清单!D35 -> 99000 | G6: =智慧消防功能清单!D34 -> 214500
A7: 4 | B7: 智慧安防 | C7: 部署AI视频分析与物联感知，实现行为识别、周界入侵、事件联动，升级视融平台 | D7: 智慧安防功能清单 | E7: =智慧安防功能清单!K29 -> 218200 | F7: =智慧安防功能清单!D32 -> 83000 | G7: =智慧安防功能清单!D31 -> 135200
A8: 5 | B8: 宿舍管理 | C8: 覆盖入住-调宿-退宿全流程，含房务、水电费、退宿、统计等模块 | D8: 宿舍管理功能清单 | E8: =宿舍管理功能清单!K23 -> 130700 | F8: =宿舍管理功能清单!D26 -> 54000 | G8: =宿舍管理功能清单!D25 -> 76700
A9: 6 | B9: 外协人员管理 | C9: 规范外协单位与人员的准入、作业、离场全流程，含费用测算、物业一体化、多渠道服务 | D9: 外协系统功能清单 | E9: =外协系统功能清单!K26 -> 310700 | F9: =外协系统功能清单!D29 -> 0 | G9: =外协系统功能清单!D28 -> 310700
A10: 7 | B10: 平台通用能力 | C10: 报表管理、系统管理、移动及多屏应用、系统数据范围、系统集成范围 | D10: 平台通用与集成 | E10: =平台通用与集成!K23 -> 93100 | F10: =平台通用与集成!D26 -> 32000 | G10: =平台通用与集成!D25 -> 61100
A11: 8 | B11: 关键技术要求 | C11: 稳定性、集成性、兼容性、实用性、先进性、性能、可扩展性、账号权限等8类 | D11: 关键技术要求 | E11: /
A12: 9 | B12: 安全与合规要求 | C12: 安全资质、口令、登录、加密、审计等18项 + 数据合规8项 | D12: 安全合规要求 | E12: /
A13: 10 | B13: 硬件需求 | C13: 智能视频监控、周界入侵、物联传感设备等硬件场景清单（附录五） | D13: 硬件需求汇总 | E13: /
A14: N | B14: 合计 | E14: =SUM(E4:E13) -> 1396300 | F14: =SUM(F5:F10) -> 303000 | G14: =SUM(G5:G10) -> 1093300

Sheet 智慧物流功能清单
A1: 智慧物流功能清单【项目重点】
A2: 序号 | B2: 二级模块 | C2: 功能点 | D2: 功能说明与要求 | E2: 二开/标品 | F2: 对接系统 | G2: 对接数据 | H2: 数量 | I2: 单位 | J2: 单价 | K2: 合价 | L2: 备注
A3: 1.4.3.1.1 车辆预约管理
A4: 1 | B4: 车辆预约管理 | C4: 在线预约入园 | D4: 支持司机通过 APP/PC/微信小程序端在线预约入园时段、送货厂房、卸货位等信息；系统自动关联(到货单)供应商或客户(送货单)；系统智能排期，自动确认预约。 | E4: 标品 | F4: SRM、WMS、TMS、车辆管理系统 | G4: 预约单、到货/送货单、供应商/客户、车辆及司机、货物、预约时段、厂房/卸货位 | H4: 1 | I4: 套 | J4: 5000 | K4: =H4*J4 -> 5000
A5: 2 | B5: 车辆预约管理 | C5: 内部代预约 | D5: 支持内部人员（如仓储、采购）代供应商司机或提货司机预约，填写车牌、货物、预计到达时间等信息，系统自动关联供应商或客户。 | E5: 二开 | F5: SRM、WMS、TMS、ERP | G5: 代预约申请、供应商/客户、车辆/司机、货物、预计到达时间、到货/送货单 | H5: 1300 | I5: 套 | J5: 7 | K5: =H5*J5 -> 9100 | L5: 二开：人\天单价1300
A6: 3 | B6: 车辆预约管理 | C6: 爽约补救机制 | D6: 对未按预约时段抵达的司机自动触发提醒；提供爽约原因分析（交通拥堵、操作失误、主观原因等）及补救方案（重新预约、释放月台、手动补签）。 | E6: 二开 | F6: WMS、TMS、iSungrow（钉钉）/短信平台 | G6: 预约单、实际到达时间、爽约标识/原因、月台释放/重新预约结果、提醒记录 | H6: 1300 | I6: 套 | J6: 7 | K6: =H6*J6 -> 9100 | L6: 二开：人\天单价1300
A7: 4 | B7: 车辆预约管理 | C7: 信息推送 | D7: 自动推送送货/提货厂房、卸货位/装货位、路线导航信息给司机，解决频次较少司机的路线困惑。 | E7: 标品 | F7: iSungrow（钉钉）/短信平台、地图/GIS服务 | G7: 送/提货厂房、装卸货位、行驶路线、司机联系方式、推送状态 | H7: 1 | I7: 套 | J7: 3000 | K7: =H7*J7 -> 3000
A8: 5 | B8: 车辆预约管理 | C8: 管理规定实时更新 | D8: 实时推送最新管理规定、安全须知至司机端，确保司机及时了解最新要求。 | E8: 标品 | F8: iSungrow（钉钉）/短信平台 | G8: 管理规定、安全须知、版本/生效时间、阅读确认、推送状态 | H8: 1 | I8: 套 | J8: 2000 | K8: =H8*J8 -> 2000
A9: 1.4.3.1.2 车辆排队叫号管理
A10: 6 | B10: 车辆排队叫号管理 | C10: 预约信息可视化 | D10: 实时展示预约车辆列表、预计等候时长、排队队列等。 | E10: 标品 | F10: WMS、TMS、车辆管理系统 | G10: 预约车辆清单、预约/到达时间、队列序号、预计等候时长、叫号状态 | H10: 1 | I10: 套 | J10: 3000 | K10: =H10*J10 -> 3000
A11: 7 | B11: 车辆排队叫号管理 | C11: 智能叫号服务 | D11: 支持按预约优先级、车辆类型自动或手动叫号，减少人工干预。 | E11: 二开 | F11: WMS、TMS、iSungrow（钉钉）/短信平台 | G11: 预约优先级、车辆类型、队列/叫号状态、叫号时间、通知状态 | H11: 1300 | I11: 套 | J11: 3 | K11: =H11*J11 -> 3900 | L11: 对接；二开：人\天单价1300
A12: 8 | B12: 车辆排队叫号管理 | C12: 紧急插队机制 | D12: 支持授权人员（调度主管、仓储收发管理员）对紧急生产物料、异常处理等场景设置插队任务；记录插队原因、审批人、插队时间；插队车辆自动置于队列最前，并通知后续车辆等待时间延长。 | E12: 二开 | F12: WMS、ERP、BPM、iSungrow（钉钉）/短信平台 | G12: 紧急插队任务、车辆/物料信息、插队原因、审批人/审批状态、队列变更、通知记录 | H12: 1300 | I12: 套 | J12: 7 | K12: =H12*J12 -> 9100 | L12: 二开：人\天单价1300
A13: 9 | B13: 车辆排队叫号管理 | C13: 等候状态提醒 | D13: 通过 APP/短信推送预计等候时长，避免司机长时间等待。 | E13: 标品 | F13: iSungrow（钉钉）/短信平台 | G13: 排队序号、预计等候时长、叫号状态、司机联系方式、推送状态 | H13: 1 | I13: 套 | J13: 2000 | K13: =H13*J13 -> 2000
A14: 1.4.3.1.3 车辆入园管理
A15: 10 | B15: 车辆入园管理 | C15: 入园效率提升 | D15: 通过黑白名单管理车辆权限与预约机制，实现无感通行；业务保留对司机手机信息安全的拍照贴标。 | E15: 二开 | F15: 车辆管理系统、道闸系统（红门）、达实门禁一卡通系统 | G15: 车辆黑白名单、预约状态、车牌/司机信息、入园核验结果、手机贴标照片、通行记录 | H15: 1300 | I15: 套 | J15: 4 | K15: =H15*J15 -> 5200 | L15: 二开：人\天单价1300
A16: 11 | B16: 车辆入园管理 | C16: 电子手续自动化 | D16: 系统自动办理电子登记、电子证件审核、电子卸货牌/装货牌发放，消除手工登记流程。 | E16: 二开 | F16: BPM、车辆管理系统、道闸系统（红门） | G16: 电子登记、证件信息/审核状态、电子卸货/装货牌、车辆/司机信息、办理状态 | H16: 1300 | I16: 套 | J16: 10 | K16: =H16*J16 -> 13000 | L16: 二开：人\天单价1300
A17: 12 | B17: 车辆入园管理 | C17: 入园信息同步 | D17: 自动将车辆信息同步至卸货位管理模块及其他系统，为后续调度提供基础。 | E17: 二开 | F17: WMS、TMS、车辆管理系统 | G17: 入园车辆/司机信息、预约状态、入园时间、装卸货位、调度状态 | H17: 1300 | I17: 套 | J17: 4 | K17: =H17*J17 -> 5200 | L17: 二开：人\天单价1300
A18: 1.4.3.1.4 车辆停靠引导
A19: 13 | B19: 车辆停靠引导 | C19: 园内路线引导可视 | D19: 提供车辆入园后的园内导航指引、最优月台分配。 | E19: 二开 | F19: 车辆管理系统、WMS、地图/GIS服务 | G19: 园区地图、道路/路线、车辆位置、月台位置/状态、最优月台分配结果 | H19: 1300 | I19: 套 | J19: 8 | K19: =H19*J19 -> 10400 | L19: 二开：人\天单价1300
A20: 14 | B20: 车辆停靠引导 | C20: 月台指引功能 | D20: 车辆通过道闸后，系统自动推送最优行驶路线至司机端，引导车辆准确到达指定月台（存在多月台装卸货情形）。 | E20: 标品 | F20: 道闸系统（红门）、车辆管理系统、WMS | G20: 道闸通行状态、车辆信息、最优路线、指定月台、推送/到达状态 | H20: 1 | I20: 套 | J20: 5000 | K20: =H20*J20 -> 5000
A21: 15 | B21: 车辆停靠引导 | C21: 智能调度信息发布 | D21: 自动推送卸货位/装货位状态、车辆调度信息至司机端。 | E21: 二开 | F21: WMS、TMS、iSungrow（钉钉）/短信平台 | G21: 卸/装货位状态、车辆调度任务、司机联系方式、推送状态 | H21: 1300 | I21: 套 | J21: 4 | K21: =H21*J21 -> 5200 | L21: 二开：人\天单价1300
A22: 1.4.3.1.5 月台可视化管理
A23: 16 | B23: 月台可视化管理 | C23: 卸货位状态实时监控 | D23: 实时显示各卸货位空满状态、占用时长、使用效率。 | E23: 标品 | F23: WMS、车辆管理系统 | G23: 卸货位/装货位状态、占用起止时间、占用时长、使用率、实时状态数据 | H23: 1 | I23: 套 | J23: 8000 | K23: =H23*J23 -> 8000
A24: 17 | B24: 月台可视化管理 | C24: 月台空满警告 | D24: 当月台长时间被占用（超过设定阈值）或出现异常占用时，系统自动向调度人员、仓储管理人员推送警告信息，支持人工介入处理。 | E24: 标品 | F24: WMS、车辆管理系统、iSungrow（钉钉）/短信平台 | G24: 月台状态、占用时长、异常占用标识、告警阈值、告警/处置记录 | H24: 1 | I24: 套 | J24: 7000 | K24: =H24*J24 -> 7000
A25: 18 | B25: 月台可视化管理 | C25: 智能分配与预锁定 | D25: 根据车辆类型、货物特性自动分配卸货位，支持预分配/锁定功能。 | E25: 二开 | F25: WMS、TMS、SRM | G25: 车辆类型、货物特性、预约时间、月台状态、预分配/锁定状态 | H25: 1300 | I25: 套 | J25: 9 | K25: =H25*J25 -> 11700 | L25: 二开：人\天单价1300
A26: 19 | B26: 月台可视化管理 | C26: 物料在途信息跟踪 （供应商来料） | D26: 关联 SRM 送货单，实时获取车内物料类型、数量、状态，准确掌握物料在途情况。 | E26: 二开 | F26: SRM | G26: 送货单、供应商、物料类型/数量、在途/到达状态、车辆信息 | H26: 1300 | I26: 套 | J26: 9 | K26: =H26*J26 -> 11700 | L26: 二开：人\天单价1300
A27: 20 | B27: 月台可视化管理 | C27: 发货单关联（发货车辆） | D27: 关联发货订单，实时获取待装货物信息，支持装车作业有序调度。 | E27: 二开 | F27: ERP、WMS、TMS | G27: 发货订单、订单明细、待装货物/数量、装车状态、车辆信息 | H27: 1300 | I27: 套 | J27: 6 | K27: =H27*J27 -> 7800 | L27: 二开：人\天单价1300
A28: 21 | B28: 月台可视化管理 | C28: 月台效率分析 | D28: 自动生成卸货位使用率、作业时长等数据，为装卸效率优化提供依据。 | E28: 二开 | F28: WMS、TMS、数据湖/BI平台 | G28: 月台作业状态、占用时长、车辆到离场/装卸时间、月台使用率、效率分析指标 | H28: 1300 | I28: 套 | J28: 7 | K28: =H28*J28 -> 9100 | L28: 二开：人\天单价1300
A29: 1.4.3.1.6 车辆出园管理
A30: 22 | B30: 车辆出园管理 | C30: 出园检查 | D30: 仓库端检查拍照，门岗处复核。 | E30: 二开 | F30: WMS、道闸系统（红门）、视频监控平台 | G30: 出库/装车确认、车辆/司机信息、检查照片、门岗复核结果、出园放行状态 | H30: 1300 | I30: 套 | J30: 4 | K30: =H30*J30 -> 5200 | L30: 二开：人\天单价1300
A31: 23 | B31: 车辆出园管理 | C31: 电子出门条联动 | D31: 依托电子出门条自动联动 EPO 系统，业务上保留车辆检查流程。 | E31: 二开 | F31: EPO系统、WMS、道闸系统（红门） | G31: 电子出门条、发货/放行单、车辆/货物信息、审批状态、出门证/门岗核验、放行结果 | H31: 1300 | I31: 套 | J31: 4 | K31: =H31*J31 -> 5200 | L31: 二开：人\天单价1300
A32: 24 | B32: 车辆出园管理 | C32: 违规记录闭环管理 | D32: 系统与车辆违规记录打通，实现：违规记录生成→推送司机/供应商→限期整改→未整改纳入黑名单→黑名单限制预约 的闭环管理。 | E32: 二开 | F32: 车辆管理系统、SRM、iSungrow（钉钉）/短信平台 | G32: 车辆违规记录、司机/供应商、整改期限/结果、黑名单状态、预约限制状态、通知记录 | H32: 1300 | I32: 套 | J32: 4 | K32: =H32*J32 -> 5200 | L32: 二开：人\天单价1300
A33: 25 | B33: 车辆出园管理 | C33: 出园信息自动推送 | D33: 自动推送车辆出园信息至调度系统及其他系统、园区管理人员。 | E33: 二开 | F33: TMS、WMS、iSungrow（钉钉）/短信平台 | G33: 出园时间/结果、车辆/司机、订单/调度任务、收发货完成状态、推送记录 | H33: 1300 | I33: 套 | J33: 3 | K33: =H33*J33 -> 3900 | L33: 二开：人\天单价1300
A34: 26 | B34: 车辆出园管理 | C34: 物流数据自动归档 | D34: 完成车辆出园后，系统自动归档车辆入园、停靠、卸货全流程数据。 | E34: 二开 | F34: WMS、TMS、数据湖 | G34: 预约、入园、排队叫号、月台、装卸、出园、评价等全流程记录及操作日志 | H34: 1300 | I34: 套 | J34: 3 | K34: =H34*J34 -> 3900 | L34: 二开：人\天单价1300
A35: 1.4.3.1.7 评价反馈
A36: 27 | B36: 评价反馈 | C36: 送货/提货即时评价 | D36: 送货或提货结束后，供应商/司机端弹窗进行本次服务评价，提供投诉渠道，快速收集单次作业问题线索。 | E36: 二开 | F36: SRM、iSungrow（钉钉）/短信平台 | G36: 服务评价、评分、投诉/反馈内容、订单/车辆/供应商/司机标识、处理状态 | H36: 1300 | I36: 套 | J36: 3 | K36: =H36*J36 -> 3900 | L36: 二开：人\天单价1300
A37: 28 | B37: 评价反馈 | C37: 仓储收货/发货异常登记 | D37: 收货端或发货端增加异常反馈，如司机不配合、货物破损等。 | E37: 二开 | F37: WMS、ERP、EPO系统 | G37: 收/发货异常、订单/物料/车辆、破损照片、责任人、处理结果 | H37: 1300 | I37: 套 | J37: 3 | K37: =H37*J37 -> 3900 | L37: 二开：人\天单价1300
A38: 29 | B38: 评价反馈 | C38: 供应商满意度调查 | D38: 支持管理员不定期下发服务调查问卷，由供应商对仓库阶段性服务质量多维度评分并电子留存，用于长期服务水平评估。 | E38: 二开 | F38: SRM、iSungrow（钉钉）/短信平台 | G38: 供应商、问卷/评价指标、评分、意见、调查时间、电子留档 | H38: 1300 | I38: 套 | J38: 3 | K38: =H38*J38 -> 3900 | L38: 二开：人\天单价1300
A39: 1.4.3.1.9 园区车辆调度管理（货车，涉及园区内部及跨园区转运）
A40: 30 | B40: 园区车辆调度管理 | C40: 调度申请 | D40: 用车部门在线提交用车申请，系统按业务规则自动匹配可用车辆或由调度人指派；车辆资源涉及外部供方（安徽交运、力之辉等）及自有车辆。自有车辆优先执行内部固定任务，空余才执行临时任务，固定任务需简化流程操作。 | E40: 二开 | F40: TMS、ERP、BPM、车辆管理系统 | G40: 用车申请、用车部门、货物重量/体积/类型、车辆资源、承运商、调度/指派结果 | H40: 1300 | I40: 套 | J40: 9 | K40: =H40*J40 -> 11700 | L40: 二开：人\天单价1300
...

Sheet 智慧消防功能清单
A1: 智慧消防功能清单
A2: 序号 | B2: 二级模块 | C2: 功能点 | D2: 功能说明与要求 | E2: 二开/标品 | F2: 对接系统 | G2: 对接数据 | H2: 数量 | I2: 单位 | J2: 单价 | K2: 合价 | L2: 备注
A3: 1.4.3.2.1 消防设施状态监测（检测准确率不低于95%）
A4: 1 | B4: 消防水系统 | C4: 水压/水位/水泵监测 | D4: 消防泵、稳压泵出水管后水压监测；消防水池、高位水箱水位监测；水泵启停/故障状态监测记录。 | E4: 标品 | F4: 消防水系统监控设备/消防主机（待现场确认） | G4: 消防泵/稳压泵状态、出水压力、水池/水箱水位、启停/故障告警、监测时间 | H4: 1 | I4: 套 | J4: 7000 | K4: =H4*J4 -> 7000
A5: 2 | B5: 消防水系统 | C5: 末端与报警阀监测 | D5: 消防系统末端压力监测；湿式/干式报警阀动作信号及前后压力监测（含系统侧与供水侧压力差事件提醒）；关键管路阀门启闭状态监测。 | E5: 标品 | F5: 消防水系统监控设备/消防主机（待现场确认） | G5: 末端压力、报警阀动作及前后压力、压力差告警、关键阀门启闭状态、监测时间 | H5: 1 | I5: 套 | J5: 7000 | K5: =H5*J5 -> 7000
A6: 3 | B6: 火灾报警监测 | C6: 火灾探测信息联网 | D6: 烟感、温感、手报联网监测；吸气式烟感、红外对射、感温光纤、可燃气体/氧气/粉尘探测等特有场所监测；红外热成像、视频火灾监控等新型报警器监测。 | E6: 标品 | F6: 火灾自动报警系统、视频监控平台 | G6: 探测器报警/故障、报警类型/位置/时间、探测器状态、热成像/视频火灾告警及关联视频索引 | H6: 1 | I6: 套 | J6: 8000 | K6: =H6*J6 -> 8000
A7: 4 | B7: 消防防排烟系统 | C7: 排烟/防烟设备监测 | D7: 排烟风机/补风机启闭状态、远程启动、故障监测；排烟口/阀/窗动作及故障监测；加压送风机/送风口动作及故障监测；电动挡烟垂壁、空调防火阀动作及故障监测；排烟排风主机流量和风向监测。 | E7: 标品 | F7: 防排烟控制系统、消防主机/联动控制器 | G7: 风机/阀/窗/送风口启停及故障状态、远程启动指令、风量/风向、联动事件及时间 | H7: 1 | I7: 套 | J7: 7000 | K7: =H7*J7 -> 7000
A8: 5 | B8: 电气火灾监控 | C8: 电气参数监测 | D8: 在线电压、剩余电流、电缆温度监测及记录；异常现场报警，现场人员确认断电。 | E8: 标品 | F8: 电气火灾监控系统 | G8: 电压、剩余电流、电缆温度、阈值/异常告警、确认及处置记录 | H8: 1 | I8: 套 | J8: 7000 | K8: =H8*J8 -> 7000
A9: 6 | B9: 建筑设施监控 | C9: 防火/机房监测 | D9: 防火门、防火卷帘状态监测；关键机房防水浸监测；关键机房排水泵启闭信号及液位监测。 | E9: 标品 | F9: 消防主机、排水泵控制系统（待现场确认） | G9: 防火门/卷帘状态、水浸告警、排水泵启停/故障、液位、事件时间 | H9: 1 | I9: 套 | J9: 8000 | K9: =H9*J9 -> 8000
A10: 7 | B10: 消防专用电源监控 | C10: 电源监测 | D10: 消防主/备用电源监测；应急照明主/备电源监测。 | E10: 标品 | F10: 消防电源监控系统 | G10: 消防主/备用电源状态、电压/故障、应急照明主/备电源状态、告警时间 | H10: 1 | I10: 套 | J10: 7000 | K10: =H10*J10 -> 7000
A11: 8 | B11: 应急照明和疏散系统 | C11: 状态监控 | D11: 应急照明状态监控；疏散指示系统监控。 | E11: 标品 | F11: 应急照明及疏散指示系统 | G11: 应急照明工作/故障状态、疏散指示状态、设备位置、告警及维护记录 | H11: 1 | I11: 套 | J11: 10000 | K11: =H11*J11 -> 10000
A12: 9 | B12: 气体灭火系统 | C12: 灭火系统监测 | D12: 系统压力监测；气体灭火主机联网监测。 | E12: 标品 | F12: 气体灭火控制系统/气灭主机 | G12: 系统压力、气灭主机报警/故障/启动状态、设备位置、联动事件时间 | H12: 1 | I12: 套 | J12: 8000 | K12: =H12*J12 -> 8000
A13: 10 | B13: 消火栓/灭火器 | C13: 状态监测 | D13: 室内外消火栓箱监测（人工录入）；灭火器状态监测（人工录入）。 | E13: 二开 | F13: 无（人工录入；预留移动巡检接入） | G13: 消火栓箱/灭火器位置、巡检状态、检查时间、责任人、异常及整改记录 | H13: 1300 | I13: 套 | J13: 5 | K13: =H13*J13 -> 6500 | L13: 二开：人\天单价1300
A14: 1.4.3.2.2 火灾监测预警功能
A15: 11 | B15: 火灾多维感知预警 | C15: 多类型报警 | D15: 传统报警器（烟感、温感、吸气式烟感、红外对射、感温光纤）+ 新型报警器（热成像、电缆测温、可燃气体、粉尘）+ AI视频分析识别烟雾/火焰；联动监控自动调取覆盖视频，空间标记弹窗、文字地址播报通知指定人员确认。 | E15: 标品 | F15: 火灾自动报警系统、视频监控平台 | G15: 火警/故障告警、报警设备/区域/位置、关联传感器状态、关联视频索引、事件确认/处置状态 | H15: 1 | I15: 套 | J15: 10000 | K15: =H15*J15 -> 10000 | L15: 报价不含AI视频分析
A16: 12 | B16: 智能预警机制 | C16: 分级预警与推送 | D16: 多级预警阈值实现分级预警；单一火情报警后联动附近多传感器与视频降低误报率；管理员确认后通过短信、微信、钉钉推送至现场/处置/相关人员；基于历史数据趋势分析识别高风险区域。 | E16: 二开 | F16: 视频监控平台、iSungrow（钉钉）/短信平台 | G16: 预警规则/阈值、告警等级、关联传感器/视频信息、风险趋势、通知对象及推送/确认记录 | H16: 1300 | I16: 套 | J16: 8 | K16: =H16*J16 -> 10400 | L16: 二开：人\天单价1300
A17: 1.4.3.2.3 应急处置与联动控制功能
A18: 13 | B18: 应急联动控制 | C18: 自动联动 | D18: 火情确认后对未启动的灭火系统、应急广播/疏散指示系统进行报警或自动启动；危险源电/液/气联动切断；通风排烟系统联动；增加模拟演练的应急联动控制功能。 | E18: 标品 | F18: 消防主机、应急广播/疏散指示系统、达实门禁一卡通系统、防排烟控制系统 | G18: 火情确认结果、联动策略/指令、灭火/广播/疏散/门禁/排烟设备状态、危险源切断状态、演练记录 | H18: 1 | I18: 套 | J18: 10000 | K18: =H18*J18 -> 10000
A19: 14 | B19: 应急指挥调度 | C19: 预案与资源调度 | D19: 预设多场景火灾应急预案一键启动；自动调动最近救援力量、设备、物资；通过预设疏散引导员指挥疏散并协助清点；处置责任人、部门责任人、园区/集团安全管理人多方信息协同。 | E19: 二开 | F19: EHS、iSungrow（钉钉） | G19: 应急预案、事件等级/位置、救援人员/设备/物资、疏散引导员、任务调度/处置进度、通知记录 | H19: 1300 | I19: 套 | J19: 10 | K19: =H19*J19 -> 13000 | L19: 二开：人\天单价1300
A20: 1.4.3.2.4 日常管理和巡检功能
A21: 15 | B21: 消防设备全生命周期管理 | C21: 电子档案与SOP | D21: 建立设备电子档案（采购、安装、维修、更换全过程）；设备故障自动诊断与告警；维保记录电子化；建立操作/维保/巡检电子化SOP。 | E21: 二开 | F21: EAM、EHS、iSungrow（钉钉） | G21: 消防设备台账、采购/安装/维修/更换记录、故障告警、维保/巡检SOP、责任人及执行记录 | H21: 1300 | I21: 套 | J21: 8 | K21: =H21*J21 -> 10400 | L21: 二开：人\天单价1300
A22: 16 | B22: 维保管理 | C22: 维保计划与评价 | D22: 自动生成维保计划到期提醒并分发；维保过程全程记录、支持照片上传与关键参数填写；建立维保质量标准并对维保单位评价。 | E22: 标品 | F22: EAM、iSungrow（钉钉） | G22: 维保计划/到期时间、设备信息、任务分派、照片/关键参数、维保结果、维保单位评价 | H22: 1 | I22: 套 | J22: 5000 | K22: =H22*J22 -> 5000
A23: 17 | B23: 消防巡检管理 | C23: 巡检任务闭环 | D23: 巡检分为每日防火巡查、季度防火检查、节前安全大检查、突击检查；任务自动分发属地责任人、钉钉提醒、延迟提醒；图片与关键参数上传确认到位；自动生成巡检报告并评估。 | E23: 二开 | F23: EHS、iSungrow（钉钉） | G23: 巡检计划/任务、责任人、签到/图片/关键参数、延迟提醒、巡检结果、报告及评估数据 | H23: 1300 | I23: 套 | J23: 6 | K23: =H23*J23 -> 7800 | L23: 二开：人\天单价1300
A24: 18 | B24: 火灾隐患整改管理 | C24: 隐患闭环 | D24: 一键上报EHS隐患随手拍，抓取全链路数据形成报表；整改延迟前三天风险预警；不能按期完成需三方确认后延期；自动抓取生成消防类隐患整改记录并动态评估风险。 | E24: 二开 | F24: EHS、iSungrow（钉钉）、BPM | G24: 隐患上报、现场照片、整改任务/责任人/期限、风险预警、延期审批、整改闭环及风险评估记录 | H24: 1300 | I24: 套 | J24: 9 | K24: =H24*J24 -> 11700 | L24: 二开：人\天单价1300
A25: 19 | B25: 人员培训与演练 | C25: 培训演练 | D25: 支持培训与演练计划制定及提醒；在线学习、测试、记录效果；模拟/实战演练消息推送、数据记录、生成演练报告。 | E25: 二开 | F25: iSungrow（钉钉） | G25: 培训/演练计划、参与人员、课程/试题/成绩、通知记录、演练过程数据、评估报告 | H25: 1300 | I25: 套 | J25: 9 | K25: =H25*J25 -> 11700 | L25: 二开：人\天单价1300
A26: 20 | B26: 智慧消防空间与设施定位 | C26: 四级空间建模 | D26: 建立园区/建筑/楼层/区域四级空间模块（轻量化建模）；自动抓取EHS 5S责任区数据；消防资源位置编码与空间维护；消防资源电子地图（网页/手机端）。 | E26: 二开 | F26: EHS、MDM/空间数据 | G26: 园区/建筑/楼层/区域、5S责任区、消防资源编码/位置、电子地图图层、空间维护记录 | H26: 1300 | I26: 套 | J26: 7 | K26: =H26*J26 -> 9100 | L26: 二开：人\天单价1300
A27: 21 | B27: 园区消防数据智能分析 | C27: 风险模型与考核 | D27: 基于消防数据的风险评估模型；AI算法隐患预测预警；定期自动生成分析报告；多维度输出人员消防管理目标评价。 | E27: 二开 | F27: 数据湖、EHS | G27: 火警/预警/故障/隐患/巡检/维保数据、风险评分、趋势分析、人员考核指标、分析报告 | H27: 1300 | I27: 套 | J27: 62 | K27: =H27*J27 -> 80600 | L27: 基于消防的数据湖做预测、预警分析 | M27: 二开：人\天单价1300
A28: 22 | B28: 用户权限管理 | C28: 角色与审计 | D28: 预设多角色；精细化权限分配；关键操作日志审计；支持园区/楼栋楼层多级管理架构。 | E28: 标品 | F28: 统一身份认证/SSO、MDM | G28: 组织/园区/楼栋/楼层层级、用户/角色/权限、权限变更、登录及关键操作审计日志 | H28: 1 | I28: 套 | J28: 5000 | K28: =H28*J28 -> 5000
A29: 23 | B29: 系统集成与数据互联 | C29: 系统对接 | D29: 对接监控系统（视频与设施地址关联、故障报警关联视频弹窗）、门禁系统（火情区域疏散门禁全开）、企业钉钉、钉钉EHS管理平台；预留扩展园区接口及消防/应急管理部门监管平台接口。 | E29: 二开 | F29: 视频监控平台、达实门禁一卡通系统、iSungrow（钉钉）、钉钉EHS管理平台、消防/应急监管平台（预留） | G29: 消防设施地址/状态、视频及告警、门禁疏散控制状态、EHS隐患/任务、通知记录、监管报送数据 | H29: 1300 | I29: 套 | J29: 16 | K29: =H29*J29 -> 20800 | L29: 二开：人\天单价1300
A30: 24 | B30: 集团-园区消防安全一张图(2.5D) | C30: 态势可视化 | D30: 支持园区→建筑→楼层逐级穿透；集团一张图呈现园区数量、设备覆盖、火警/预警/故障/隐患总量及处置进展、安全评估排名；园区一张图动态展示各类事件实时分布与处置状态，支持按类型/严重程度/区域筛选与视频联动。 | E30: 二开 | F30: 视频监控平台、消防主机、EHS、数据湖/BI | G30: 园区/建筑/楼层空间数据、设备覆盖/在线率、火警/预警/故障/隐患、处置进展、安全评分/排名、关联视频 | H30: 1300 | I30: 套 | J30: 16 | K30: =H30*J30 -> 20800 | L30: 二开：人\天单价1300
A31: 25 | B31: 其他功能需求 | C31: 充电与知识推送 | D31: 电动汽车充电桩监控及报警；电动自行车/叉车/AGV充电区管理（充电、视频、热成像）；安全知识按需推送；消防安全排行榜。 | E31: 二开 | F31: 充电桩监控系统、视频监控平台、iSungrow（钉钉）/短信平台 | G31: 充电桩运行/告警、充电区视频/热成像告警、安全知识内容/推送记录、消防安全排行数据 | H31: 1300 | I31: 套 | J31: 9 | K31: =H31*J31 -> 11700 | L31: 二开：人\天单价1300
A32: N | D32: 合计 | K32: =SUM(K3:K31) -> 313500
C34: 二开（元）： | D34: 214500
C35: 标品（元）： | D35: 99000

Sheet 智慧安防功能清单
A1: 智慧安防功能清单
A2: 序号 | B2: 二级模块 | C2: 功能点 | D2: 功能说明与要求 | E2: 二开/标品 | F2: 对接系统 | G2: 对接数据 | H2: 数量 | I2: 单位 | J2: 单价 | K2: 合价 | L2: 备注
A3: 1.4.3.3.2.1 系统设计（软件建设）
A4: 1 | B4: 平台基础服务 | C4: 统一底座 | D4: 统一操作系统、数据库、中间件正版授权与部署；平台核心服务支持集群部署、负载均衡。 | E4: 标品 | F4: / | G4: / | H4: 1 | I4: 套 | J4: 35000 | K4: =H4*J4 -> 35000
A5: 2 | B5: 统一门户与可视化 | C5: 多端与地图引擎 | D5: 浏览器端、桌面客户端、移动端（iSungrow联动）；2.5D地图加载集成CAD/BIM图纸，设备与区域精准映射与图层管理；全局态势驾驶舱展示设备状态、实时告警、人流车流、KPI等。 | E5: 二开 | F5: iSungrow（钉钉）、视频监控平台、达实门禁一卡通系统、消防系统、MDM/空间数据 | G5: CAD/BIM/地图及设备点位、设备状态、视频/门禁/消防告警、人流车流、KPI、用户/组织及多端访问数据 | H5: 1300 | I5: 套 | J5: 20 | K5: =H5*J5 -> 26000 | L5: 2.5D地图 | M5: 二开：人\天单价1300
A6: 3 | B6: 视频管理服务 | C6: 视频流与存储 | D6: 视频流媒体服务（直播、转码、分发）；录像存储管理（计划/事件录制、存储策略、循环覆盖）；视频智能运维（在线监测、质量诊断、存储健康度检查）。 | E6: 标品 | F6: 视频监控平台 | G6: 摄像机/通道、实时视频流、录像计划/片段/存储状态、转码分发状态、设备在线/质量/存储健康度告警 | H6: 1 | I6: 套 | J6: 10000 | K6: =H6*J6 -> 10000
A7: 1.4.3.3.2.2 智能分析与应用功能软件
A8: 4 | B8: AI算法仓与应用 | C8: 算法授权 | D8: 行为分析（安全帽/反光衣/工服检测、区域入侵、越界、人员聚集、徘徊、离岗睡岗、攀爬等）；事件检测（烟火识别、烟雾检测、物品遗留/移取、人员倒地、交通违章等）；实时视频/图片分析及历史录像智能检索（以图搜图、特征检索、轨迹寻踪）；部分告警工单自动闭环。 | E8: 标品 | F8: 视频监控平台、EHS | G8: 实时视频/图片、算法模型及场景参数、人员/车辆/行为特征、AI告警、历史录像索引、工单/处置结果 | H8: 1 | I8: 套 | J8: 10000 | K8: =H8*J8 -> 10000 | L8: 报价不含算法，对接和订阅，做告警推送
A9: 5 | B9: 告警与事件中心 | C9: 告警归一化 | D9: 统一告警接入引擎多源归一化；智能告警规则引擎（分级、过滤、压缩、关联）；可视化告警处置工作流引擎（工单创建、派发、反馈、闭环）。 | E9: 标品 | F9: 视频监控平台、EHS、iSungrow（钉钉） | G9: 多源告警事件、告警等级/规则/关联关系、工单、派发对象、处置反馈、闭环状态、通知记录 | H9: 1 | I9: 套 | J9: 8000 | K9: =H9*J9 -> 8000
A10: 6 | B10: 业务管理模块 | C10: 巡检/告警/配置 | D10: AI摄像头及告警数据看板；告警列表记录与详情查看；AI告警场景配置（关联算法、告警场景参数）；报警联动（自动弹出现场图像视频复核、声音监听、对讲）；2.5D电子地图配置与反控操作。 | E10: 标品 | F10: 视频监控平台 | G10: 摄像机/算法配置、AI告警、现场图像/视频/音频、电子地图图层及点位、反控操作记录 | H10: 1 | I10: 套 | J10: 5000 | K10: =H10*J10 -> 5000
A11: 系统间联动 · 核心安防与AI物联感知
A12: 7 | B12: 生产与研发全场景AI行为识别 | C12: 产线/作业区识别 | D12: 产线与测试区（火焰烟雾、抽烟、绝缘鞋、非授权入侵、防护口罩）；高危机械与特种作业区（安全带安全帽、机械臂危险区、铅衣、吊装警戒线/晕倒）；仓储与危化品区（火焰烟雾、抽烟、手机、PPE）；通用厂区与机房（火焰烟雾、抽烟）。 | E12: 二开 | F12: 视频监控平台、EHS | G12: 产线/测试区/仓储区视频、识别场景、人员PPE/行为结果、区域入侵/烟火等告警、事件处置记录 | H12: 1300 | I12: 套 | J12: 8 | K12: =H12*J12 -> 10400 | L12: 报价不含算法，对接和订阅，做告警推送 | M12: 二开：人\天单价1300
A13: 8 | B13: 高风险与重点区域IoT深度监测 | C13: 物联联动 | D13: 危化品区域气体探测与泄漏报警+人员滞留超限预警；受限空间人员定位与有害气体联动报警；动火作业实时监控与'人证匹配'验证；职业健康环境监测（噪声、粉尘暴露时长）。需预留硬件接口。 | E13: 二开 | F13: 气体检测设备、人员定位系统、EHS | G13: 气体浓度/泄漏告警、人员位置/滞留时长、受限空间状态、动火作业人员证件比对、噪声/粉尘暴露数据 | H13: 1300 | I13: 套 | J13: 8 | K13: =H13*J13 -> 10400 | L13: 报价不含算法，对接和订阅，做告警推送 | M13: 二开：人\天单价1300
A14: 9 | B14: 5S与现场规范智能监测 | C14: 现场秩序识别 | D14: 摄像头识别消防通道占用等隐患；识别物料占道、超线摆放、地面垃圾等违反5S行为。 | E14: 二开 | F14: 视频监控平台、EHS | G14: 消防通道/物料/5S现场视频、违规类型/位置/时间、抓拍证据、整改任务及闭环记录 | H14: 1300 | I14: 套 | J14: 7 | K14: =H14*J14 -> 9100 | L14: 报价不含算法，对接和订阅，做告警推送 | M14: 二开：人\天单价1300
A15: 10 | B15: 厂区车辆与特种设备安全管控 | C15: 车辆管控 | D15: 厂区道路反光马甲/防砸鞋/安全带识别；特种车辆（叉车、堆高车、托盘车）AI人脸授权管理与非授权驾驶告警抓拍；叉车限速预警与'人车分流'区域入侵报警。 | E15: 二开 | F15: 车辆管理系统、视频监控平台、达实门禁一卡通系统 | G15: 特种车辆/驾驶员、授权人脸/资质、车辆位置/速度、PPE识别、区域入侵、抓拍/告警及处置记录 | H15: 1300 | I15: 套 | J15: 7 | K15: =H15*J15 -> 9100 | L15: 报价不含算法，对接和订阅，做告警推送 | M15: 二开：人\天单价1300
A16: 智能预警与矩阵式信息通知 / 跨系统联动
A17: 11 | B17: 矩阵式自动化通知分发 | C17: 分级分类通知 | D17: 多渠道提醒（弹窗、短信、语音电话、钉钉）；按人员组织架构分级分类精准推送；相关方（承包商）违规专属通知链路（需与EHS危险作业模块打通获取责任人）。 | E17: 二开 | F17: iSungrow（钉钉）、EHS、短信/语音通知服务 | G17: 告警事件/等级、组织/人员/相关方、责任人、通知策略、钉钉/短信/语音发送及签收记录 | H17: 1300 | I17: 套 | J17: 9 | K17: =H17*J17 -> 11700 | M17: 二开：人\天单价1300
A18: 12 | B18: EHS管理平台深度联动 | C18: 两票作业监管 | D18: 与EHS危险作业模块打通，调用现场摄像头对动火等作业人员进行姓名/人脸/身份证比对；业务画面一键调用与历史违规追溯，形成作业评价闭环。 | E18: 标品 | F18: EHS、视频监控平台 | G18: 危险作业票、作业区域/时间、作业人员姓名/人脸/身份证、现场视频、违规记录、作业评价及闭环数据 | H18: 1 | I18: 套 | J18: 15000 | K18: =H18*J18 -> 15000
A19: 13 | B19: 消防与生产系统联动控制 | C19: 门禁疏散/演练 | D19: 火警确认下自动解锁疏散通道门禁并记录疏散路径与时间节点；消防及安防演练数字化管理，AI监控自动清点楼内未撤离人数、识别被困人员并生成演练评估报告。 | E19: 二开 | F19: 消防系统、达实门禁一卡通系统、视频监控平台 | G19: 火警确认、疏散门禁控制指令/状态、疏散路径/时间、人员清点/被困识别、演练过程及评估报告 | H19: 1300 | I19: 套 | J19: 10 | K19: =H19*J19 -> 13000 | M19: 二开：人\天单价1300
A20: 14 | B20: 相关方信用与黑名单联动 | C20: 禁入机制 | D20: 严重违规记录与相关方管理流程、EHS、门禁、制造体系打通，触发严重违规自动全集团黑名单禁入，门禁同步失效。 | E20: 二开 | F20: EHS、达实门禁一卡通系统、人力资源系统/MDM | G20: 严重违规记录、相关方/人员档案、黑名单状态、生效范围、门禁权限变更、禁入执行记录 | H20: 1300 | I20: 套 | J20: 8 | K20: =H20*J20 -> 10400 | M20: 二开：人\天单价1300
A21: 数据资产、日常管理与可视化 / 系统集成
A22: 15 | B22: 安防应急地图（员工端与管理端） | C22: 应急资源可视化 | D22: 地图精准标绘AED、急救药箱、微型消防站等应急物资及应急联系人；员工端一键拨打应急电话；'一键报警'按钮获取员工大致位置并自动推送应急负责人。 | E22: 二开 | F22: MDM/空间数据、视频监控平台、EHS | G22: AED/药箱/微型消防站位置、应急联系人、员工大致位置、一键报警事件、推送及处置记录 | H22: 1300 | I22: 套 | J22: 15 | K22: =H22*J22 -> 19500 | M22: 二开：人\天单价1300
A23: 16 | B23: 数据管理与台账分析 | C23: 数据沉淀与报表 | D23: 保留至少一年高清报警记录及图片/视频片段；多维度（事业部、区域、人员类型、相关方、违规类型）筛选查询与带图导出；内置AI分析自动生成隐患趋势、违规排名等图表。 | E23: 二开 | F23: 数据湖/BI、EHS | G23: 报警记录、图片/视频片段、组织/区域/人员/相关方/违规类型、处置状态、隐患趋势及排名指标 | H23: 1300 | I23: 套 | J23: 6 | K23: =H23*J23 -> 7800 | M23: 二开：人\天单价1300
A24: 17 | B24: 系统集成与外部数据开放 | C24: 集团数据贯通 | D24: 提供标准化数据开放API接口，向集团EHS管理平台、ESG报告系统稳定输出安防及健康安全标准化指标数据。 | E24: 二开 | F24: EHS、ESG报告系统、数据湖 | G24: 安防事件、职业健康/安全指标、标准化指标口径、统计周期、报送状态及接口调用日志 | H24: 1300 | I24: 套 | J24: 6 | K24: =H24*J24 -> 7800 | M24: 二开：人\天单价1300
A25: 1.4.3.3 硬件建设（含重点部位硬件更新补充）
A26: 18 | B26: 智能视频监控硬件 | C26: 摄像机配备 | D26: 出清单/设计及深化图并调试接入，原则上尽可能利旧；含枪机、智能球机、全景、热成像双光谱、防爆型、AI边缘计算结构化摄像机；配套防雷器、防水箱、立杆、支架、补光灯。 | E26: / | F26: / | G26: / | H26: / | I26: / | J26: / | K26: /
A27: 19 | B27: 周界入侵报警硬件 | C27: 周界探测 | D27: 脉冲电子围栏系统或振动光纤探测系统等，出设计深化图并调试接入；辅助现场声光报警器。 | E27: / | F27: / | G27: / | H27: / | I27: / | J27: / | K27: /
A28: 20 | B28: 物联网传感设备 | C28: 传感器接入 | D28: 温湿度、水浸、烟雾探测器等环境传感器；特定气体泄漏、压力、流量等专用探测器，出设计深化图并调试接入；实现所有硬件、传感器、第三方平台接入智慧园区平台。 | E28: / | F28: / | G28: / | H28: / | I28: / | J28: / | K28: /
A29: N | D29: 合计 | K29: =SUM(K3:K28) -> 218200
C31: 二开（元）： | D31: 135200
C32: 标品（元）： | D32: 83000

Sheet 宿舍管理功能清单
A1: 宿舍管理功能清单
A2: 序号 | B2: 二级模块 | C2: 功能点 | D2: 功能说明与要求 | E2: 二开/标品 | F2: 对接系统 | G2: 对接数据 | H2: 数量 | I2: 单位 | J2: 单价 | K2: 合价 | L2: 备注
A3: 1.4.3.4.1 员工入住模块
A4: 1 | B4: 入住申请流程 | C4: 在职/待入职申请 | D4: 在职人员经宿舍服务平台提交住宿申请并由后勤审核安排房间；待入职人员由HR代申请；申请信息同步至BPM入职系统；退宿后无法再次申请（二次申请提醒）；嵌入租房补贴申请选项按满两年标准核算。 | E4: 二开 | F4: 人力资源系统、BPM、iSungrow（钉钉） | G4: 员工/待入职人员、部门/职级、住宿申请/审批、入职状态、房间分配、退宿记录、租房补贴申请及核算周期 | H4: 1300 | I4: 套 | J4: 10 | K4: =H4*J4 -> 13000 | L4: 二开：人\天单价1300
A5: 2 | B5: 房务管理 | C5: 房源可视化与智能分寝 | D5: 按'园区→楼栋→楼层→房间'层级展示状态（空房/已住/维修中/待入住）；同步展示房型实拍图、面积、朝向、租金、配置；结合个性化标签、部门、职级智能分寝并排除维修房间。 | E5: 标品 | F5: 人力资源系统/MDM | G5: 园区/楼栋/楼层/房间、房型/租金/配置/图片、房间状态、入住人员、部门/职级/个性化标签、维修状态 | H5: 1 | I5: 套 | J5: 15000 | K5: =H5*J5 -> 15000
A6: 3 | B6: 入住温馨提示 | C6: 二维码与推送 | D6: 分配后自动触发提醒，生成入园二维码门岗审核；已入职员工钉钉卡片推送、待入职员工短信链接推送入住指南长图。 | E6: 二开 | F6: iSungrow（钉钉）/短信平台、门岗核验系统 | G6: 入住分配结果、入园二维码、员工联系方式/入职状态、入住指南、推送及门岗核验记录 | H6: 1300 | I6: 套 | J6: 6 | K6: =H6*J6 -> 7800 | L6: 二开：人\天单价1300
A7: 1.4.3.4.2 住宿管理模块
A8: 4 | B8: 入住/调寝管理 | C8: 入住办理与调寝 | D8: 本人凭身份证核验后线上签订材料存档；个性化标签录入用于智能推荐；调寝流程含原/新宿管审核、生成调寝通知单，调寝后24小时内工卡权限切换、水电表数据切换；每人因个人原因仅限调寝1次。 | E8: 二开 | F8: BPM、达实门禁一卡通系统、智能水电表系统 | G8: 身份证核验、入住/调寝申请与审批、住宿材料/签字、房间/人员变更、工卡权限变更、水电表归属及读数切换 | H8: 1300 | I8: 套 | J8: 10 | K8: =H8*J8 -> 13000 | L8: 二开：人\天单价1300
A9: 5 | B9: 维修管理 | C9: 工单分级 | D9: 员工端按故障等级提交（紧急故障需上传现场照片标记紧急工单）；维修端展示工单信息、派单、反馈进度；修复后员工线上确认结果；工单自动存档可按园区/房间/时间查询。 | E9: 标品 | F9: iSungrow（钉钉） | G9: 维修工单、故障等级/照片、房间/报修人、派单/处理进度、维修结果、员工确认及归档信息 | H9: 1 | I9: 套 | J9: 8000 | K9: =H9*J9 -> 8000
A10: 6 | B10: 出入授权 | C10: 门禁权限 | D10: 刷卡方式配置宿舍门、楼栋门禁权限；退宿后自动权限失效；宿舍一楼大堂设刷卡/刷脸闸机区分权限身份。 | E10: 二开 | F10: 达实门禁一卡通系统 | G10: 人员/工卡/人脸、宿舍门/楼栋/闸机权限、权限生效/失效时间、出入记录 | H10: 1300 | I10: 套 | J10: 6 | K10: =H10*J10 -> 7800 | L10: 二开：人\天单价1300
A11: 7 | B11: 同住人员信息 | C11: 信息展示 | D11: 支持查看同住人员工号、姓名、兴趣爱好、生活习惯标签（需本人设置允许展示）；离职/调寝后24小时内更新。 | E11: 二开 | F11: 人力资源系统 | G11: 同住人员工号/姓名、入住/离职/调寝状态、兴趣爱好/生活习惯标签、展示授权状态 | H11: 1300 | I11: 套 | J11: 9 | K11: =H11*J11 -> 11700 | L11: 二开：人\天单价1300
A12: 8 | B12: 员工自助 | C12: 时间查询与提醒 | D12: 查询入住起始日期、住宿总时长、免费总时长、剩余免费天数；两年免费到期前30天钉钉推送到期提醒（含缓冲期规则）；知识库Q&A。 | E12: 标品 | F12: 人力资源系统、iSungrow（钉钉） | G12: 入住起止时间、免费/自费住宿天数、缓冲期规则、到期日期、提醒对象及推送记录、知识库内容 | H12: 1 | I12: 套 | J12: 11000 | K12: =H12*J12 -> 11000
A13: 1.4.3.4.3 水电费模块
A14: 9 | B14: 智能水电表联动 | C14: 计费与结算 | D14: 链接园区智能水电表自动获取实时度数；单价管理员可调整并公示；按实际入住天数分摊；每月1日自动生成上月水电费结算表可导出。 | E14: 标品 | F14: EMS、智能水电表系统 | G14: 房间水/电表读数、抄表时间、单价/公示版本、入住天数、分摊规则、月度结算单及费用明细 | H14: 1 | I14: 套 | J14: 5000 | K14: =H14*J14 -> 5000
A15: 10 | B15: 员工端用量查询 | C15: 实时查看 | D15: 员工可查看当日、入住期间的水电用量及对应费用。 | E15: 标品 | F15: EMS、智能水电表系统 | G15: 当日及累计水/电用量、抄表时间、单价、费用、入住期间统计数据 | H15: 1 | I15: 套 | J15: 5000 | K15: =H15*J15 -> 5000
A16: 1.4.3.4.4 员工退宿模块
A17: 11 | B17: 离职/正常退宿 | C17: 退宿闭环 | D17: 关联离职流程自动触发退宿提醒；员工截止日期前联系宿管验收；验收通过标记已退宿并生成退宿确认单线上签字；不通过需缴纳赔偿费（拒缴从工资扣除）；退宿后自动清除门禁权限并注销账户。 | E17: 二开 | F17: 人力资源系统、BPM、达实门禁一卡通系统、薪酬系统（如有） | G17: 离职/退宿申请与审批、验收结果/签字、房间及损坏记录、赔偿费用/扣款、门禁权限注销、账户状态 | H17: 1300 | I17: 套 | J17: 10 | K17: =H17*J17 -> 13000 | L17: 二开：人\天单价1300
A18: 1.4.3.4.5 统计模块
A19: 12 | B19: 续住费用统计 | C19: 超期续住计费 | D19: 管理员设置免费/自费续住天数与续住单价（单人间50、双人间25、四人间12元/天/位）；自动筛选超期人员计算续租费用并生成明细表。 | E19: 二开 | F19: 人力资源系统、薪酬/费控系统（如有） | G19: 免费/自费续住规则、房型/单价、住宿时长、超期人员、续住费用及明细 | H19: 1300 | I19: 套 | J19: 4 | K19: =H19*J19 -> 5200 | L19: 二开：人\天单价1300
A20: 13 | B20: 租房补贴发放时间段统计 | C20: 补贴核算 | D20: 按住宿时长+租房补贴时长累计满两年标准核算，生成应发放补贴时间段并导出明细表。 | E20: 二开 | F20: 人力资源系统、薪酬/费控系统（如有） | G20: 入住周期、租房补贴周期、两年累计时长、应发补贴时间段、人员及核算明细 | H20: 1300 | I20: 套 | J20: 4 | K20: =H20*J20 -> 5200 | L20: 二开：人\天单价1300
A21: 14 | B21: 宿舍档案统计 | C21: 人员档案 | D21: 当前入住人员房间档案（工号、姓名、入住日期、标签）；以往入住人员（入住周期、退宿原因、是否损坏记录）。 | E21: 标品 | F21: 人力资源系统 | G21: 当前/历史入住人员、工号/姓名、房间、入住/退宿日期、标签、退宿原因、损坏记录 | H21: 1 | I21: 套 | J21: 5000 | K21: =H21*J21 -> 5000
A22: 15 | B22: 首页数据看板 | C22: 核心数据 | D22: 展示各园区房源概况、入住率、空置率、水电用量、工单数据等，支持点击下钻查看明细。 | E22: 标品 | F22: EMS、iSungrow（钉钉）、数据湖/BI | G22: 园区房源/入住/空置数据、水电用量/费用、维修工单、统计口径及下钻明细 | H22: 1 | I22: 套 | J22: 5000 | K22: =H22*J22 -> 5000
A23: N | D23: 合计 | K23: =SUM(K3:K22) -> 130700
C25: 二开（元）： | D25: 76700
C26: 标品（元）： | D26: 54000

Sheet 外协系统功能清单
A1: 外协系统功能清单
A2: 序号 | B2: 二级模块 | C2: 功能点 | D2: 功能说明与要求 | E2: 二开/标品 | F2: 对接系统 | G2: 对接数据 | H2: 数量 | I2: 单位 | J2: 单价 | K2: 合价 | L2: 备注
A3: 1.4.3.5.1 - 1.4.3.5.6 外协人员基础管理
A4: 1 | B4: 人员信息管理模块 | C4: 信息录入与审核 | D4: 批量/单个录入外协人员信息，上传证件扫描件数字化存储；多级审核流程；信息查询修改、归档与注销；黑名单与EHS、门禁、人力系统打通实现全集团禁入。 | E4: 二开 | F4: EHS、达实门禁一卡通系统、人力资源系统、BPM | G4: 外协单位/人员、证件扫描件、岗位/合同、审核/归档/注销、黑名单、EHS安全状态、门禁权限及审批记录 | H4: 1300 | I4: 套 | J4: 9 | K4: =H4*J4 -> 11700 | L4: 二开：人\天单价1300
A5: 2 | B5: 准入管理模块 | C5: 资质与准入 | D5: 按岗位设置资质审核项并自动识别有效期提醒；标准化培训课程体系与笔试实操考核；准入审批生成电子准入凭证同步相关模块。 | E5: 二开 | F5: EHS、BPM、达实门禁一卡通系统 | G5: 岗位准入标准、资质证书/有效期、培训/考试成绩、准入申请/审批、电子准入凭证、门禁授权状态 | H5: 1300 | I5: 套 | J5: 10 | K5: =H5*J5 -> 13000 | L5: 二开：人\天单价1300
A6: 3 | B6: 考勤管理模块 | C6: 打卡与统计 | D6: 支持指纹、手机定位等多种打卡方式与范围限制；自动统计出勤、加班、迟到早退；请假补卡审批联动。 | E6: 二开 | F6: iSungrow（钉钉）、人力资源系统、BPM | G6: 打卡位置/时间/方式、出勤/加班/迟到早退、请假/补卡申请及审批、人员/班次信息 | H6: 1300 | I6: 套 | J6: 10 | K6: =H6*J6 -> 13000 | L6: 二开：人\天单价1300
A7: 4 | B7: 行为管理模块 | C7: 违规与评估 | D7: 建立违规分类体系及处罚标准并关联单位/个人档案；360度定期行为评估生成评估报告。 | E7: 二开 | F7: EHS、人力资源系统 | G7: 违规分类/处罚标准、违规记录、单位/个人档案、评估维度/评分、评估报告 | H7: 1300 | I7: 套 | J7: 10 | K7: =H7*J7 -> 13000 | L7: 二开：人\天单价1300
A8: 5 | B8: 安全管理模块 | C8: 培训/检查/事故 | D8: 安全培训记录与未达标限制进入；安全检查隐患整改闭环；事故记录与分析形成案例库。 | E8: 二开 | F8: EHS、达实门禁一卡通系统 | G8: 安全培训/考试、检查任务/隐患/整改、事故记录/分析、准入限制及门禁限制状态 | H8: 1300 | I8: 套 | J8: 19 | K8: =H8*J8 -> 24700 | L8: 二开：人\天单价1300
A9: 6 | B9: 服务质量管理模块 | C9: 评价与结算 | D9: 针对物业/食堂/施工分别设置评价指标；内外部多渠道匿名评价汇总；综合得分反馈改进；按得分/考勤/处罚周期性计算结算金额。 | E9: 二开 | F9: 人力资源系统、ERP/费控系统 | G9: 服务评价指标/评分、考勤、处罚、服务单位/人员、结算周期、应结算金额及明细 | H9: 1300 | I9: 套 | J9: 11 | K9: =H9*J9 -> 14300 | L9: 二开：人\天单价1300
A10: 1.4.3.5.7 费用智能化测算系统
A11: 7 | B11: 数据接入与自动生成 | C11: 多源数据整合 | D11: 自动同步钉钉考勤原始数据；自动生成考勤终表、花名册、配套服务明细、费用汇总表；对接门禁记录、物资代采明细、考核评分统一归集。 | E11: 二开 | F11: iSungrow（钉钉）、达实门禁一卡通系统、ERP/采购系统、EHS | G11: 钉钉原始考勤、门禁记录、花名册、配套服务/物资代采明细、考核评分、考勤终表及费用汇总 | H11: 1300 | I11: 套 | J11: 10 | K11: =H11*J11 -> 13000 | L11: 二开：人\天单价1300
A12: 8 | B12: 智能计算引擎 | C12: 规则自动化 | D12: 内置出勤天数、超龄识别扣款、迟到早退判定、配套服务时长折算等规则自动判定扣款；扣款明细自动输出汇总；基于源头数据保障可追溯可复核。 | E12: 二开 | F12: iSungrow（钉钉）、人力资源系统、ERP/费控系统 | G12: 原始考勤、年龄/人员信息、服务时长、扣款规则/明细、费用汇总及追溯标识 | H12: 1300 | I12: 套 | J12: 20 | K12: =H12*J12 -> 26000 | L12: 二开：人\天单价1300
A13: 9 | B13: 流程协作模块 | C13: 线上审批闭环 | D13: 保洁/保安/维修等配套服务线上申请审批同步结算表；物业服务考核线上化形成'考核-扣款-结算'闭环。 | E13: 二开 | F13: BPM、ERP/费控系统 | G13: 配套服务申请/审批、物业考核评分、扣款、结算单、审批及归档状态 | H13: 1300 | I13: 套 | J13: 15 | K13: =H13*J13 -> 19500 | L13: 二开：人\天单价1300
A14: 10 | B14: 审批视图与看板 | C14: 领导看板 | D14: 费用总览、环比分析、异常波动提示、考核结果关联；所有费用报表支持导出、打印与归档。 | E14: 二开 | F14: ERP/费控系统、数据湖/BI | G14: 费用总额/明细、环比指标、异常波动、考核结果、报表导出/打印/归档记录 | H14: 1300 | I14: 套 | J14: 10 | K14: =H14*J14 -> 13000 | L14: 二开：人\天单价1300
A15: 1.4.3.5.8 物业工作一体化数字平台
A16: 11 | B16: 智能巡检与工单闭环 | C16: 移动化巡检 | D16: 钉钉推送巡检任务打卡拍照记录；一键生成工单全程留痕闭环；AI辅助派单与路径优化；数据看板展示完成率、响应/解决时长、高频问题热力图。 | E16: 二开 | F16: iSungrow（钉钉） | G16: 巡检任务/签到/照片、工单、派单/处理时间、完成率、响应/解决时长、高频问题、推送记录 | H16: 1300 | I16: 套 | J16: 13 | K16: =H16*J16 -> 16900 | L16: 二开：人\天单价1300
A17: 12 | B17: 可视化工作计划与进度 | C17: 计划管理 | D17: 模板化计划复用；甘特图/看板视图展示进度与责任人；智能提醒与逾期预警。 | E17: 二开 | F17: iSungrow（钉钉） | G17: 工作计划/模板、任务/责任人、进度、甘特/看板状态、提醒/逾期预警记录 | H17: 1300 | I17: 套 | J17: 8 | K17: =H17*J17 -> 10400 | L17: 二开：人\天单价1300
A18: 13 | B18: 数字化培训与知识库 | C18: 培训沉淀 | D18: 在线培训（课程发布、任务推送、签到考试）；学习进度与考核记录；SOP/操作手册/案例库/视频集中管理检索。 | E18: 二开 | F18: iSungrow（钉钉） | G18: 培训课程/资料、培训任务、签到/考试、学习进度/成绩、SOP/案例/视频及检索记录 | H18: 1300 | I18: 套 | J18: 10 | K18: =H18*J18 -> 13000 | L18: 二开：人\天单价1300
A19: 14 | B19: 数据看板与决策支持 | C19: 运营总览 | D19: 整合巡检/工单/计划/培训数据形成物业总览看板；多维统计分析；预测性维护建议；月度报告自动生成。 | E19: 二开 | F19: 数据湖/BI | G19: 巡检/工单/计划/培训数据、完成率/时长、高频问题、运营指标、预测维护建议、月度报告 | H19: 1300 | I19: 套 | J19: 10 | K19: =H19*J19 -> 13000 | L19: 二开：人\天单价1300
A20: 1.4.3.5.9 - 1.4.3.5.11 外包人员、调度与多渠道服务
A21: 15 | B21: 外包人员与服务质量管理 | C21: 信息与评价联动 | D21: 物业/保洁/绿化/维修等外包人员统一录入与资质合同管理到期提醒；差异化评价指标、多渠道评价自动汇总、结算联动、服务响应/解决率监管纳入考核。 | E21: 二开 | F21: 人力资源系统、ERP/费控系统、EHS | G21: 外包人员/单位、资质/合同/到期提醒、服务评价、考勤/处罚、结算、响应/解决率及考核数据 | H21: 1300 | I21: 套 | J21: 12 | K21: =H21*J21 -> 15600 | L21: 二开：人\天单价1300
A22: 16 | B22: 智慧调度与资源优化 | C22: 动态排班 | D22: 结合历史工单/巡检/实时请求算法优化排班与工作路线；预留物业机器人（扫地/巡检机器人）对接接口。 | E22: 二开 | F22: 物业机器人系统（预留）、iSungrow（钉钉） | G22: 历史工单/巡检、实时服务请求、人员技能/班次/位置、排班/路线、机器人任务及执行状态 | H22: 1300 | I22: 套 | J22: 13 | K22: =H22*J22 -> 16900 | L22: 二开：人\天单价1300
A23: 17 | B23: 多渠道统一服务请求入口 | C23: 全渠道接入 | D23: 钉钉/企业微信/PC门户/现场扫码多渠道提交服务请求；智能表单引导；语音转工单。 | E23: 二开 | F23: iSungrow（钉钉）、企业微信、语音转文字服务 | G23: 服务请求、渠道来源、用户/位置、智能表单、语音转写、工单、受理状态 | H23: 1300 | I23: 套 | J23: 25 | K23: =H23*J23 -> 32500 | L23: 二开：人\天单价1300
A24: 18 | B24: 智能派单与调度 | C24: 自动派单 | D24: 基于NLP匹配服务类别与技能；结合人员忙闲、地理位置、用户要求自动派发，支持人工坐席接管辅助。 | E24: 二开 | F24: iSungrow（钉钉）、人力资源系统/MDM | G24: 服务类别/技能、人员忙闲/位置、用户要求、派单建议/结果、人工接管、调度日志 | H24: 1300 | I24: 套 | J24: 15 | K24: =H24*J24 -> 19500 | L24: 二开：人\天单价1300
A25: 19 | B25: 服务过程透明化与满意度 | C25: 过程留痕与评价 | D25: 进度实时可查、关键节点钉钉推送、服务轨迹留痕；一键评价、差评自动触发回访、评价关联绩效考核；客服数据分析看板（服务量监控、热点问题预警、SLA趋势分析）。 | E25: 二开 | F25: iSungrow（钉钉）、数据湖/BI、人力资源系统 | G25: 服务进度/轨迹、关键节点通知、评价/差评/回访、绩效关联、服务量/热点/SLA趋势 | H25: 1300 | I25: 套 | J25: 9 | K25: =H25*J25 -> 11700 | L25: 二开：人\天单价1300
A26: N | D26: 合计 | K26: =SUM(K3:K25) -> 310700
C28: 二开（元）： | D28: 310700
C29: 标品（元）： | D29: 0

Sheet 平台通用与集成
A1: 平台通用能力、数据范围与系统集成
A2: 序号 | B2: 二级模块 | C2: 功能点 | D2: 功能说明与要求 | E2: 二开/标品 | F2: 对接系统 | G2: 对接数据 | H2: 数量 | I2: 单位 | J2: 单价 | K2: 合价 | L2: 备注
A3: 1.4.3.6 报表管理模块
A4: 1 | B4: 报表管理 | C4: 园区运营总览驾驶舱 | D4: 园区总览地图（告警、能耗、安防点位）；当日关键KPI（总能耗、产值、安全运行天数、出入人数）每日更新；实时告警滚动，能源/安防/环境核心指标每秒更新。不少于20张定制报表。 | E4: 二开 | F4: EMS、视频监控平台、消防系统、达实门禁一卡通系统、EHS、数据湖、MDM/空间数据 | G4: 园区地图/点位、能耗、安防/消防告警、设备状态、出入人数、产值、安全运行天数、环境指标及实时KPI | H4: 1300 | I4: 套 | J4: 8 | K4: =H4*J4 -> 10400 | L4: 2D可视化 二开：人\天单价1300
A5: 2 | B5: 报表管理 | C5: 安防态势一张图 | D5: 电子地图集成视频、门禁、报警点位；实时告警事件统计与处置状态；人员热力图；消防设备在线率与报警历史。不少于10张定制报表，每小时更新。 | E5: 二开 | F5: 视频监控平台、达实门禁一卡通系统、消防系统、EHS、MDM/空间数据 | G5: 电子地图/点位、视频、门禁通行、报警事件/处置状态、人员热力、消防设备在线率/报警历史 | H5: 1300 | I5: 套 | J5: 3 | K5: =H5*J5 -> 3900
A6: 3 | B6: 报表管理 | C6: 通行记录分析报表 | D6: 按人员、部门、门禁点统计进出记录，生成考勤辅助报表、重点区域访问日志。不少于10张，每分钟更新。 | E6: 二开 | F6: 达实门禁一卡通系统、人力资源系统/MDM | G6: 人员/部门/门禁点、进出记录、考勤辅助数据、重点区域访问日志、统计周期 | H6: 1300 | I6: 套 | J6: 3 | K6: =H6*J6 -> 3900
A7: 4 | B7: 报表管理 | C7: 设施健康度看板 | D7: 关键设备在线率、故障率、平均修复时间；预防性维护计划完成率。不少于10张，每分钟更新。 | E7: 二开 | F7: EAM、EMS、消防/安防设备系统 | G7: 设备台账、在线/故障状态、故障率、维修工单/修复时间、预防性维护计划/完成率 | H7: 1300 | I7: 套 | J7: 3 | K7: =H7*J7 -> 3900
A8: 5 | B8: 报表管理 | C8: 能耗报表 | D8: 总能耗、产品及工序单耗、设备单耗等报表（能耗数据从EMS系统获取），每分钟更新。 | E8: 二开 | F8: EMS | G8: 总能耗、产品/工序/设备能耗、抄表时间、统计口径、能耗报表数据 | H8: 1300 | I8: 套 | J8: 3 | K8: =H8*J8 -> 3900
A9: 6 | B9: 报表管理 | C9: 移动端与自定义报表 | D9: 支持移动端报表查询；其他报表可自定义快速开发，所有报表可查可导；提供工位级/楼栋级/园区级三级看板。 | E9: 二开 | F9: iSungrow（钉钉）、数据湖/BI、MDM/空间数据 | G9: 报表/看板定义、移动端查询/导出记录、工位/楼栋/园区层级、指标及下钻明细 | H9: 1300 | I9: 套 | J9: 3 | K9: =H9*J9 -> 3900
A10: 1.4.3.7 系统管理模块
A11: 7 | B11: 系统管理 | C11: 用户权限管理 | D11: 基于角色的访问控制模型（RBAC），多种用户角色分配操作权限，支持角色及权限调整、密码重置修改。 | E11: 标品 | F11: / | G11: / | H11: 1 | I11: 套 | J11: 2000 | K11: =H11*J11 -> 2000
A12: 8 | B12: 系统管理 | C12: 日志管理 | D12: 记录所有用户操作日志，支持多条件查询，定期归档日志数据。 | E12: 标品 | F12: / | G12: / | H12: 1 | I12: 套 | J12: 2000 | K12: =H12*J12 -> 2000
A13: 1.4.3.8 移动及多屏应用
A14: 9 | B14: 移动多屏 | C14: 多终端支持 | D14: 支持PC、手机、PDA、PAD、电视机等多种操作系统与展示载体；手持终端实现条码扫码、信息录入、设备/工单管理、审批等。 | E14: 二开 | F14: / | G14: / | H14: 1300 | I14: 套 | J14: 8 | K14: =H14*J14 -> 10400 | L14: 二开：人\天单价1300
A15: 10 | B15: 移动多屏 | C15: 消息智能推送 | D15: 报表移动端查看；任务提醒、工单派发、审批待办、逾期预警等钉钉实时推送；具备钉钉、邮件推送功能按策略推送指定人员。 | E15: 标品 | F15: / | G15: / | H15: 1 | I15: 套 | J15: 20000 | K15: =H15*J15 -> 20000
A16: 1.4.4 系统数据范围（数字大脑）
A17: 11 | B17: 数据范围 | C17: 主数据与空间数据 | D17: 园区主数据（多园区维护）、地理空间数据（二维矢量/倾斜摄影/BIM轻量化模型）、资产主数据、人员主数据。 | E17: 二开 | F17: / | G17: / | H17: 1300 | I17: 套 | J17: 9 | K17: =H17*J17 -> 11700 | L17: 二维； 二开：人\天单价1300
A18: 12 | B18: 数据范围 | C18: 运行与业务数据 | D18: 环境状态数据、安防与消防数据、设备运行数据、能源消耗数据、事件与工单数据、操作日志/访问记录等。 | E18: 标品 | F18: / | G18: / | H18: 1 | I18: 套 | J18: 8000 | K18: =H18*J18 -> 8000
A19: 13 | B19: 数据范围 | C19: 主数据治理 | D19: 遵循联想/最终使用方主数据管理标准；无法从外围系统获取的数据供应商提供整理方法和模板并指导导入。 | E19: 二开 | F19: / | G19: / | H19: 1300 | I19: 套 | J19: 7 | K19: =H19*J19 -> 9100
A20: 1.4.5 系统集成范围（关键目标之一，经 ESB 集成）
A21: 14 | B21: 系统集成 | C21: 内部系统对接 | D21: iSungrow（钉钉）、BPM、轻应用、MDM、PS/WTS、EAM、WMS、TMS、EMS、ERP、EHS、SRM、费控系统、数据湖。其中EAM/WMS/TMS/SRM如不涉及标准功能改动则不涉及额外对接费用。 | E21: 二开 | F21: / | G21: / | H21: 1 | I21: 套 | J21: 0 | K21: =H21*J21 -> 0 | L21: 前面报价已含
A22: 15 | B22: 系统集成 | C22: 第三方平台对接 | D22: 视频监控平台、道闸系统（红门）、达实门禁一卡通系统、车辆管理系统等，涉及第三方对接会产生额外费用。 | E22: 二开 | F22: / | G22: / | H22: 1 | I22: 套 | J22: 0 | K22: =H22*J22 -> 0 | L22: 前面报价已含
A23: N | D23: 合计 | K23: =SUM(K4:K22) -> 93100
C25: 二开（元）： | D25: 61100
C26: 标品（元）： | D26: 32000

Sheet 关键技术要求
A1: 关键技术要求
A2: 序号 | B2: 要求类别 | C2: 要求要点 | D2: 具体指标 / 说明 | E2: 响应情况 | F2: 响应说明
A3: 1 | B3: 稳定性 | C3: 高可用架构 | D3: 采用成熟稳定先进的数据库、网络通讯协议、中间件与高可用架构；提供及时准确监控警报与自动化警报处理机制。 | E3: 满足
A4: 2 | B4: 稳定性 | C4: 可用性指标 | D4: 7×24小时运行，年可用率>99.9%；全年系统软件故障应小于5小时。 | E4: 满足
A5: 3 | B5: 高集成性 | C5: 全场景集成 | D5: 与所有内部、外部、第三方系统实现主动、被动、实时、定时集成交互，满足所有业务、数据、应用及蓝图需求。 | E5: 满足
A6: 4 | B6: 兼容性 | C6: B/S架构与浏览器 | D6: B/S架构免安装免维护；客户端支持中文Windows/Linux/Unix；支持IE11+、Edge120+、谷歌120+、火狐120+，普通使用无需额外安装控件。 | E6: 满足
A7: 5 | B7: 兼容性 | C7: 基础组件对接 | D7: 无缝对接指定基础技术组件及中间件（AI模型、缓存、消息队列、数据库），遵循接口规范与技术标准。 | E7: 满足
A8: 6 | B8: 实用性 | C8: 交互与查询 | D8: 访问页面响应无延迟；数据内嵌可视化；结构化管理与层级查看；多策略查询统计分析（所有字段可作筛选条件）；Office/WPS在线预览编辑；界面遵循品牌设计规范。 | E8: 满足
A9: 7 | B9: 先进性 | C9: 国际化 | D9: 完善的无代码侵入性国际化（多语言、多货币、多时区）支持能力。 | E9: 满足
A10: 8 | B10: 先进性 | C10: 二次开发与源码 | D10: 完善易操作的可视化二次开发平台；源码交付含PC端和移动端二次开发代码、核心源码、底层依赖包源码，其中二次开发代码必须交付。 | E10: 满足
A11: 9 | B11: 先进性 | C11: 接口与API | D11: 可视化接口管理平台，接口可配置可灵活调度、完整接口日志；支持Restful API且新增字段立即体现；支持增量/全量同步；主动调用第三方HTTP接口推送增量更新；记录推送状态失败可重发。 | E11: 满足
A12: 10 | B12: 先进性 | C12: 日志与稽核 | D12: 可视化日志管理平台（系统/应用/接口的访问、执行、操作、调用、错误、增删改查），重要数据字段级增删改日志；使用情况综合分析可导出；回收站功能可按时间段恢复删除的重要数据。 | E12: 满足
A13: 11 | B13: 性能要求 | C13: 数据量 | D13: 支持管理至少5PB业务数据量，且性能指标不出现显著衰减。 | E13: 满足
A14: 12 | B14: 性能要求 | C14: 响应时间 | D14: 普通页面≤2秒；关键事务操作≤3秒；API接口95%响应≤500毫秒。 | E14: 满足
... A18: 16 | B18: 可扩展性 | C18: 可视化配置 | D18: 支持业务模型可视化定义（无需二次开发），通过配置扩展模型、属性、工作流模板、审批流、权限、菜单、表单排版、值列表、编码规则等。 | E18: 满足
A19: 17 | B19: 账号与权限管理 | C19: 账号集成 | D19: 通过HR/iPaaS/SSO接口创建/修改/禁用组织部门与人员；可配置二次验证登录；以最终使用方SSO为IDP的单点登录集成；访问白名单（指定域名/IP）。 | E19: 满足 | F19: 通过 HR/iPaaS/SSO 接口与最终使用方身份源集成，支持组织、部门和人员的全量/增量同步及账号创建、修改、禁用；支持以最终使用方 SSO 为 IDP 的单点登录、可配置二次认证，并通过域名/IP 白名单限制访问。
A20: 18 | B20: 账号与权限管理 | C20: 细粒度权限 | D20: 基于组织、角色、用户、项目、数据类型/状态、工作流状态等多维综合权限；字段级显示/隐藏/编辑；权限可代理/转移/复制；灵活审批流配置。 | E20: 满足 | F20: 采用“组织—角色—用户—项目—数据状态”多维权限模型，支持字段级可见/编辑控制、数据权限与工作流状态联动；权限可按授权流程进行代理、转移和复制，所有授权、变更及审批过程保留可审计记录。

Sheet 安全合规要求
A1: 安全与合规要求 — 对应 SOW 2.2.3
A2: 序号 | B2: 类别 | C2: 要点 | D2: 具体要求 | E2: 响应情况 | F2: 响应说明
A3: 2.2.3.1 安全要求
A4: 1 | B4: 安全要求 | C4: 安全资质 | D4: 安全资质：提供产品对应国内及国际安全资质（网络安全等级保护备案、ISO27001/27018、SOC1/2/3、CSA STAR等），须在有效期内。 | E4: 满足
A5: 2 | B5: 安全要求 | C5: 口令策略 | D5: 口令策略：支持口令复杂度和定期更换自定义策略（≥8位、含大小写字母/数字/特殊字符不低于三种、90天更换、历史密码不重复）。 | E5: 满足 | F5: 支持在管理端配置口令复杂度、最小长度、历史密码不可重复及强制定期更换策略；系统可按不少于 8 位、大小写字母/数字/特殊字符中至少三类、90 天到期的规则执行，并保留策略调整审计记录。
A6: 3 | B6: 安全要求 | C6: 安全登录 | D6: 安全登录：登录失败处理（失败3次锁定10分钟、超时30分钟自动退出）；提供账号口令以外认证方式（短信/图形验证码）。 | E6: 满足 | F6: 支持连续登录失败锁定、会话超时自动退出和验证码/短信等辅助认证方式；可配置失败 3 次锁定 10 分钟、无操作 30 分钟自动退出，并记录登录失败、锁定和解锁日志。
A7: 4 | B7: 安全要求 | C7: 安全要求 | D7: 服务账户采用证书认证，禁止明文存储凭据，禁止共享账户或默认密码。 | E7: 满足 | F7: 服务账户采用证书、密钥或令牌等非明文凭据进行认证；凭据通过受控配置/密钥管理机制保存和轮换，禁止共享账户、默认口令及在代码、日志或配置文件中明文存储敏感凭据。
A8: 5 | B8: 安全要求 | C8: 用户账号权限 | D8: 用户账号权限：支持多权限账号（用户、超级/系统/审计/安全管理员），满足最小化原则。 | E8: 满足
A9: 6 | B9: 安全要求 | C9: 网络安全 | D9: 网络安全：IP及端口访问控制默认拒绝所有流量、仅开放必需端口；WAF、IPS防护，具备防范DoS/DDoS能力。 | E9: 满足
A10: 7 | B10: 安全要求 | C10: API鉴权 | D10: API鉴权：API接口安全传输，调用前鉴别鉴权，支持调用日志记录。 | E10: 满足
A11: 8 | B11: 安全要求 | C11: 日志审计 | D11: 日志审计：针对全员重要操作审计（用户操作、系统事件、网络流量），日志至少保存180天。 | E11: 满足
A12: 9 | B12: 安全要求 | C12: 安全要求 | D12: 提供SSL/TLS加密证书，确保所有信息传输加密进行。 | E12: 满足 | F12: 系统全链路采用 HTTPS/TLS 加密传输，部署由合规机构签发且在有效期内的 SSL/TLS 证书；证书到期前预警并按变更流程续期，禁止通过明文 HTTP 传输业务及身份认证信息。
A13: 10 | B13: 安全要求 | C13: 产品要求 | D13: 产品要求：产品为现有资源并做品控保证；开源产品提供后续运维方案；第三方控件/框架/字体获正版授权，出具承诺函。 | E13: 满足
A14: 11 | B14: 安全要求 | C14: 资产清单 | D14: 资产清单：软硬件产品配套资产信息（硬件型号、服务端口、网络协议、中间件版本、API等）。 | E14: 满足
A15: 12 | B15: 安全要求 | C15: 供应商说明 | D15: 供应商说明：说明是否有历史漏洞及相应修复案例与经验。 | E15: 满足
A16: 13 | B16: 安全要求 | C16: 安全证明 | D16: 安全证明：提供开发安全能力证明（认证、会话控制、加密等在编码阶段实现）。 | E16: 满足
A17: 14 | B17: 安全要求 | C17: 安全测试 | D17: 安全测试：提供安全自测报告及开源组件列表；按《漏洞管理办法》测试修复复测，维保期内对新漏洞负责。 | E17: 满足
A18: 15 | B18: 安全要求 | C18: 数据分类分级 | D18: 数据分类分级：按《数据安全分类分级流程》标签化管理并实施差异化安全访问控制策略。 | E18: 满足
A19: 16 | B19: 安全要求 | C19: 数据脱敏 | D19: 数据脱敏：非生产环境避免使用未处理真实敏感数据，同步前进行脱敏/漂白处理。 | E19: 满足 | F19: 建立生产与非生产环境数据隔离机制；测试、培训及演示环境优先使用模拟数据，确需使用生产数据时按字段和场景执行脱敏/去标识化处理，并保留审批与操作记录。
A20: 17 | B20: 安全要求 | C20: 存储加密 | D20: 存储加密：敏感信息持久化存储及跨网络传输采用强加密算法。 | E20: 满足 | F20: 对敏感信息持久化存储实施字段级或存储介质加密，对跨网络传输实施 TLS 加密；密钥与数据分离管理，按权限控制访问并建立密钥轮换、备份和审计机制。
A21: 18 | B21: 安全要求 | C21: 数据销毁 | D21: 数据销毁：项目交付或服务终止后提供数据销毁证明。 | E21: 满足
A22: 2.2.3.2 合规要求（全程国内部署，不涉及数据跨境）
A23: 1 | B23: 合规要求 | C23: 系统全部部署节点在国内， | D23: 系统全部部署节点在国内，符合等保要求；所有数据国内存储处理，严禁向境外传输存储。 | E23: 满足 | F23: 项目部署在中国境内的机房或云资源，业务数据、备份和日志均在境内存储与处理；实施阶段提供部署架构、数据流向和资源地域说明，并按要求配合等保建设及测评。
A24: 2 | B24: 合规要求 | C24: 终端软件符合国内个人信息 | D24: 终端软件符合国内个人信息保护、数据安全法规，杜绝违规收集使用个人信息。 | E24: 满足 | F24: 终端仅在业务必要范围内收集个人信息，落实告知、同意、最小必要、权限控制和安全存储要求；上线前完成隐私合规自查，并按适用法规及时调整终端功能与隐私告知。
A25: 3 | B25: 合规要求 | C25: 管理员账号仅允许国内登录 | D25: 管理员账号仅允许国内登录，留存不少于6个月登录日志。 | E25: 满足 | F25: 管理员登录通过境内网络访问控制、IP/地域白名单等策略进行限制；管理员登录、登出、失败、锁定及关键操作日志统一留存，保存期限不少于 6 个月并支持审计查询。
A26: 4 | B26: 合规要求 | C26: 梳理国内数据全生命周期 | D26: 梳理国内数据全生命周期（采集、存储、使用、传输、共享、销毁）流转，存储周期符合法规不超必要期限。 | E26: 满足 | F26: 建立数据采集、传输、存储、使用、共享、归档和销毁全生命周期台账，明确数据分类分级、责任主体、访问权限、留存期限及销毁方式；定期复核数据流向和最小留存要求。
A27: 5 | B27: 合规要求 | C27: 开展PIA | D27: 开展PIA（个人信息保护影响评估），制定可行缓解措施。 | E27: 满足 | F27: 在涉及个人信息处理的功能上线、重大变更和高风险处理活动前开展 PIA，形成评估报告、风险清单和缓解措施；对整改事项跟踪闭环并在变更后复评。
A28: 6 | B28: 合规要求 | C28: 开展SRA | D28: 开展SRA（信息安全评估），建立健全数据安全管理制度及应急预案。 | E28: 满足 | F28: 按信息安全管理要求开展 SRA，覆盖架构、账号权限、接口、数据、漏洞及运维等风险；形成整改计划、应急预案和演练记录，并对重大风险整改进行复核。
A29: 7 | B29: 合规要求 | C29: 撰写国内适配的隐私政策、 | D29: 撰写国内适配的隐私政策、用户协议、Cookie相关文本（中文为主）。 | E29: 满足 | F29: 提供中文隐私政策、用户协议及 Cookie/SDK 相关告知文本，明确处理目的、范围、保存期限、共享对象和用户权利；在终端显著位置展示并保留版本、生效及用户确认记录。
A30: 8 | B30: 合规要求 | C30: 所有合规文件符合国内现行 | D30: 所有合规文件符合国内现行法规，具备可追溯性与可审计性，法规更新时及时修订。 | E30: 满足 | F30: 建立法规与合规文件版本管理机制，记录适用法规、修订依据、审核/发布/生效信息；法规或业务变更时及时评估影响、修订文件并保留全程可追溯与可审计记录。

Sheet 硬件需求汇总
A1: 硬件场景需求汇总 — 对应 SOW 附录五
A2: 项目范围 | B2: 系统 | C2: 设施设备 | D2: 涉及硬件类型 / 数量
A3: 智慧消防系统 | B3: 消防水系统 | C3: 消防水池 / 水箱 | D3: 水位仪传感器（水池7个、水箱6个，含电动力）、出水管流量传感器12个
A4: 智慧消防系统 | B4: 消防水系统 | C4: 消防泵/喷淋泵 / 稳压泵 | D4: 电气监控28个；稳压泵电气监控+启停状态/次数监测28个（各含电动力4个）
A5: 智慧消防系统 | B5: 消防水系统 | C5: 隔膜气压罐 / 配电柜 / 控制柜 | D5: 隔膜罐14个、配电柜电气监控9个、控制柜电气监控+远程手自动变更28个
A6: 智慧消防系统 | B6: 消防水系统 | C6: 消防测试栓 / 末端测试 | D6: 压力传感器：屋面测试栓30、末端测试200
A7: 智慧消防系统 | B7: 消防水系统 | C7: 进水阀 / 关键管路 / 报警阀 | D7: 流量计+压力传感器13个；50个阀门启闭状态/压力/流量监测；69个报警阀+69个水力警铃
A8: 智慧消防系统 | B8: 消防水系统 | C8: 消防主机 / 消防水炮主机 | D8: 主机信号传输22；水炮电磁阀启动信号2
A9: 智慧消防系统 | B9: 全淹没气灭 | C9: 环境检测 / 电磁阀泄压口 | D9: 氧浓度监测接入33个；压力传感器/电磁阀启动监测100个
A10: 智慧消防系统 | B10: 排烟系统 / 防火卷帘 | C10: 排烟风机 / 电动挡烟垂壁 | D10: 排烟风速计量（含风向）110；释放状态监测
A11: 智慧消防系统 | B11: 排水系统 | C11: 雨水截止阀 / 排水泵 / 机房 | D11: 自动灭火联动截止阀关闭；启闭监测24个（6消防泵房）；防水浸监测10个
A12: 智慧消防系统 | B12: 可燃气体 | C12: 可燃气体报警主机 / 管路 | D12: 报警主机接入8个；燃气/压缩空气管道联动电磁阀2个
A13: 智慧消防系统 | B13: 电气火灾监控 | C13: 在线监测 | D13: 在线电压、剩余电流、电缆温度检测 400+
... A18: 智慧安防系统 | B18: 巡更系统 | C18: 巡更点 | D18: 使用NFC等设备进行巡更管理 40+
A20: 注：以上为附录五硬件场景需求表要点汇总，具体点位数量与利旧原则以现场勘察及深化设计为准。
