Workbook

Sheet 总价汇总表
A1: 密级：公开
A2: 阳光电源智慧园区一期建设清单报价清单-汇总表
A3: 序号 | B3: 系统名称 | C3: 税率 | D3: 不含税总价 | E3: 含税总价 | F3: 备注
A4: 1 | B4: 硬件部分 | C4: 0.13 | D4: ='硬件-报价汇总表'!D7 -> 7857359 | E4: =D4*(1+C4) -> 8878815.7
A5: 2 | B5: 软件部分 | C5: 0.13 | D5: ='软件-报价汇总表'!G7 -> 3952000 | E5: =D5*(1+C5) -> 4465760
A6: 3 | B6: 总计（元） | D6: =SUM(D4:D5) -> 11809359
D7: 按此未税金额投标

Sheet 硬件-报价汇总表
A1: 密级：公开
A2: 阳光电源智慧园区一期建设清单（硬件）报价清单
A3: 序号 | B3: 系统名称 | C3: 税率 | D3: 不含税总价 | E3: 备注
A4: 1 | B4: 智慧消防及物联系统 | C4: 0.13 | D4: =SUM('硬件-报价明细'!Q4:Q33) -> 2604713
A5: 2 | B5: 智慧安防系统 | C5: 0.13 | D5: =SUM('硬件-报价明细'!Q36:Q110) -> 5229283
A6: 3 | B6: 等保测评 | C6: 0.13 | D6: =SUM('硬件-报价明细'!Q112) -> 23363
A7: 4 | B7: 不含税总计（元） | D7: =SUM(D4:D6) -> 7857359
A8: 报价须知： 1、报价前请仔细阅读《硬件-报价说明》。 2、付款方式：电汇，合同签订后预付合同对应金额的20%，初验完成后支付合同对应金额的50%（且累积支付不超实际产值70%），终验决算完成支付至决算对应金额的90%，剩余10%作为质保金，自竣工验收通过满1年后如无质量问题、无发生甲方代扣代付维修费用，甲方无息支付质保金。

Sheet 硬件-报价说明
A1: 密级：公开
A2: 阳光电源智慧园区一期建设清单（硬件） 投标报价说明
A3: 说明 | B3: 本报价说明作为投标文件的重要组成部分，与招标文件、技术规格书及合同具有同等效力。投标人须仔细阅读并充分理解所有条款，报价提交后视为已完全响应。
A4: 一、报价范围与计价模式
A5: 总价包含范围 | B5: 1、投标总价含设备、材料等运输、卸货、搬用、保存、安装、集成调试，通断测试，福禄克测试，质保期内保证项目稳定运行的所需全部费用。
B6: 2、投标总价含设备、线缆、柜、箱体等的机打标签、整理等工作，达到《阳光电源弱电施工工艺参考图册》、《阳光电源厂区及办公区弱电标识标签规则》要求。
B7: 3、投标总价含施工、技术支持、操作人员培训等，含3年原厂质保运维服务等，故障1小时响应，故障处理6小时内完成。
B8: 4、投标总价含材料费、施工费、调试费、措施费、安全文明施工费、税金、总包管理服务费、施工用水电费用、辅材、实现平台功能前端设备调整（角度、位置等）等项目交付前一切费用，辅材包括但不限于六类非屏蔽水晶头、音频接插头、各种螺丝、吊卡、丝杆、铁皮卡、自攻螺丝、膨胀管、绝缘子、接线端子、弓背、管道支持柱、拉爆三件套、膨胀螺栓、机柜螺丝、垫片、绝缘胶布、透明胶布、扎带、标签纸、魔术贴、网线固线器、标签机、钩钉、刚性卡箍、螺丝杆帽、PVC线槽、自喷漆、明装86盒、明装86盒盖板、弯管器、墙面开孔及开槽及修复、地面开挖及绿化恢复、其他施工工具等辅材。
A9: “实体净量+量价分离”计价规则 | B9: 本项目所有强弱电管、线、桥架类材料实行“实体净量+量价分离”计价模式，清单工程量仅依据设计图纸标注的水平/垂直投影净长度计算，施工中必然发生的桥架（含管道）内敷设弯曲、桥架上翻下翻、机柜与终端处的预留长度，以及各类管、线、桥架类材料的合理损耗等，其工程量与费用均视为投标人施工技术的一部分，须在编制综合单价时一并考虑（相关费用在材料单价中体现），结算时不再单独计量。
A10: 综合单价包干 | B10: 综合单价为包干价，包括但不限于完成工程量清单子目特征描述、工作内容描述等全部内容所需的人工费、材料费（甲供材除外）、机械费、管理费、利润、税金等全部费用，特征描述中不完善，但按常规属于完成该对应子目所必须有的工作内容，视为已包含在综合单价中。
A11: 二、技术要求与执行标准
A12: 工艺与标签规范 | B12: 施工须符合《阳光电源弱电施工工艺参考图册》、《阳光电源厂区及办公区弱电标识标签规则》，含设备、线缆、柜体等机打标签及整理。
A13: 施工界面与现场踏勘 | B13: 投标人应踏勘现场，充分了解施工移交界面及标准（如地面、墙面找平层厚度可能产生的变化），相关费用包含在报价中。
A14: 深化设计与规范要求 | B14: 本工程工程量清单项目仅列出主要包含范围，投标单位应结合设计图及标准作法进行理解，投标单位需按规范及设计要求深化施工工艺及对应施工工艺作法，本部分费用已含在本合同总价中。
A15: 三、投标报价与格式要求
A16: 报价格式 | B16: 报价时按照甲方提供表格格式要求进行报价；乙方提供excel表格报价电子档文件（可编辑版本即可），并提供word版本盖章报价扫描件（包含表头：序号、项目名称、工程量、单位、投标品牌、投标型号、参数（响应/正偏离/负偏离）、正/负偏离参数项、材料未税单价、施工未税单价、未税小计、备注）。
A17: 单价一致性 | B17: 清单中所列相同项目，投标单位报价须保持一致，若投标报价不一致，则以报价较低的单价计算并调整总价。
A18: 链接正确性 | B18: 投标清单中的链接由投标人自行负责核实。
A19: 金额精度 | B19: 工程量清单内所有工程量及金额均需保留两位小数，并以显示精度为准。
A20: 四、风险与变更条款
A21: 未尽事宜 | B21: 其他未尽事宜详见招标技术规格书及其他招标材料。
A22: 设计冲突处理 | B22: 清单中的所有主材要求详见图纸说明、技术规范书要求及清单描述，如相关描述有冲突时，按高标准执行。
A23: 材料及品牌更换 | B23: 材料如招标人提出替换时，费用只计算材料价差和税金，不再计取其他费用。
A24: 施工风险 | B24: 1、投标人已综合考虑施工中可能发生的各类风险（如材料损耗、预留长度、现场条件变化等），相关费用已包含在报价中。
B25: 2、合同期内人工、材料、机械和临时设施及施工水电费的费用、费率等价格要素的波动，合同执行期内一律不予调整。
B26: 3、施工费含白天施工、夜间施工、节假日施工等。

Sheet 硬件-报价明细
A1: 密级：公开 | H1: 乙方必填项 | I1: 乙方必填项 | J1: 乙方必填项 | K1: 乙方必填项 | L1: 乙方必填项 | M1: 乙方必填项 | O1: 乙方必填项 | Q1: 乙方必填项
A2: 序号 | B2: 设备名称 | C2: 技术参数要求 | D2: 推荐品牌 | E2: 数量 | F2: 单位 | G2: 备注 | H2: 投标品牌 | I2: 投标型号 | J2: 投标参数 | K2: 参数（响应/正偏离/负偏离） | L2: 正/负偏离 参数项 | M2: 施工未税单价 | N2: 施工小计未税 | O2: 材料未税单价 | P2: 材料小计未税 | Q2: 未税小计 | R2: 备注
B3: 一、智慧消防及物联系统
A4: 1 | B4: 用户信息传输装置 | C4: 壁挂式，用于消防远程监控，通过RS232端口实时监测所连接火灾报警控制器的报警信息，并通过有线网络传递到监控平台。满足GB26875-2011标准。 | D4: 主机信号采集数量：青鸟自动报警主机*20，青岛鼎信自动报警主机*1，利达自动报警主机*1，各品牌需对应使用适配的用户信息传输硬件 | E4: 22 | F4: 台 | H4: 青鸟 | I4: JBF-TD803 | J4: 下行：RS232串口（三芯电缆，长度<15米） 上行：TCP/IP网络（标准网线，长度<50米）; 最多可记录 100,000 条历史事件; 主电：AC 187~242V, 50Hz 备电：DC 12V / 4Ah（支持主备电自动切换）; 2组 DC12V 200mA 有源输出（驱动继电器） 1组 DC12V 200mA 电源（内部模块供电） 1组 DC5V 1A 电源（内部模块供电）; 壁挂式安装，上进线; 尺寸310mm(长) × 110mm(宽) × 420mm(高) 满足GB26875-2011标准。 | K4: 响应 | L4: / | M4: 489 | N4: =E4*M4 -> 10758 | O4: 4035 | P4: =E4*O4 -> 88770 | Q4: =E4*(M4+O4) -> 99528
E5: 1 | F5: 台 | H5: 鼎信 | I5: TS-CS-8101 | J5: 主电电源：额定工作电压 AC220V/50Hz，宽电压范围 AC176V～AC420V 可接入； 备电电源：12V/2.3Ah 蓄电池； 容量：配接一台控制器； 液晶规格：320×480 彩色液晶屏； 使用环境：温度：0℃~+40℃； 相对湿度≤95%，不凝露； 外形尺寸：270.0mm× 190.0mm× 62.5mm(长× 宽× 高)； 安装孔距：水平间距 226.0mm，垂直间距 93.0mm； 重量：约 2.1kg； 外壳防护等级：IP30； | K5: 响应 | L5: / | M5: 489 | N5: =E5*M5 -> 489 | O5: 7434 | P5: =E5*O5 -> 7434 | Q5: =E5*(M5+O5) -> 7923
E6: 1 | F6: 台 | H6: 利达 | I6: LD6920 | J6: DC 24V；< 200mA； CAN总线、RS232串口、开关量输入；支持 GPRS/2G、TCP/IP、电话线（可选配） | K6: 响应 | L6: / | M6: 489 | N6: =E6*M6 -> 489 | O6: 5310 | P6: =E6*O6 -> 5310 | Q6: =E6*(M6+O6) -> 5799
A7: 2 | B7: 全局网络控制器 | C7: 1.名称：全局网络控制器 2.参数要求：单核 A8@1GHz，1GB DDR3 / 4GB microSD，2× 百兆，2×RS-485，可扩展4 个 I/O/ 现场总线模块。协议：BACnet IP/MS/TP + Modbus TCP/RTU + LonWorks + KNX + SNMP + oBIX，编程：Niagara 图形化编程，功能极强，适合复杂联锁 / 算法。满足现场现场功能所需的点位授权费 | D7: 霍尼韦尔、江森、西门子 | E7: 9 | F7: 台 | H7: 霍尼韦尔 | I7: WEB-8050-U | J7: 1GHz处理器，1024MB内存，4096MB闪存，支持50个Device且数据点不大于2,500点，2条总线 | K7: 响应 | L7: / | M7: 326 | N7: =E7*M7 -> 2934 | O7: 33864 | P7: =E7*O7 -> 304776 | Q7: =E7*(M7+O7) -> 307710
A8: 3 | B8: 可编程网络控制器 | C8: 通讯接口：100M以太网，双网口 协议：BACnetIP/Modbus-TCP 扩展接口通讯：控制器内部协议 DI输入接口：数量最大24路，干接点接入 DO控制接口：8路，继电器负载能力2A/30VDC UI输入接口：最大16路，支持电阻型温度NTC20K，电压型湿度0~10V，电压型CO2,0~10V，电压型CO 0~10V,电流型水压4~20mA，电流型流量计4~20mA，执行器0~10V和2~10V反馈 AO输出接口：8路，支持4~20mA和0~10V输出 RS485接口数量：2个，其中一个支持多合一传感器接入，另外一路备用 支持PLC功能，支持PLC逻辑编程 尺寸：225x115x 57mm 外壳原料： UL 94 ABS 电源：DC24V/3A 重量：500g | D8: 霍尼韦尔、江森、西门子 | E8: 129 | F8: 台 | H8: 霍尼韦尔 | I8: PUC5533-PB2 | J8: BACnet现场控制器DDC 5UI,5DI,3AO,3DO | K8: 响应 | L8: / | M8: 233 | N8: =E8*M8 -> 30057 | O8: 1405 | P8: =E8*O8 -> 181245 | Q8: =E8*(M8+O8) -> 211302 | S8: 招标要求带网络协议装换控制模块，PUC5533-PB2为总线型控制模块不满足招标参数，
A9: 4 | B9: 可编程控制盘 | C9: 1、包含：空开、导轨及接线端子 2、国产优质箱体，根据实际安装设备测量后成套定制 | D9: 国产一线品牌，空开品牌为良信、正泰、公牛 | E9: 129 | F9: 台 | H9: 正泰 | I9: 定制成套 | J9: 含空开、导轨及接线端子，国产优质箱体，根据实际安装设备测量后成套定制 | K9: 响应 | L9: / | M9: 233 | N9: =E9*M9 -> 30057 | O9: 781 | P9: =E9*O9 -> 100749 | Q9: =E9*(M9+O9) -> 130806
A10: 5 | B10: 电源模块 | C10: 输入：85–264VAC（全球宽压），50/60Hz 输出：24VDC 可调（约 24–26V） 电流：1.3A / 2.5A / 4A（常用 4A 配 DDC） 保护：过压、短路、过载、过热（自恢复） EMC：EN61000-6-2、EN61000-4 系列，工业级 安装：35mm DIN 导轨 外壳：UL94 V-0 阻燃塑料 工作温度：-20℃ ~ +60℃ | D10: 霍尼韦尔、江森、西门子 | E10: 129 | F10: 台 | H10: 施耐德 | I10: ABL2REM12100D | J10: ‌输入‌：90~264VAC全球宽压，适配50/60Hz工业电网 ‌输出‌：24VDC，额定电流5A，总功率120W，输出电压支持24~28V微调 ‌转换效率‌：最高可达87.5%，满载运行温升可控 ‌防护机制‌：集成过压、短路、过载、过热四重自恢复保护，故障消除后自动恢复运行 ‌安装方式‌：适配标准35mm DIN导轨，卡扣式安装无需额外固定 ‌外壳与环境‌：UL94 V-0阻燃塑料外壳，工作温度范围-20℃~+65℃ ‌合规认证‌：通过UL508工业控制设备认证，满足EN61000-6-2工业级EMC抗扰标准 | K10: 响应 | L10: / | M10: 17 | N10: =E10*M10 -> 2193 | O10: 276 | P10: =E10*O10 -> 35604 | Q10: =E10*(M10+O10) -> 37797
A11: 6 | B11: 液位开关 | C11: 电缆长度：3M；电缆类型：PVC（聚氯乙烯）；包装形式：纸箱批量简易包装； | D11: 霍尼韦尔、江森、西门子 | E11: 13 | F11: 台 | H11: 霍尼韦尔 | I11: HSL-LS05 | J11: 浮球液位开关,延长线缆长度5m | K11: 响应 | L11: / | M11: 140 | N11: =E11*M11 -> 1820 | O11: 159 | P11: =E11*O11 -> 2067 | Q11: =E11*(M11+O11) -> 3887
A12: 7 | B12: 压力变送器 | C12: 输出信号：4-20MA；量程范围：0-25 bar；过程连接：1/4 NPT；电气连接：1M； | D12: 霍尼韦尔、江森、西门子 | E12: 362 | F12: 台 | H12: 霍尼韦尔 | I12: HSP-W | J12: 量程0-16Bar，精度：±1%FS ；信号0-10VDC，电源14-30VDC； IP65；3线制；G1/4 male | K12: 响应 | L12: / | M12: 140 | N12: =E12*M12 -> 50680 | O12: 412 | P12: =E12*O12 -> 149144 | Q12: =E12*(M12+O12) -> 199824
A13: 8 | B13: 流量传感器 | C13: 电源:10 to 35 VDC；电源消耗:最大40mA；输出:脉冲:NPN开集方波输出，最大60V@50mA;频率:3.2至200Hz。脉冲宽度:2.5毫秒+25%，4-20mA:4mA是0fts，20 mA是25 fts。过程连接:标准配置为1-1/2”NPT外螺纹，可选2“NPT外螺纹。管径满足现场环境 | D13: 霍尼韦尔、江森、西门子 | E13: 75 | F13: 台 | H13: 霍尼韦尔 | I13: PFT-IDN-B111-S | J13: 供电与功耗：10-35 VDC，最大 40mA。 - 脉冲输出：NPN 开集方波，最大 60V@50mA，频率 3.2-200Hz，脉宽 2.5ms±25%。 • 模拟输出：4mA 对应 0 ft/s，20mA 对应 25 ft/s。 - 过程连接：标准 1½" NPT 外螺纹。 • 材质与量程：黄铜本体，流速范围 1.2-25 ft/s（0.37-7.62 m/s） | K13: 响应 | L13: / | M13: 408 | N13: =E13*M13 -> 30600 | O13: 4779 | P13: =E13*O13 -> 358425 | Q13: =E13*(M13+O13) -> 389025
A14: 9 | B14: 氧浓度监测传感器 | C14: 工作温度 -20~50℃ 工作湿度 5~95% RH 无冷凝 压力范围 90~110KPa 稳定性 ≤5% 信号值 / 年 响应时间 ≤10S 预热时间 ≥5 分钟 零点漂移（-20~40℃） ±0.3%Vol 重复性 ≤1% 使用寿命 ≥24 个月 量程 0~25% VOL 精度 ±2%FS 分辨率 0.1%VOL | D14: 霍尼韦尔、江森、西门子 | E14: 26 | F14: 台 | H14: 霍尼韦尔 | I14: G3Ex121 | J14: 电源：DC24V±25% 输出：0~10V，4~20mA(三线)，RS485/Modbus 负载：≥2kΩ(0~10V)，≤500Ω(4~20mA) 开关输出：1×SPST，3A/30VDC 显示：LED 数码管显示，电源/故障/报警LED 指示灯 应用环境：-20~55°C，10~95%RH(非冷凝)，压力86~106kPa 外壳材料：铸铝外壳，不锈钢探头和不锈钢网烧结过滤器 | K14: 响应 | L14: / | M14: 140 | N14: =E14*M14 -> 3640 | O14: 1912 | P14: =E14*O14 -> 49712 | Q14: =E14*(M14+O14) -> 53352
A15: 10 | B15: 温湿度传感器 | C15: 精度：±2%RH；湿度输出：0-10V；温度输出：NTC20K，±0.2°C @25°C；温度量程：0~50℃；继电器输出：无；LCD显示无； | D15: 霍尼韦尔、江森、西门子 | E15: 2 | F15: 台 | H15: 霍尼韦尔 | I15: HSH-RV3B | J15: 壁挂式温湿度传感器，NTC20K温度输出，3%湿度精度，0~10V | K15: 响应 | L15: / | M15: 140 | N15: =E15*M15 -> 280 | O15: 425 | P15: =E15*O15 -> 850 | Q15: =E15*(M15+O15) -> 1130
A16: 11 | B16: 管道风速监测传感器 | C16: 量程：0–20 m/s（0–4000 ft/min），精度：±0.2 m/s（≤10 m/s）；±2% FS（>10 m/s），输出信号：0–10VDC（线性对应量程），供电：24VDC ±10%（BA 标准供电） 材质 / 防护：ABS 外壳，探杆 304 不锈钢；IP65 温度：-10℃~+50℃（耐高温款可达 80℃） 安装：法兰开孔插入式，带密封圈，漏风小 | D16: 霍尼韦尔、江森、西门子 | E16: 89 | F16: 台 | H16: 霍尼韦尔 | I16: AVT25101 | J16: 风速变送器，风管型风速变送器，输出：0-10VDC&4-20mA | K16: 响应 | L16: / | M16: 140 | N16: =E16*M16 -> 12460 | O16: 913 | P16: =E16*O16 -> 81257 | Q16: =E16*(M16+O16) -> 93717
A17: 12 | B17: 继电器 | C17: 适配电磁阀信号选配 | D17: 霍尼韦尔、江森、西门子 | E17: 100 | F17: 个 | H17: 西门子 | I17: ER2EL - D24 | J17: 8脚 5A 2开2闭 DC24V | K17: 响应 | L17: / | M17: 17 | N17: =E17*M17 -> 1700 | O17: 16 | P17: =E17*O17 -> 1600 | Q17: =E17*(M17+O17) -> 3300
A18: 13 | B18: 交流电流变送器 | C18: 输出4-20mA三相模块RS485信号 | D18: 霍尼韦尔、江森、西门子 | E18: 168 | F18: 个 | H18: 霍尼韦尔 | I18: CSNK500M | J18: 输出4-20mA，三相模块，RS485信号 | K18: 响应 | L18: / | M18: 140 | N18: =E18*M18 -> 23520 | O18: 457 | P18: =E18*O18 -> 76776 | Q18: =E18*(M18+O18) -> 100296
A19: 14 | B19: 光纤熔接盒（含光纤熔纤） | C19: SC4芯单模满配含熔接尾纤、法兰、SC光跳线 | D19: 一舟、普天天纪、罗格朗 | E19: 129 | F19: 个 | H19: 一舟 | I19: S953-4X+S905-3*4+S812*4 | J19: SC4芯单模满配含熔接尾纤、法兰、SC光跳线 | K19: 响应 | L19: / | M19: 52 | N19: =E19*M19 -> 6708 | O19: 71 | P19: =E19*O19 -> 9159 | Q19: =E19*(M19+O19) -> 15867
A20: 15 | B20: 光纤收发器 | C20: 1个10/100M/1000M网口，1个1000Mbps光口（SC），工作波长：1550nm（发送）、1310nm（接收），20km。 | D20: TP-LINK、山泽、烽火 | E20: 129 | F20: 对 | H20: TP-LINK | I20: TL-FC311A-20+TL-FC311B-20 | J20: 1个10/100M/1000M网口，1个1000Mbps光口（SC），工作波长：1550nm（发送）、1310nm（接收），20km。 | K20: 响应 | L20: / | M20: 17 | N20: =E20*M20 -> 2193 | O20: 240 | P20: =E20*O20 -> 30960 | Q20: =E20*(M20+O20) -> 33153
A21: 16 | B21: 光纤收发器架 | C21: 14槽光纤收发器机架；标准机柜安装； | D21: TP-LINK、山泽、烽火 | E21: 34 | F21: 个 | H21: TP-LINK | I21: TL-FC1400 | J21: 14槽光纤收发器机架；标准机柜安装； | K21: 响应 | L21: / | M21: 17 | N21: =E21*M21 -> 578 | O21: 504 | P21: =E21*O21 -> 17136 | Q21: =E21*(M21+O21) -> 17714
A22: 17 | B22: 室外4芯单模光缆 | C22: 1.标准：YD/T769，ISO/IEC11801，ANSI/TIA -568-C.3 2.全截面阻水结构，松套管填充纤膏，松套管和钢带之间填充缆膏，确保良好的阻水防潮性能 3.光纤规格：B1.3（OS2） 4.衰减＠20℃（dB/Km）：＠1310nm≤0.36，＠1550nm≤0.22 5.光纤芯数：4芯 6.护套：夹带钢丝的钢-聚乙烯粘结护套，MDPE，黑色 7.允许拉伸力：长期：600N，短期：1500N 8.允许压扁力：长期：300N/100mm，短期：1000N/100mm 9.最小弯曲半径：动态：20D，静态：10D | D22: 一舟、普天天纪、罗格朗 | E22: 130000 | F22: m | H22: 一舟 | I22: D173-4 | J22: 1.标准：YD/T769，ISO/IEC11801，ANSI/TIA -568-C.3 2.全截面阻水结构，松套管填充纤膏，松套管和钢带之间填充缆膏，确保良好的阻水防潮性能 3.光纤规格：B1.3（OS2） 4.衰减＠20℃（dB/Km）：＠1310nm≤0.36，＠1550nm≤0.22 5.光纤芯数：4芯 6.护套：夹带钢丝的钢-聚乙烯粘结护套，MDPE，黑色 7.允许拉伸力：长期：600N，短期：1500N 8.允许压扁力：长期：300N/100mm，短期：1000N/100mm 9.最小弯曲半径：动态：20D，静态：10D | K22: 响应 | L22: / | M22: 1 | N22: =E22*M22 -> 130000 | O22: 2 | P22: =E22*O22 -> 260000 | Q22: =E22*(M22+O22) -> 390000 | S22: 施工费偏低无法实现
A23: 18 | B23: 24口光纤配线架（含尾纤、LC双工耦合器、熔接） | C23: 1.标准：YD/T778，ISO/IEC 11801，ANSI/TIA -568-C.3 2.安装方式：19″机架式安装 3.4个光缆进线口，带固定PG头，盒内配置光缆护套固定装置，光缆加强件固定装置 4.通用型设计，可兼容：LC双工、SC单工、FC、ST适配器，一个4口支架仅需一颗螺丝，便于安装和拆卸 5.进出光纤方便灵活，有充裕的光纤盘存空间，光纤和尾纤弯曲半径不小于30mm 6.端口数量： 24口，空余端口可安装空白功能件，高度：1U 7.表面处理：静电喷塑 8.材料：优质冷扎钢板 9.表面颜色：黑色 10.含LC双工耦合器 | D23: 一舟、普天天纪、罗格朗 | E23: 24 | F23: 个 | H23: 一舟 | I23: S952-12X+S905-7-1*12+S813*24 | J23: 1.标准：YD/T778，ISO/IEC 11801，ANSI/TIA -568-C.3 2.安装方式：19″机架式安装 3.4个光缆进线口，带固定PG头，盒内配置光缆护套固定装置，光缆加强件固定装置 4.通用型设计，可兼容：LC双工、SC单工、FC、ST适配器，一个4口支架仅需一颗螺丝，便于安装和拆卸 5.进出光纤方便灵活，有充裕的光纤盘存空间，光纤和尾纤弯曲半径不小于30mm 6.端口数量： 24口，空余端口可安装空白功能件，高度：1U 7.表面处理：静电喷塑 8.材料：优质冷扎钢板 9.表面颜色：黑色 10.含LC双工耦合器 | K23: 响应 | L23: / | M23: 17 | N23: =E23*M23 -> 408 | O23: 308 | P23: =E23*O23 -> 7392 | Q23: =E23*(M23+O23) -> 7800
A24: 19 | B24: 光纤跳线 | C24: 单模双芯SC-LC优质2米光纤跳线； | D24: 一舟、普天天纪、罗格朗 | E24: =E20 -> 129 | F24: 个 | H24: 一舟 | I24: S928 | J24: 单模双芯SC-LC优质2米光纤跳线； | K24: 响应 | L24: / | M24: 6 | N24: =E24*M24 -> 774 | O24: 24 | P24: =E24*O24 -> 3096 | Q24: =E24*(M24+O24) -> 3870
A25: 20 | B25: 六类非屏蔽跳线（2m） | C25: 1.标准：不低于TIA/EIA568-C.2、ISO/IEC11801、IEC60332-1、GB 50311； 2.导体规格：多股绞合，软圆铜线，4×2×23AWG； 3.护套材料：PVC，护套外径：6.3±0.3mm； 4.插头规格：RJ45，8P8C； 5.插拔次数：≥1000次； 6.最高传输频率：不小于250MHz； 7.线缆外护套上间隔印有商标、电缆编号、电缆类别、线规、防火等级、标准； 8.支持以太网供电应用（POE/POE+）； 9.描述：用于办公桌桌面跳线，长度2米 10.为了保证性能的匹配性和稳定性，综合布线光纤系统、铜缆系统应采用同一品牌。 | D25: 一舟、普天天纪、罗格朗 | E25: =E20*2 -> 258 | F25: 个 | H25: 一舟 | I25: SF200-GY | J25: 1.标准：不低于TIA/EIA568-C.2、ISO/IEC11801、IEC60332-1、GB 50311； 2.导体规格：2.导体规格：多股绞合铜线，4×2×24AWG； 3.护套材料：PVC，护套外径：6.3±0.3mm； 4.插头规格：RJ45，8P8C； 5.插拔次数：≥1000次； 6.最高传输频率：不小于250MHz； 7.线缆外护套上间隔印有商标、电缆编号、电缆类别、线规、防火等级、标准； 8.支持以太网供电应用（POE/POE+）； 9.描述：用于办公桌桌面跳线，长度2米 10.为了保证性能的匹配性和稳定性，综合布线光纤系统、铜缆系统应采用同一品牌。 | K25: 响应 | L25: / | M25: 6 | N25: =E25*M25 -> 1548 | O25: 13 | P25: =E25*O25 -> 3354 | Q25: =E25*(M25+O25) -> 4902
A26: 21 | B26: 24口接入交换机-单电源 | C26: ★在不插板卡情况下，单设备交换容量≥336Gbps，包转发率≥120Mpps，提供≥24个千兆电接口、≥4个千兆SFP光接口 1、支持堆叠技术或者虚拟化技术 2、支持 4K 802.1Q VLAN,支持Voice VLAN及Voice VLAN中可以同时识别多厂家的OUI地址，支持端口VLAN、MAC VLAN 3、支持标准IP ACL（基于IP地址的硬件ACL）支持扩展IP ACL（基于IP地址、TCP/UDP端口号的硬件ACL） 4、支持QOS 5、支持一对一、多对一、一对多的镜像 6、支持DHCP Server、DHCP Client、DHCP Snooping、DHCP Relay、DHCP Option82 7、支持广播风暴抑制 8、支持设备登陆管理的AAA安全认证、radius认证、支持802.1x、支持ssh2.0 9、支持STP/RSTP/MSTP协议 10、支持链路聚合（支持静态、动态链路聚合、千兆口聚合） 11、有标准的或私有的邻居发现协议 12、支持VLAN虚接口 13、支持 IPv4 /ipv6静态路由 14、支持OSPFv2、OSPFv3 15、支持SNMPv1/v2/v3，WEB网管，支持命令行接口配置，Telnet，SSH，Console口配置，支持系统日志，分级告警，调试信息输出，NTP/SNTP ★16、提供真实有效的工信部入网证复印件； ★17、原厂质保≥3年 ★18、考虑设备兼容性、项目实施、交付及售后服务，采用与核心交换机同一品牌。 | D26: 华三、锐捷（非睿易） | E26: 12 | F26: 台 | H26: 锐捷 | I26: RG-S2910-24GT4SFP-L | J26: 24个10/100/1000Base-T自适应以太网接口，4个1GE SFP接口； 交换容量:598Gbps/5.98Tbps;包转发率:126Mpps; 支持4K 802.1Q VLAN，支持Port based VLAN，支持MAC based VLAN，支持Voice VLAN，支持GVRP； 支持STP、RSTP、MSTP； 支持DHCP Server ，支持DHCP Client ，支持DHCP Snooping，支持DHCP Relay； 支持VSU虚拟化技术，支持本地堆叠和远程堆叠，支持通过标准业务口实现虚拟化； 支持IPv4/IPv6静态路由、可扩展支持RIP、RIPng、OSPF、OSPFv3协议; 支持端口流量识别，支持端口流量限速，支持802.1p/DSCP/TOS流量分类，支持SP、WRR、DRR、SP+WFQ、 SP+WRR、SP+DRR、RED/WRED队列调度； 支持过滤非法的MAC地址，支持广播风暴抑制，支持BPDU Guard，支持CPP、NFPP，支持端口保护； 支持SNMP、CLI(Telnet/Console)、RMON、SSH、Syslog/Debug、NTP/SNTP、FTP、TFTP、Web、WIS公有云平台管理; | K26: 响应 | L26: / | M26: 58 | N26: =E26*M26 -> 696 | O26: 1487 | P26: =E26*O26 -> 17844 | Q26: =E26*(M26+O26) -> 18540
A27: 22 | B27: 千兆单模光模块 | C27: LC接口，单模千兆光纤（和交换机同品牌） | D27: 华三、锐捷（非睿易） | E27: 24 | F27: 个 | H27: 锐捷 | I27: MINI-GBIC-LX-SM1310 | J27: 1000BASE-LX mini GBIC转换模块（1310nm），10km | K27: 响应 | L27: / | M27: 2 | N27: =E27*M27 -> 48 | O27: 112 | P27: =E27*O27 -> 2688 | Q27: =E27*(M27+O27) -> 2736
A28: 23 | B28: 信号线 | C28: 国标，RVV2*1.0 | D28: 一舟、普天天纪、罗格朗 | E28: 3800 | F28: m | H28: 一舟 | I28: G1807_60227 IEC 53(RVV) 2x1.0 | J28: 国标，RVV2*1.0 | K28: 响应 | L28: / | M28: 2 | N28: =E28*M28 -> 7600 | O28: 3 | P28: =E28*O28 -> 11400 | Q28: =E28*(M28+O28) -> 19000
A29: 24 | B29: 信号线 | C29: 国标，RVVP2*1.0 | D29: 一舟、普天天纪、罗格朗 | E29: 7200 | F29: m | H29: 一舟 | I29: G4407_RVVP2x1.0 | J29: 国标，RVVP2*1.0 | K29: 响应 | L29: / | M29: 2 | N29: =E29*M29 -> 14400 | O29: 6 | P29: =E29*O29 -> 43200 | Q29: =E29*(M29+O29) -> 57600
A30: 25 | B30: 信号线 | C30: 国标，RVVP4*1.0 | D30: 一舟、普天天纪、罗格朗 | E30: 5000 | F30: m | H30: 一舟 | I30: G4607_RVVP4*1.0 | J30: 国标，RVVP4*1.0 | K30: 响应 | L30: / | M30: 2 | N30: =E30*M30 -> 10000 | O30: 9 | P30: =E30*O30 -> 45000 | Q30: =E30*(M30+O30) -> 55000
A31: 26 | B31: 信号线 | C31: 国标，RVVP6*1.0 | D31: 一舟、普天天纪、罗格朗 | E31: 154 | F31: m | H31: 一舟 | I31: G4807_RVVP6x1.0 | J31: 国标，RVVP6*1.0 | K31: 响应 | L31: / | M31: 2 | N31: =E31*M31 -> 308 | O31: 13 | P31: =E31*O31 -> 2002 | Q31: =E31*(M31+O31) -> 2310
A32: 27 | B32: JDG20管 | C32: JDG管，壁厚不小于1.0MM,φ20；含主材、接头、固定扣件（含钢结构扣件）等辅材 | D32: 国产 | E32: 25000 | F32: m | H32: 国产 | I32: JDG20*1.0 | J32: JDG管，壁厚不小于1.0MM,φ20；含主材、接头、固定扣件（含钢结构扣件） | K32: 响应 | L32: / | M32: 10 | N32: =E32*M32 -> 250000 | O32: 3 | P32: =E32*O32 -> 75000 | Q32: =E32*(M32+O32) -> 325000
A33: 28 | B33: 辅材 | C33: 设备安装配套辅材，水晶头，扎带等 | D33: 国产 | E33: 1 | F33: 项 | H33: 国产 | I33: / | J33: / | K33: 响应 | L33: / | M33: 5825 | N33: =E33*M33 -> 5825 | O33: 0 | P33: =E33*O33 -> 0 | Q33: =E33*(M33+O33) -> 5825
B34: 二、智慧安防系统 | N34: =E34*M34 -> 0 | P34: =E34*O34 -> 0
B35: 2.1、视频监控系统 | N35: =E35*M35 -> 0 | P35: =E35*O35 -> 0
A36: 1 | B36: 抗振防抖场景专用摄像机 | C36: 1.设备采用金属机身，主要接口：1个M12航空头网络接口、1个CVBS接口、1个音频输入接口，1个音频输出接口、1个RS485接口、1个报警输入接口、1个报警输出接口、1个SD卡卡槽（内置） 2.内置1/1.8英寸，400万像素CMOS传感器；最大亮度鉴别等级试验≥11级；最大帧率60fps；延时试验小于200ms；照度适应范围不小于140dB 3.外壳防护等级IP66/IP68 4.机身部分碰撞防护等级IK10 5.摄像机应能在额定电源电压DC9V-DC36V范围内正常工作，支持POE供电 6.设备支持红外和暖光补光灯，可通过IE浏览器或客户端切换补光灯类型 7.最低照度试验：彩色：0.0005 lx，黑白：0.0001 lx 8.支持开启、关闭畸变矫正功能 9.防抖功能检查：在水平X轴方向随机抖动频率范围5Hz-62Hz，加速度有效值：5.6m/s²，最大振幅3.39mm；相机配置：2560X1440，最大焦距，座装安装，镜头方向朝下；在图像中指定4个像素点，最大偏移应不超过±1%。 10.防抖功能检查：在水平Y轴方向随机抖动频率范围5Hz-62Hz，加速度有效值：5.6m/s²，最大振幅3.39mm；相机配置：2560X1440，最大焦距，座装安装，镜头方向朝下；在图像中指定4个像素点，最大偏移应不超过±1%。 11.防抖功能检查：在垂直Z轴方向随机抖动频率范围5Hz-26Hz，加速度有效值：5.6m/s²，最大振幅3.39mm；相机配置：2560X1440，最大焦距，座装安装，镜头方向朝下；在图像中指定4个像素点，最大偏移应不超过±1.5%。 12.在彩色模式下，当照度降低至一定值时，设备可自动开启白光灯补光，设备在白天、夜晚均可输出彩色视频图像 13.可通过扫描预览界面上生产的二维码获取设备资料。 14.当移动侦测、进入区域、离开区域、越界区域或区域入侵报警类型设置为人和/或车时，仅当检测区域中出现对应的人和/或车时，才触发报警；当报警产生时，可触发联动白光灯闪烁，白光灯闪烁的时间和频率可设置 15.设备具有APP管理功能，支持在线导入APP、删除APP、加载运行APP、配置APP操作，APP管理操作无需重启设备，操作期间预览画面无中断。 16.设备支持用户自定义最多16个AI算法库，可设置当前生效的算法库和显示当前算法库的运行状态，并支持修改、删除算法库及自定义算法库名称。 17.设备具有良好的环境适应性，工作温度范围可达-40℃～60℃。 | D36: 海康 | E36: 6 | F36: 台 | H36: 海康威视 | I36: DS-2XC7245/KZ | J36: 1.设备采用金属机身，主要接口：1个M12航空头网络接口、1个CVBS接口、1个音频输入接口，1个音频输出接口、1个RS485接口、1个报警输入接口、1个报警输出接口、1个SD卡卡槽（内置）。 2.内置1/1.8英寸，400万像素CMOS传感器。 3.最大亮度鉴别等级试验≥11级。 4.最大帧率60fps。 5.延时试验小于200ms。 6.照度适应范围不小于140dB。 7.外壳防护等级IP66/IP68。 8.机身部分碰撞防护等级IK10。 9.摄像机应能在额定电源电压DC9V-DC36V范围内正常工作，支持POE供电。 10.设备支持红外和暖光补光灯，可通过IE浏览器或客户端切换补光灯类型。 11.最低照度试验：彩色：0.0005 lx，黑白：0.0001 lx。 12.支持开启、关闭畸变矫正功能。 13.防抖功能检查：在水平X轴方向随机抖动频率范围5Hz-62Hz，加速度有效值：5.6m/s²，最大振幅3.39mm；相机配置：2560X1440，最大焦距，座装安装，镜头方向朝下；在图像中指定4个像素点，最大偏移应不超过±1%。 14.防抖功能检查：在水平Y轴方向随机抖动频率范围5Hz-62Hz，加速度有效值：5.6m/s²，最大振幅3.39mm；相机配置：2560X1440，最大焦距，座装安装，镜头方向朝下；在图像中指定4个像素点，最大偏移应不超过±1%。 15.防抖功能检查：在垂直Z轴方向随机抖动频率范围5Hz-26Hz，加速度有效值：5.6m/s²，最大振幅3.39mm；相机配置：2560X1440，最大焦距，座装安装，镜头方向朝下；在图像中指定4个像素点，最大偏移应不超过±1.5%。 16.在彩色模式下，当照度降低至一定值时，设备可自动开启白光灯补光，设备在白天、夜晚均可输出彩色视频图像 17.可通过扫描预览界面上生产的二维码获取设备资料。 18.当移动侦测、进入区域、离开区域、越界区域或区域入侵报警类型设置为人和/或车时，仅当检测区域中出现对应的人和/或车时，才触发报警；当报警产生时，可触发联动白光灯闪烁，白光灯闪烁的时间和频率可设置 19.设备具有APP管理功能，支持在线导入APP、删除APP、加载运行APP、配置APP操作，APP管理操作无需重启设备，操作期间预览画面无中断。 20.设备支持用户自定义最多16个AI算法库，可设置当前生效的算法库和显示当前算法库的运行状态，并支持修改、删除算法库及自定义算法库名称。 21.设备具有良好的环境适应性，工作温度范围可达-40℃～60℃。 | K36: 响应 | L36: / | M36: 210 | N36: =E36*M36 -> 1260 | O36: 3027 | P36: =E36*O36 -> 18162 | Q36: =E36*(M36+O36) -> 19422
A37: 2 | B37: 400万变焦筒型网络摄像机 | C37: 1.支持输出图像分辨率不低于2560x1440 2.最低照度彩色：0.005 lx，最大亮度鉴别等级不小于11级 3.补光距离：红外不低于50 m，白光不低于30 m 4.支持电动变焦 5.具备区域入侵、越界、进入区域、离开区域、人员聚集、快速移动、徘徊、物品移除、物品遗留、停车智能分析功能，当以上智能分析行为达到设定的阈值时，可通过客户端软件或IE浏览器给出报警提示 6.同一场景相同图像质量下设备在H.264或H265编码方式时，开启智能编码功能和不开启智能编码相比，码率节约80% 7.靶面尺寸为1/2.7英寸，内置1个麦克风，具有1个RJ45 网络接口，1路音频输入、1路音频输出、1路报警输入、1路报警输出、1 个复位按钮、1个 SD 卡槽、1个 DC12V 电压输出接口 8.支持H.264、H.265视频编码格式，且具有High Profile编码能力 9.支持电源电源在DC12V±25%范围内变化时正常工作，支持POE 10.IP67防护等级 | D37: 海康 | E37: 68 | F37: 台 | H37: 海康威视 | I37: DS-2CD2645V3-FD | J37: 1.支持输出图像分辨率不低于2560x1440 2.支持电动变焦；焦距&视场角：2.7~13.5 mm，水平视场角：100.2°~33.3°，垂直视场角：53.3°~18.7°，对角视场角：119.0°~38.1° 3.最低照度彩色：0.005 lx，最大亮度鉴别等级不小于11级 4.补光距离：红外不低于50 m，白光不低于30 m 5.具备区域入侵、越界、进入区域、离开区域、人员聚集、快速移动、徘徊、物品移除、物品遗留、停车智能分析功能，当以上智能分析行为达到设定的阈值时，可通过客户端软件或IE浏览器给出报警提示 6.同一场景相同图像质量下设备在H.264或H265编码方式时，开启智能编码功能和不开启智能编码相比，码率节约80% 7.靶面尺寸为1/2.7英寸，内置1个麦克风，具有1个RJ45 网络接口，1路音频输入、1路音频输出、1路报警输入、1路报警输出、1 个复位按钮、1个 SD 卡槽、1个 DC12V 电压输出接口 8.支持H.264、H.265视频编码格式，且具有High Profile编码能力 9.支持电源电源在DC12V±25%范围内变化时正常工作，支持POE 10.IP67防护等级 | K37: 响应 | L37: / | M37: 140 | N37: =E37*M37 -> 9520 | O37: 526 | P37: =E37*O37 -> 35768 | Q37: =E37*(M37+O37) -> 45288
A38: 3 | B38: 热成像摄像机 | C38: ★热成像：分辨率：256×192；焦距：焦距可选：3/7/10mm； 可见光：分辨率：2688*1520，400万；焦距：焦距可选：4mm/8mm/12.4mm； 支持1路音频输入，1路音频输出； 支持2路报警输入，2路报警输出； 外壳防护等级：IP67； 电源电压在DC12V±20%范围内变化时，能正常工作； 可通过IE浏览器在热成像画面中设置点、线段、区域测温规则； 点测温、线测温、区域测温中存在高于或者低于报警或预报警温度时，可在客户端显示不同的报警颜色进行报警提示，联动报警输出，联动录像及联动抓拍； 支持声音联动报警功能。可对智能行为、温度超过阈值、出现高温点等行为进行检测并报警，报警声音可设置，同时支持自定义； ★噪声等效温差为8mk，最小可分辨温差为200mk（（公京检第2401130038号第100条） 热成像视频图像具有白热、黑热、融合1、融合2、彩虹1、铁红2、深褐色等42种显示模式 含安装支架 | D38: 海康 | E38: 199 | F38: 台 | H38: 海康威视 | I38: HM-TD2628-XX/T1A | J38: 1.热成像分辨率：256 × 192；热成像焦距可选值：3mm/7mm/10 mm 2.可见光分辨率：2688 × 1520；可见光焦距可选值：4mm/8mm/12.4 mm 3.报警输入：支持2路DC 0~5 V报警输入；报警输出：支持2路常开型继电器输出，报警类型可设置 4.音频输入：1路3.5 mm Mic in/Line in interface. Line input: 2-2.4 V[p-p]；音频输出：1路3.5mm Impedance: 600Ω 5.电源输入：12 VDC ± 25%，PoE (802.3at, class 4) 6.防护等级：IP67 7.可通过IE浏览器在热成像画面中设置点、线段、区域测温规则 8.点测温、线测温、区域测温中存在高于或者低于报警或预报警温度时，可在客户端显示不同的报警颜色进行报警提示，联动报警输出，联动录像及联动抓拍 9.支持声音联动报警功能。可对智能行为、温度超过阈值、出现高温点等行为进行检测并报警，报警声音可设置，同时支持自定义 10.噪声等效温差(NETD)检验：热成像视频图像噪声等效温差(NETD)≤8mK 11.最小可分辨温差(MRTD)检验：热成像视频图像最小可分辨温差(MRTD)≤200mk 12.热成像视频图像具有白热、黑热、融合1、融合2、彩虹1、铁红2、深褐色等42种显示模式 13.画面分割功能检验：可通过IE浏览器开启或关闭画面分割功能，开启后会将画面平分为12宫格，每个宫格均可输出最高温、最低温及平均温数值 含支架安装 | K38: 响应 | L38: / | M38: 140 | N38: =E38*M38 -> 27860 | O38: 2097 | P38: =E38*O38 -> 417303 | Q38: =E38*(M38+O38) -> 445163
A39: 4 | B39: 高空球型鹰眼 | C39: 1.全景通道最高分辨率不小于6072 x 2640，细节通道最高分辨率不小于3840x2160。 2.全景通道内置4个镜头、靶面尺寸不小于1/1.8英寸的CMOS传感器，细节通道内置1个镜头，靶面尺寸不小于1/1.2英寸的CMOS传感器。 3.设备在全景拼接模式下，垂直视场角不小于110°，水平视场角不小于180°。可将4个全景视频图像进行拼接，实现不小于180°拼接画面显示，并抓拍拼接后的图片。 4.细节通道内置镜头支持不小于45倍光学变倍，镜头最大焦距不小于320mm。 5.设备具有光学防抖功能，将镜头倍率设置为最大，快门设置为1/25s，在振动台振幅不大于0.3°，振动频率不大于10Hz情况下，设备视场角应无明显变化，视频图像在振动过程中应保持稳定清晰 6.设备内置2个雨刷器，雨刷器1可清洁全景通道镜头表面玻璃，雨刷器2可清洁细节通道镜头表面玻璃。 7.设备细节通道水平手控最大速度不小于500°/s，垂直手控最大速度不小于350°/s。 8.设备具备双安装接口，一个为快速旋转安装接口，一个为多孔稳定安装接口。 9.支持不小于300个预置位，支持预置位冻结功能。 10.内置不少于3个GPU芯片。 11.支持智能行为分析功能，智能分析行为类型为区域入侵、越界入侵、进入区域、离开区域等，支持行为分析触发后联动聚焦、联动目标跟踪、报警上传等多种报警触发方式。 12.设备在全景视频图像中点击或框选移动目标至设备开始转动的时间小于0.3s，全景图像检测到且框选出移动目标至设备开始转动时间小于0.3s。 13.设备全景通道支持人员密度检测功能，可开启、关闭人员密度检测功能，最多可设置8个多边形（3～10条边）人员密度检测区域。每个区域的名称、人员数量报警阈值等级（低、中、高等级）可自定义。 14.设备全景通道车辆拥堵检测功能，开启车辆拥堵检测功能后，当设置区域内的车辆滞留时间超过设定值时，可通过IE浏览器给出报警提示。 15.设备可切换智能模式，当更换当前智能模式时设备不需重启，新智能模式即可生效。 16.设备全景通道具有默认拼接、手动拼接、自动拼接3种拼接模式；自动拼接模式下设备可自动获取特征并进行拼接。 17.设备具有AI-ISP图像质量提升功能，在低照度环境下，可自动调节预览场景视频画面中人脸、人体、车辆等目标及预览场景视频画面的区域曝光、亮度、色彩饱和度、对比度、锐度等。 18.设备具有不少于1个RJ45网络接口、1个光纤接口、7路报警输入、2路报警输出、1路音频输入、1路音频输出。内置的北斗定位模块，具有定位功能，可自动获取设备所在位置经纬度信息。 19.防护等级不低于IP67。 | D39: 海康 | E39: 3 | F39: 台 | H39: 海康威视 | I39: DS-2DP1618XS-LD | J39: 1.全景通道最高分辨率不小于6072 x 2640，细节通道最高分辨率不小于3840x2160。 2.全景通道内置4个镜头、靶面尺寸不小于1/1.8英寸的CMOS传感器，细节通道内置1个镜头，靶面尺寸不小于1/1.2英寸的CMOS传感器。 3.设备在全景拼接模式下，垂直视场角不小于110°，水平视场角不小于180°。可将4个全景视频图像进行拼接，实现不小于180°拼接画面显示，并抓拍拼接后的图片。 4.细节通道内置镜头支持不小于45倍光学变倍，镜头最大焦距不小于320mm。 5.设备具有光学防抖功能，将镜头倍率设置为最大，快门设置为1/25s，在振动台振幅不大于0.3°，振动频率不大于10Hz情况下，设备视场角应无明显变化，视频图像在振动过程中应保持稳定清晰。 6.设备内置2个雨刷器，雨刷器1可清洁全景通道镜头表面玻璃，雨刷器2可清洁细节通道镜头表面玻璃。 7.设备细节通道水平手控最大速度不小于500°/s，垂直手控最大速度不小于350°/s。 8.设备具备双安装接口，一个为快速旋转安装接口，一个为多孔稳定安装接口。 9.支持不小于300个预置位，支持预置位冻结功能。 10.内置不少于3个GPU芯片。 11.支持智能行为分析功能，智能分析行为类型为区域入侵、越界入侵、进入区域、离开区域等，支持行为分析触发后联动聚焦、联动目标跟踪、报警上传等多种报警触发方式。 12.设备在全景视频图像中点击或框选移动目标至设备开始转动的时间小于0.3s，全景图像检测到且框选出移动目标至设备开始转动时间小于0.3s。 13.设备全景通道支持人员密度检测功能，可开启、关闭人员密度检测功能，最多可设置8个多边形（3～10条边）人员密度检测区域。每个区域的名称、人员数量报警阈值等级（低、中、高等级）可自定义。 14.设备全景通道车辆拥堵检测功能，开启车辆拥堵检测功能后，当设置区域内的车辆滞留时间超过设定值时，可通过IE浏览器给出报警提示。 15.设备可切换智能模式，当更换当前智能模式时设备不需重启，新智能模式即可生效。 16.设备水平安装在8m高度时，可通过全景通道监控设备正下方8m且水平距离0.5m处的行人目标。 17.设备全景通道具有默认拼接、手动拼接、自动拼接3种拼接模式；自动拼接模式下设备可自动获取特征并进行拼接。 18.设备具有AI-ISP图像质量提升功能，在低照度环境下，可自动调节预览场景视频画面中人脸、人体、车辆等目标及预览场景视频画面的区域曝光、亮度、色彩饱和度、对比度、锐度等。 19.设备支持画中画功能，可通过IE浏览器在细节图像中叠加全景视频图像进行预览。 20.设备可在立体防控系统平台上添加、修改、删除和标注AR标签，包括警务站视频标签、建筑物视频标签、卡口视频标签和普通视频标签，最多可添加500个标签。可通过客户端软件在视频画面上添加定点标签、区域标签、矢量标签和方向标签，并可对标签进行联动操作。 21.当设备调焦或转动时，立体防控系统平台上的AR视频标签应与所标记物体保持相对静止。 22.当通过标签名称对标签进行搜索并选中指定标签时，设备应转动至指定标签方向并聚焦，当点击指定标签时，可查看标签信息并对相关联的设备视频图像进行预览和放大等操作。 23.设备具有偏色矫正功能，可通过手动或自动的方式对采集到的视频进行偏色矫正。 24.设备可对全景通道、细节通道监控画面中的移动标签进行跟踪且跟踪时间、跟踪倍率可设，在跟踪过程中，移动标签始终位于画面中心位置。在细节通道上添加或删除指定标签时，全景通道的相同位置应自动添加或删除该标签。 25.开启补光灯，可识别距设备不小于500m处的人体轮廓。 26.设备具有不少于1个RJ45网络接口、1个光纤接口、7路报警输入、2路报警输出、1路音频输入、1路音频输出。内置的北斗定位模块，具有定位功能，可自动获取设备所在位置经纬度信息。 27.防护等级不低于IP67。 | K39: 响应 | L39: / | M39: 233 | N39: =E39*M39 -> 699 | O39: 28673 | P39: =E39*O39 -> 86019 | Q39: =E39*(M39+O39) -> 86718
A40: 5 | B40: 人脸识别布控球 | C40: 1.单北斗5G双摄便携球套装 2.支持双摄：40倍光学变倍机芯，最大分辨率2560*1440，图像清晰、细腻，低照度，彩色0.0001Lux；全景镜头8M，分辨率2160×3840 3.支持自动彩转黑功能，实现昼夜监控 4.支持人脸比对，可存储30W张人脸名单（含一张1TB TF卡） 5.支持车辆检测及抓拍 6.支持抽烟、佩戴安全帽、玩手机、未穿工作服检测 7.支持3D-DNR 8.支持双TF卡存储 9.支持5G模块（天线内置），可额外扩展1个4G模块 10.配置可拆卸电池，单电池可支持8-9小时连续工作 11.支持双MIC、双扬声器，可选配支持LINE IN\LINE OUT 12.支持自定义语音导入，可关联智能分析报警 13.自带2.4寸LCD显示屏，可支持视频预览，云台控制等，可显示当前电池电量、定位状态、3G/4G/5G状态、录像状态、存储容量、蓝牙状态、平台连接状态、Wi-Fi状态、智能算法模式等 14.底部配置高吸力磁铁，安装便捷 | D40: 海康 | E40: 5 | F40: 台 | H40: 海康威视 | I40: iDS-MCD402-MF/40X+TF-P1/1T/TAY | J40: 1.单北斗5G双摄便携球套装 2.支持双摄：40倍光学变倍机芯，最大分辨率2560*1440，图像清晰、细腻，低照度，彩色0.0001Lux；全景镜头8M，分辨率2160×3840； 3.支持自动彩转黑功能，实现昼夜监控 4.支持人脸比对，可存储30W张人脸名单（已配置1张1TB TF卡） 5.支持车辆检测及抓拍 6.支持抽烟、佩戴安全帽、玩手机、未穿工作服检测 7.支持3D-DNR 8.支持双TF卡存储 9.支持5G模块（天线内置），可额外扩展1个4G模块 10.配置可拆卸电池，单电池可支持8-9小时连续工作 11.支持双MIC、双扬声器，可选配支持LINE IN\LINE OUT 12.支持自定义语音导入，可关联智能分析报警 13.自带2.4寸LCD显示屏，可支持视频预览，云台控制等，可显示当前电池电量、定位状态、3G/4G/5G状态、录像状态、存储容量、蓝牙状态、平台连接状态、Wi-Fi状态、智能算法模式等 14.底部配置高吸力磁铁，安装便捷 | K40: 响应 | L40: / | M40: 233 | N40: =E40*M40 -> 1165 | O40: 18053 | P40: =E40*O40 -> 90265 | Q40: =E40*(M40+O40) -> 91430
...

Sheet 软件-报价汇总表
A1: 密级：公开
A2: 阳光电源智慧园区一期建设清单（软件）报价清单
A3: 序号 | B3: 项目内容 | C3: 数量 | D3: 单位 | E3: 税率 | F3: 未税单价 | G3: 未税小计 | H3: 含税小计
A4: 1 | B4: 产品费用 | C4: 1 | D4: 项 | E4: 0.13 | F4: ='软件-产品费用报价明细'!G11 -> 2270000 | G4: =C4*F4 -> 2270000 | H4: =G4*(1+E4) -> 2565100
A5: 2 | B5: 实施费用 | C5: 1 | D5: 项 | E5: 0.13 | F5: ='软件-实施费用报价明细'!N36 -> 1455000 | G5: =C5*F5 -> 1455000 | H5: =G5*(1+E5) -> 1644150
A6: 3 | B6: 运维费（第四到第五年） | C6: 2 | D6: 年 | E6: 0.13 | F6: =G4*5% -> 113500 | G6: =C6*F6 -> 227000 | H6: =G6*(1+E6) -> 256510
A7: 4 | B7: 合计 | G7: =SUM(G4:G6) -> 3952000 | H7: =SUM(H4:H6) -> 4465760
A8: 报价须知： 1、三年免费维护（即一期整体验收后36个月），第四年开始维护费用比率为产品费用的【5】 %；即第四年开始每年收取【113500】元；维保协议根据需要另行签订，维保价格不高于本次报价。 2、报价已包含完成本项目的一切费用； 3、报价有效期：90天； 4、付款方式：电汇，合同签订后预付合同对应金额20%，蓝图完成经客户确认后支付合同对应金额20%，上线完成经客户确认后支付合同对应金额30%，上线6个月保驾护航完成经客户确认后支付合同对应金额20%，自上线验收合格1年后支付10%。 5、本项目一期的所有功能需求及产品，均由报价人提供； 6、实施费用为人天单价，后续增加期数（如有）实施费用以不高于本次人天价格执行； 7、人天费用不得已“赠送、总价折扣、缩减人天量形式”进行优惠； 8、单价需符合市场规律，价格不得以免费赠送形式报价； 9、本次项目具体清单，请按自己格式拟定，并且与本表一起盖章作为投标价格标；

Sheet 软件-产品费用报价明细
A1: 序号 | B1: 软件/模块名称 | C1: 版本号 | D1: 数量 | E1: 单位 | F1: 未税单价 | G1: 未税合计 | H1: 是否买断 | I1: 备注
A2: =ROW()-1 -> 1 | B2: 智慧物流 | C2: V1.0 | D2: 1 | E2: 套 | F2: 450000 | G2: =D2*F2 -> 450000 | H2: 否 | I2: 如是否买断为“否”，则报价需包含运维阶段（第一至五年）的所有订阅费用
A3: =ROW()-1 -> 2 | B3: 智慧消防 | C3: V1.0 | D3: 1 | E3: 套 | F3: 300000 | G3: =D3*F3 -> 300000 | H3: 否
A4: =ROW()-1 -> 3 | B4: 智慧安防 | C4: V1.0 | D4: 1 | E4: 套 | F4: 250000 | G4: =D4*F4 -> 250000 | H4: 否
A5: =ROW()-1 -> 4 | B5: 宿舍管理 | C5: V1.0 | D5: 1 | E5: 套 | F5: 150000 | G5: =D5*F5 -> 150000 | H5: 否
A6: =ROW()-1 -> 5 | B6: 外协人员管理 | C6: V1.0 | D6: 1 | E6: 套 | F6: 300000 | G6: =D6*F6 -> 300000 | H6: 否
A7: =ROW()-1 -> 6 | B7: 报表管理模块 | C7: V1.0 | D7: 1 | E7: 套 | F7: 250000 | G7: =D7*F7 -> 250000 | H7: 否
A8: =ROW()-1 -> 7 | B8: 系统管理模块 | C8: V1.0 | D8: 1 | E8: 套 | F8: 20000 | G8: =D8*F8 -> 20000 | H8: 否
A9: =ROW()-1 -> 8 | B9: 移动及多屏应用 | C9: V1.0 | D9: 1 | E9: 套 | F9: 50000 | G9: =D9*F9 -> 50000 | H9: 否
A10: =ROW()-1 -> 9 | B10: 智慧园区平台 | C10: V1.0 | D10: 1 | E10: 套 | F10: 500000 | G10: =D10*F10 -> 500000 | H10: 否
A11: 未税合计 | G11: =SUM(G2:G10) -> 2270000

Sheet 软件-实施费用报价明细
A1: 密级：秘密
A2: 【阳光电源智慧园区一期建设项目】人天资源投入价格清单
A3: 项目人员姓名 | B3: 项目角色 | C3: 实施方式 | D3: 人天数量（人/天） | M3: 人天费用（未税）
D4: 项目启动 | E4: 需求分析 | F4: 方案设计 | G4: 系统开发 | H4: 系统测试 | I4: 上线准备 | J4: 上线推广 | K4: 上线后现场运维【6】个月 | L4: 人天汇总 | M4: 实施单价 （人/天/元） | N4: 实施费用 小计(元)
B5: 自然周 | C5: 现场/远程 | D5: Week1—Week2 | E5: Week3—Week6 | F5: Week6—Week12 | G5: Week8—Week32 | H5: Week17—Week36 | I5: Week20—Week37 | J5: Week23—Week40 | K5: Week41—Week64
B6: 项目经理 | C6: 现场 | D6: 8 | E6: 10 | F6: 12 | G6: 20 | H6: 8 | I6: 5 | J6: 15 | K6: 0 | L6: =SUM(D6:K6) -> 78 | M6: 2000 | N6: =M6*L6 -> 156000
C7: 远程 | D7: 0 | E7: 0 | F7: 0 | G7: 0 | H7: 0 | I7: 0 | J7: 0 | K7: 0 | L7: =SUM(D7:K7) -> 0 | M7: 2000 | N7: =M7*L7 -> 0
B8: 业务分析师 | C8: 现场 | D8: 3 | E8: 5 | F8: 0 | G8: 0 | H8: 0 | I8: 0 | J8: 0 | K8: 0 | L8: =SUM(D8:K8) -> 8 | M8: 2000 | N8: =M8*L8 -> 16000
C9: 远程 | D9: 0 | E9: 5 | F9: 15 | G9: 5 | H9: 0 | I9: 0 | J9: 0 | K9: 0 | L9: =SUM(D9:K9) -> 25 | M9: 2000 | N9: =M9*L9 -> 50000
B10: 方案架构师 | C10: 现场 | D10: 3 | E10: 0 | F10: 0 | G10: 0 | H10: 0 | I10: 0 | J10: 0 | K10: 0 | L10: =SUM(D10:K10) -> 3 | M10: 2000 | N10: =M10*L10 -> 6000
C11: 远程 | D11: 0 | E11: 10 | F11: 15 | G11: 0 | H11: 0 | I11: 0 | J11: 0 | K11: 0 | L11: =SUM(D11:K11) -> 25 | M11: 2000 | N11: =M11*L11 -> 50000
B12: 产品经理 | C12: 现场 | D12: 0 | E12: 5 | F12: 0 | G12: 0 | H12: 0 | I12: 0 | J12: 0 | K12: 0 | L12: =SUM(D12:K12) -> 5 | M12: 2000 | N12: =M12*L12 -> 10000
C13: 远程 | D13: 3 | E13: 5 | F13: 15 | G13: 10 | H13: 0 | I13: 0 | J13: 0 | K13: 0 | L13: =SUM(D13:K13) -> 33 | M13: 2000 | N13: =M13*L13 -> 66000
B14: UI工程师 | C14: 现场 | D14: 0 | E14: 0 | F14: 0 | G14: 0 | H14: 0 | I14: 0 | J14: 0 | K14: 0 | L14: =SUM(D14:K14) -> 0 | M14: 1500 | N14: =M14*L14 -> 0
C15: 远程 | D15: 0 | E15: 3 | F15: 10 | G15: 2 | H15: 0 | I15: 0 | J15: 0 | K15: 0 | L15: =SUM(D15:K15) -> 15 | M15: 1500 | N15: =M15*L15 -> 22500
B16: 开发工程师1 | C16: 现场 | D16: 0 | E16: 0 | F16: 0 | G16: 0 | H16: 0 | I16: 0 | J16: 0 | K16: 0 | L16: =SUM(D16:K16) -> 0 | M16: 2000 | N16: =M16*L16 -> 0
C17: 远程 | D17: 0 | E17: 0 | F17: 0 | G17: 60 | H17: 10 | I17: 2 | J17: 0 | K17: 0 | L17: =SUM(D17:K17) -> 72 | M17: 2000 | N17: =M17*L17 -> 144000
B18: 开发工程师2 | C18: 现场 | D18: 0 | E18: 0 | F18: 0 | G18: 0 | H18: 0 | I18: 0 | J18: 0 | K18: 0 | L18: =SUM(D18:K18) -> 0 | M18: 2000 | N18: =M18*L18 -> 0
C19: 远程 | D19: 0 | E19: 0 | F19: 0 | G19: 60 | H19: 10 | I19: 2 | J19: 0 | K19: 0 | L19: =SUM(D19:K19) -> 72 | M19: 2000 | N19: =M19*L19 -> 144000
B20: 开发工程师3 | C20: 现场 | D20: 0 | E20: 0 | F20: 0 | G20: 0 | H20: 0 | I20: 0 | J20: 0 | K20: 0 | L20: =SUM(D20:K20) -> 0 | M20: 2000 | N20: =M20*L20 -> 0
C21: 远程 | D21: 0 | E21: 0 | F21: 0 | G21: 60 | H21: 10 | I21: 2 | J21: 0 | K21: 0 | L21: =SUM(D21:K21) -> 72 | M21: 2000 | N21: =M21*L21 -> 144000
B22: 开发工程师4 | C22: 现场 | D22: 0 | E22: 0 | F22: 0 | G22: 0 | H22: 0 | I22: 0 | J22: 0 | K22: 0 | L22: =SUM(D22:K22) -> 0 | M22: 2000 | N22: =M22*L22 -> 0
C23: 远程 | D23: 0 | E23: 0 | F23: 0 | G23: 60 | H23: 10 | I23: 2 | J23: 0 | K23: 0 | L23: =SUM(D23:K23) -> 72 | M23: 2000 | N23: =M23*L23 -> 144000
B24: 测试工程师1 | C24: 现场 | D24: 0 | E24: 0 | F24: 0 | G24: 0 | H24: 0 | I24: 0 | J24: 0 | K24: 0 | L24: =SUM(D24:K24) -> 0 | M24: 1200 | N24: =M24*L24 -> 0
C25: 远程 | D25: 0 | E25: 0 | F25: 0 | G25: 0 | H25: 30 | I25: 0 | J25: 0 | K25: 0 | L25: =SUM(D25:K25) -> 30 | M25: 1200 | N25: =M25*L25 -> 36000
B26: 测试工程师2 | C26: 现场 | D26: 0 | E26: 0 | F26: 0 | G26: 0 | H26: 0 | I26: 0 | J26: 0 | K26: 0 | L26: =SUM(D26:K26) -> 0 | M26: 1200 | N26: =M26*L26 -> 0
C27: 远程 | D27: 0 | E27: 0 | F27: 0 | G27: 0 | H27: 30 | I27: 0 | J27: 0 | K27: 0 | L27: =SUM(D27:K27) -> 30 | M27: 1200 | N27: =M27*L27 -> 36000
B28: 实施顾问 | C28: 现场 | D28: 0 | E28: 0 | F28: 0 | G28: 0 | H28: 0 | I28: 40 | J28: 30 | K28: 0 | L28: =SUM(D28:K28) -> 70 | M28: 1500 | N28: =M28*L28 -> 105000
C29: 远程 | D29: 0 | E29: 0 | F29: 0 | G29: 0 | H29: 0 | I29: 0 | J29: 0 | K29: 0 | L29: =SUM(D29:K29) -> 0 | M29: 1500 | N29: =M29*L29 -> 0
B30: 实施工程师 | C30: 现场 | D30: 0 | E30: 0 | F30: 0 | G30: 0 | H30: 0 | I30: 0 | J30: 0 | K30: 0 | L30: =SUM(D30:K30) -> 0 | M30: 1500 | N30: =M30*L30 -> 0
C31: 远程 | D31: 0 | E31: 0 | F31: 0 | G31: 0 | H31: 0 | I31: 40 | J31: 30 | K31: 0 | L31: =SUM(D31:K31) -> 70 | M31: 1500 | N31: =M31*L31 -> 105000
B32: 运维工程师 | C32: 现场 | D32: 0 | E32: 0 | F32: 0 | G32: 0 | H32: 0 | I32: 0 | J32: 0 | K32: 132 | L32: =SUM(D32:K32) -> 132 | M32: 1500 | N32: =M32*L32 -> 198000
C33: 远程 | D33: 0 | E33: 0 | F33: 0 | G33: 0 | H33: 0 | I33: 0 | J33: 0 | K33: 0 | L33: =SUM(D33:K33) -> 0 | M33: 1500 | N33: =M33*L33 -> 0
B34: 项目专员 | C34: 现场 | D34: 0 | E34: 0 | F34: 0 | G34: 0 | H34: 0 | I34: 0 | J34: 0 | K34: 0 | L34: =SUM(D34:K34) -> 0 | M34: 1500 | N34: =M34*L34 -> 0
C35: 远程 | D35: 0 | E35: 0 | F35: 0 | G35: 0 | H35: 0 | I35: 10 | J35: 5 | K35: 0 | L35: =SUM(D35:K35) -> 15 | M35: 1500 | N35: =M35*L35 -> 22500
K36: 人天量总计 | L36: =SUM(L6:L35) -> 827 | M36: 费用总计 | N36: =SUM(N6:N35) -> 1455000
A37: 甲方备注： | C37: 请合理安排项目计划，人力投入需要具体到每个人员的每周投入
C38: 本项目报价清单中单价固定，招标范围内总价包干。项目交付中若有需求量变更按投标单价据实结算；
C39: 项目费用需要在表中具体到每个人员的实施费用，费用包含差旅食宿等一切费用，后期不再接受报价外费用。
A40: 乙方备注： | C40: 实施费用增值税专票税率：【13】 %
...

Sheet 附录五硬件场景需求表
A1: 项目范围 | B1: 系统 | C1: 序号 | D1: 设施设备 | E1: 数量 | F1: 涉及硬件类型
A2: 智慧消防系统 | B2: 消防水系统 | C2: 1 | D2: 消防水池 | E2: 水池数量 | F2: 水位仪传感器7个（包括电动力1个）
C3: 2 | D3: 消防水箱 | E3: 水箱数量 | F3: 水位仪传感器6个（包括电动力1个）、出水管流量传感器12个（包括电动力2个）
C4: 3 | D4: 消防泵/喷淋泵 | E4: 泵数量 | F4: 电气监控28个（包括电动力4个）
C5: 4 | D5: 稳压泵 | E5: 泵数量 | F5: 电气监控、启停状态/次数监测28个（包括电动力4个）
C6: 5 | D6: 隔膜气压罐 | E6: 罐体数量 | F6: 14个（包括电动力2个）
C7: 6 | D7: 配电柜 | E7: 柜体数量 | F7: 电气监控9个（包括电动力2个）
C8: 7 | D8: 控制柜 | E8: 柜体数量 | F8: 电气监控、远程手自动变更28个（包括电动力4个）
C9: 8 | D9: 消防测试栓 | E9: 屋面测试栓数量 | F9: 压力传感器 30
C10: 9 | D10: 末端测试 | E10: 末端数量 | F10: 压力传感器 200
C11: 10 | D11: 消防泵房 | E11: 泵房数量 | F11: 9个（包括电动力2个消防泵房/稳压泵房）
C12: 11 | D12: 进水阀 | E12: 水池、水箱水量 | F12: 流量计、压力传感器13个（包括电动力2个）
C13: 12 | D13: 关键管路（进出水主管） | E13: 进出水管数量 | F13: 阀门启闭状态检测、压力传感器、流量监测（50个阀门启闭状态、压力传感器、流量监测）
C14: 13 | D14: 湿式报警阀\预作用阀 | E14: 报警阀数量 | F14: 上下腔压力监测、判断，水力警铃传感69个报警阀、69个水力警铃
... C16: 15 | D16: 消防水炮主机 | E16: 水炮数量 | F16: 电磁阀启动信号 2
B17: 全淹没气灭 | C17: 16 | D17: 环境检测 | E17: 全淹没房间数量 | F17: 氧浓度监测接入消防平台 33个
C18: 17 | D18: 电磁阀、泄压口 | E18: 瓶体数量 | F18: 压力传感器/电磁阀启动监测（100个）
B19: 排烟系统 | C19: 18 | D19: 排烟风机 | E19: 风机数量 | F19: 排烟风速计量（含风向）110
C20: 19 | D20: 电动挡烟垂壁 | E20: / | F20: 释放状态
B21: 防火卷帘 | F21: 释放状态
B22: 排水系统 | C22: 20 | D22: 雨水截止阀 | F22: 自动灭火后联动对应雨水截止阀关闭
C23: 21 | D23: 关键机房、泵房排水泵 | E23: 水泵数量 | F23: 启闭监测 24个（6个消防泵房）
C24: 22 | D24: 关键机房、泵房 | F24: 防水浸监测（10个）
B25: 可燃气体 | C25: 23 | D25: 可燃气体报警主机 | E25: 主机数量 | F25: 可燃气体报警主机接入消防平台 8个
C26: 24 | D26: 可燃气体管路 | E26: 燃气管道数量 | F26: 燃气、压缩空气等管道加装可联动电磁阀 （2个）
B27: 电气火灾监控 | F27: 在线电压、剩余电流检测、电缆温度检测 数量太多400+
B28: 视频监控系统 | C28: 25 | D28: 自动报警系统 | F28: 自动报警系统联动范围摄像头、算法判断 数量太多1000+
C29: 26 | D29: 安全出口堵塞 | F29: 摄像头算法判断安全出口、疏散通道 150+
C30: 27 | D30: 屋面光伏摄像头 | F30: 烟雾、火焰摄像头 （60+）
D31: 电动自行车充电区 | F31: 40+
D32: 电动叉车充电区 | F32: 8
D33: AGV充电区 | F33: 15
D34: 电动汽车充电区 | F34: 60+
D35: 厨房灶台 | F35: 15+
B36: 关键岗位通讯设备 | C36: 28 | D36: 手持设备 | F36: 关键岗位用于设备点检、救援联动、保修维修等功能(12-15台）
A37: 智慧安防系统 | B37: 周界防护 | C37: 29 | D37: 震动光纤 | F37: 光纤、接收器等（4000米周长）
C38: 30 | D38: 周界监控 | F38: 基于算法和震动光纤提示报警（40台摄像机）
C39: 31 | D39: 红外对射报警 | F39: 对车辆道闸下口、窄小区域提示报警（11）
B40: 全面监控 | C40: 32 | D40: 屋面 | F40: 鹰眼相机 提供园区概状视频监控3-4台
C41: 33 | D41: 车道相机 | F41: 对违停、逆行等行为进行算法判断20台
...
