Workbook

Sheet 总价汇总表
A1: 密级：公开
A2: XX智慧园区一期建设清单报价清单-汇总表
A3: 序号 | B3: 系统名称 | C3: 税率 | D3: 不含税总价 | E3: 含税总价 | F3: 备注
A4: 1 | B4: 硬件部分 | C4: 0.13 | D4: ='硬件-报价汇总表'!D7 -> 8509539.1 | E4: =D4*(1+C4) -> 9615779.1
A5: 2 | B5: 软件部分 | C5: 0.13 | D5: 2550183 | E5: =D5*(1+C5) -> 2881706.8
A6: 3 | B6: 总计（元） | D6: =SUM(D4:D5) -> 11059722 | E6: =SUM(E4:E5) -> 12497486
D7: 按此未税金额投标
C9: 施工合计未税 | D9: 材料合计未税
C10: ='硬件-报价明细'!N115 -> 1686598 | D10: ='硬件-报价明细'!P115 -> 6822941.1 | E10: =SUM(C10:D10) -> 8509539.1
C12: =C10*1.13 -> 1905855.7 | D12: =D10*1.13 -> 7709923.4 | E12: =SUM(C12:D12) -> 9615779.1
C14: 111 | D14: 667
D16: =1180-C14-D14 -> 402

Sheet 硬件-报价汇总表
A1: 密级：公开
A2: XX智慧园区一期建设清单（硬件）报价清单
A3: 序号 | B3: 系统名称 | C3: 税率 | D3: 不含税总价 | E3: 备注
A4: 1 | B4: 智慧消防及物联系统 | C4: 0.13 | D4: =SUM('硬件-报价明细'!Q7:Q33) -> 3180591.7
A5: 2 | B5: 智慧安防系统 | C5: 0.13 | D5: =SUM('硬件-报价明细'!Q36:Q110) -> 5271075.4
A6: 3 | B6: 等保测评 | C6: 0.13 | D6: ='硬件-报价明细'!Q112 -> 57872
A7: 4 | B7: 不含税总计（元） | D7: =SUM(D4:D6) -> 8509539.1
A8: 报价须知： 1、报价前请仔细阅读《硬件-报价说明》。 2、付款方式：电汇，初验完成后支付合同对应金额的70%（且累积支付不超实际产值70%），终验决算完成支付至决算对应金额的90%，剩余10%作为质保金，自竣工验收通过满1年后如无质量问题、无发生甲方代扣代付维修费用，甲方无息支付质保金。详见SOW内约定。

Sheet 硬件-报价说明
A1: 密级：公开
A2: XX智慧园区一期建设清单（硬件） 投标报价说明
A3: 说明 | B3: 本报价说明作为投标文件的重要组成部分，与招标文件、技术规格书及合同具有同等效力。投标人须仔细阅读并充分理解所有条款，报价提交后视为已完全响应。
A4: 一、报价范围与计价模式
A5: 总价包含范围 | B5: 1、投标总价含设备、材料等运输、卸货、搬用、保存、安装、集成调试，通断测试，福禄克测试，质保期内保证项目稳定运行的所需全部费用。
B6: 2、投标总价含设备、线缆、柜、箱体等的机打标签、整理等工作，达到《XX弱电施工工艺参考图册》、《XX厂区及办公区弱电标识标签规则》要求。
B7: 3、投标总价含施工、技术支持、操作人员培训等，含3年原厂质保运维服务等，故障1小时响应，故障处理6小时内完成。
B8: 4、投标总价含材料费、施工费、调试费、措施费、安全文明施工费、税金、总包管理服务费、施工用水电费用、辅材、实现平台功能前端设备调整（角度、位置等）等项目交付前一切费用，辅材包括但不限于六类非屏蔽水晶头、音频接插头、各种螺丝、吊卡、丝杆、铁皮卡、自攻螺丝、膨胀管、绝缘子、接线端子、弓背、管道支持柱、拉爆三件套、膨胀螺栓、机柜螺丝、垫片、绝缘胶布、透明胶布、扎带、标签纸、魔术贴、网线固线器、标签机、钩钉、刚性卡箍、螺丝杆帽、PVC线槽、自喷漆、明装86盒、明装86盒盖板、弯管器、墙面开孔及开槽及修复、地面开挖及绿化恢复、其他施工工具等辅材。
A9: “实体净量+量价分离”计价规则 | B9: 本项目所有强弱电管、线、桥架类材料实行“实体净量+量价分离”计价模式，清单工程量仅依据设计图纸标注的水平/垂直投影净长度计算，施工中必然发生的桥架（含管道）内敷设弯曲、桥架上翻下翻、机柜与终端处的预留长度，以及各类管、线、桥架类材料的合理损耗等，其工程量与费用均视为投标人施工技术的一部分，须在编制综合单价时一并考虑（相关费用在材料单价中体现），结算时不再单独计量。
A10: 综合单价包干 | B10: 综合单价为包干价，包括但不限于完成工程量清单子目特征描述、工作内容描述等全部内容所需的人工费、材料费（甲供材除外）、机械费、管理费、利润、税金等全部费用，特征描述中不完善，但按常规属于完成该对应子目所必须有的工作内容，视为已包含在综合单价中。
A11: 二、技术要求与执行标准
A12: 工艺与标签规范 | B12: 施工须符合《XX弱电施工工艺参考图册》、《XX厂区及办公区弱电标识标签规则》，含设备、线缆、柜体等机打标签及整理。
A13: 施工界面与现场踏勘 | B13: 投标人应踏勘现场，充分了解施工移交界面及标准（如地面、墙面找平层厚度可能产生的变化），相关费用包含在报价中。
A14: 深化设计与规范要求 | B14: 本工程工程量清单项目仅列出主要包含范围，投标单位应结合设计图及标准作法进行理解，投标单位需按规范及设计要求深化施工工艺及对应施工工艺作法，本部分费用已含在本合同总价中。
A15: 三、投标报价与格式要求
A16: 报价格式 | B16: 报价时按照甲方提供表格格式要求进行报价；乙方提供excel表格报价电子档文件（可编辑版本即可），并提供word版本盖章报价扫描件（包含表头：序号、项目名称、工程量、单位、投标品牌、投标型号、参数（响应/正偏离/负偏离）、正/负偏离参数项、材料未税单价、施工未税单价、未税小计、备注）。
A17: 单价一致性 | B17: 清单中所列相同项目，投标单位报价须保持一致，若投标报价不一致，则以报价较低的单价计算并调整总价。
A18: 链接正确性 | B18: 投标清单中的链接由投标人自行负责核实。
A19: 金额精度 | B19: 工程量清单内所有工程量及金额均需保留两位小数，并以显示精度为准。
A20: 四、风险与变更条款
A21: 未尽事宜 | B21: 其他未尽事宜详见招标技术规格书及其他招标材料。
A22: 设计冲突处理 | B22: 清单中的所有主材要求详见图纸说明、技术规范书要求及清单描述，如相关描述有冲突时，按高标准执行。
A23: 材料及品牌更换 | B23: 材料如招标人提出替换时，费用只计算材料价差和税金，不再计取其他费用。
A24: 施工风险 | B24: 1、投标人已综合考虑施工中可能发生的各类风险（如材料损耗、预留长度、现场条件变化等），相关费用已包含在报价中。
B25: 2、合同期内人工、材料、机械和临时设施及施工水电费的费用、费率等价格要素的波动，合同执行期内一律不予调整。
B26: 3、施工费含白天施工、夜间施工、节假日施工等。

Sheet 硬件-报价明细
A1: 密级：公开 | H1: 乙方必填项 | I1: 乙方必填项 | J1: 乙方必填项 | K1: 乙方必填项 | L1: 乙方必填项 | M1: 乙方必填项 | O1: 乙方必填项 | Q1: 乙方必填项
A2: 序号 | B2: 设备名称 | C2: 技术参数要求 | D2: 推荐品牌 | E2: 数量 | F2: 单位 | G2: 备注 | H2: 投标品牌 | I2: 投标型号 | J2: 投标参数 | K2: 参数（响应/正偏离/负偏离） | L2: 正/负偏离 参数项 | M2: 施工未税单价 | N2: 施工合价未税 | O2: 材料未税单价 | P2: 材料合价未税 | Q2: 未税小计 | R2: 备注
B3: 一、智慧消防及物联系统
A4: 1 | B4: 用户信息传输装置 | C4: 壁挂式，用于消防远程监控，通过RS232端口实时监测所连接火灾报警控制器的报警信息，并通过有线网络传递到监控平台。满足GB26875-2011标准。 | D4: 主机信号采集数量：青鸟自动报警主机*20，青岛鼎信自动报警主机*1，利达自动报警主机*1，各品牌需对应使用适配的用户信息传输硬件 | E4: 24 | F4: 台 | H4: 青鸟 | I4: JBF5891 | J4: 用于实现火灾报警控制器与云端进行有线通讯（网线）的联网设备，DC24V供电，外型尺寸 136*89*36(mm)。 | K4: 响应 | M4: 131.84 | N4: =E4*M4 -> 3164.16 | O4: 2622.5 | P4: =E4*O4 -> 62940 | Q4: =ROUND((M4+O4)*E4,2) -> 66104.16
E5: 1 | F5: 台 | H5: 鼎信 | I5: TS-CS-8101 | J5: 主电电源：额定工作电压 AC220V/50Hz，宽电压范围 AC176V～AC420V 可接入； 备电电源：12V/2.3Ah 蓄电池； 容量：配接一台控制器； 液晶规格：320×480 彩色液晶屏； 使用环境：温度：0℃~+40℃； 相对湿度≤95%，不凝露； 外形尺寸：270.0mm× 190.0mm× 62.5mm(长× 宽× 高)； 安装孔距：水平间距 226.0mm，垂直间距 93.0mm； 重量：约 2.1kg； 外壳防护等级：IP30； | K5: 响应 | M5: 131.84 | N5: =E5*M5 -> 131.84 | O5: 7255 | P5: =E5*O5 -> 7255 | Q5: =ROUND((M5+O5)*E5,2) -> 7386.84 | S5: 增加项
E6: 1 | F6: 台 | H6: 利达 | I6: LD6920 | J6: DC 24V；< 200mA； CAN总线、RS232串口、开关量输入；支持 GPRS/2G、TCP/IP、电话线（可选配） | K6: 响应 | M6: 131.84 | N6: =E6*M6 -> 131.84 | O6: 5243 | P6: =E6*O6 -> 5243 | Q6: =ROUND((M6+O6)*E6,2) -> 5374.84 | S6: 增加项
A7: 2 | B7: 全局网络控制器 | C7: 1.名称：全局网络控制器 2.参数要求：单核 A8@1GHz，1GB DDR3 / 4GB microSD，2× 百兆，2×RS-485，可扩展4 个 I/O/ 现场总线模块。协议：BACnet IP/MS/TP + Modbus TCP/RTU + LonWorks + KNX + SNMP + oBIX，编程：Niagara 图形化编程，功能极强，适合复杂联锁 / 算法。满足现场现场功能所需的点位授权费 | D7: 霍尼韦尔、江森、西门子 | E7: 9 | F7: 台 | H7: 霍尼韦尔 | I7: ECC200-PE | J7: 边缘网络控制器，3条RS485总线；支持编程数据管理等功能 | K7: 响应 | M7: 32.96 | N7: =E7*M7 -> 296.64 | O7: 7240.88 | P7: =E7*O7 -> 65167.92 | Q7: =ROUND((M7+O7)*E7,2) -> 65464.56
A8: 3 | B8: 可编程网络控制器 | C8: 通讯接口：100M以太网，双网口 协议：BACnetIP/Modbus-TCP 扩展接口通讯：控制器内部协议 DI输入接口：数量最大24路，干接点接入 DO控制接口：8路，继电器负载能力2A/30VDC UI输入接口：最大16路，支持电阻型温度NTC20K，电压型湿度0~10V，电压型CO2,0~10V，电压型CO 0~10V,电流型水压4~20mA，电流型流量计4~20mA，执行器0~10V和2~10V反馈 AO输出接口：8路，支持4~20mA和0~10V输出 RS485接口数量：2个，其中一个支持多合一传感器接入，另外一路备用 支持PLC功能，支持PLC逻辑编程 尺寸：225x115x 57mm 外壳原料： UL 94 ABS 电源：DC24V/3A 重量：500g | D8: 霍尼韦尔、江森、西门子 | E8: 129 | F8: 台 | H8: 霍尼韦尔 | I8: WEBs系列控制器 | J8: 通讯接口：100M以太网，双网口 协议：BACnetIP/Modbus-TCP 扩展接口通讯：控制器内部协议 DI输入接口：数量最大24路，干接点接入 DO控制接口：8路，继电器负载能力2A/30VDC UI输入接口：最大16路，支持电阻型温度NTC20K，电压型湿度0~10V，电压型CO2,0~10V，电压型CO 0~10V,电流型水压4~20mA，电流型流量计4~20mA，执行器0~10V和2~10V反馈 AO输出接口：8路，支持4~20mA和0~10V输出 RS485接口数量：2个，其中一个支持多合一传感器接入，另外一路备用 | K8: 响应 | M8: 32.96 | N8: =E8*M8 -> 4251.84 | O8: 5424.7 | P8: =E8*O8 -> 699786.3 | Q8: =ROUND((M8+O8)*E8,2) -> 704038.14 | S8: 没有点表，满配接入点56个可以打7折
A9: 4 | B9: 可编程控制盘 | C9: 1、包含：空开、导轨及接线端子 2、国产优质箱体，根据实际安装设备测量后成套定制 | D9: 国产一线品牌，空开品牌为良信、正泰、公牛 | E9: 129 | F9: 台 | H9: 定制 | I9: DDC-Panel-XL | J9: 1、包含：空开、导轨及接线端子 2、国产优质箱体，根据实际安装设备测量后成套定制 | K9: 响应 | M9: 164.8 | N9: =E9*M9 -> 21259.2 | O9: 1485.31 | P9: =E9*O9 -> 191604.99 | Q9: =ROUND((M9+O9)*E9,2) -> 212864.19
A10: 5 | B10: 电源模块 | C10: 输入：85–264VAC（全球宽压），50/60Hz 输出：24VDC 可调（约 24–26V） 电流：1.3A / 2.5A / 4A（常用 4A 配 DDC） 保护：过压、短路、过载、过热（自恢复） EMC：EN61000-6-2、EN61000-4 系列，工业级 安装：35mm DIN 导轨 外壳：UL94 V-0 阻燃塑料 工作温度：-20℃ ~ +60℃ | D10: 霍尼韦尔、江森、西门子 | E10: 129 | F10: 台 | H10: 霍尼韦尔 | I10: 24VDC | J10: 输入：85–264VAC（全球宽压），50/60Hz 输出：24VDC 可调（约 24–26V） 电流：1.3A / 2.5A / 4A（常用 4A 配 DDC） 保护：过压、短路、过载、过热（自恢复） EMC：EN61000-6-2、EN61000-4 系列，工业级 安装：35mm DIN 导轨 外壳：UL94 V-0 阻燃塑料 工作温度：-20℃ ~ +60℃ | K10: 响应 | M10: 21.63 | N10: =E10*M10 -> 2790.27 | O10: 102.8 | P10: =E10*O10 -> 13261.2 | Q10: =ROUND((M10+O10)*E10,2) -> 16051.47 | S10: 修改品牌
A11: 6 | B11: 液位开关 | C11: 电缆长度：3M；电缆类型：PVC（聚氯乙烯）；包装形式：纸箱批量简易包装； | D11: 霍尼韦尔、江森、西门子 | E11: 13 | F11: 台 | H11: 霍尼韦尔 | I11: HSL-LS05 | J11: 电缆长度：5M；电缆类型：PVC（聚氯乙烯）；包装形式：纸箱批量简易包装； | K11: 响应 | M11: 154.5 | N11: =E11*M11 -> 2008.5 | O11: 169.89 | P11: =E11*O11 -> 2208.57 | Q11: =ROUND((M11+O11)*E11,2) -> 4217.07 | S11: 修改品牌
A12: 7 | B12: 压力变送器 | C12: 输出信号：4-20MA；量程范围：0-25 bar；过程连接：1/4 NPT；电气连接：1M； | D12: 霍尼韦尔、江森、西门子 | E12: 362 | F12: 台 | H12: 霍尼韦尔 | I12: HSP-W225MB | J12: 输出信号：4-20MA；量程范围：0-25 bar；过程连接：1/4 NPT；电气连接：1M； | K12: 响应 | M12: 131.84 | N12: =E12*M12 -> 47726.08 | O12: 494.79 | P12: =E12*O12 -> 179113.98 | Q12: =ROUND((M12+O12)*E12,2) -> 226840.06 | S12: 修改品牌
A13: 8 | B13: 流量传感器 | C13: 电源:10 to 35 VDC；电源消耗:最大40mA；输出:脉冲:NPN开集方波输出，最大60V@50mA;频率:3.2至200Hz。脉冲宽度:2.5毫秒+25%，4-20mA:4mA是0fts，20 mA是25 fts。过程连接:标准配置为1-1/2”NPT外螺纹，可选2“NPT外螺纹。管径满足现场环境 | D13: 霍尼韦尔、江森、西门子 | E13: 75 | F13: 台 | H13: 霍尼韦尔 | I13: HMF-EM16F100N4MY | J13: 口径100，通讯协议和接口：Modbus RTU， RS485，输出信号：4-20mA脉冲输，供电：24VDC100VAC 至 240VAC | K13: 响应 | M13: 350.2 | N13: =E13*M13 -> 26265 | O13: 7055.22 | P13: =E13*O13 -> 529141.5 | Q13: =ROUND((M13+O13)*E13,2) -> 555406.5 | S13: 修改品牌
A14: 9 | B14: 氧浓度监测传感器 | C14: 工作温度 -20~50℃ 工作湿度 5~95% RH 无冷凝 压力范围 90~110KPa 稳定性 ≤5% 信号值 / 年 响应时间 ≤10S 预热时间 ≥5 分钟 零点漂移（-20~40℃） ±0.3%Vol 重复性 ≤1% 使用寿命 ≥24 个月 量程 0~25% VOL 精度 ±2%FS 分辨率 0.1%VOL | D14: 霍尼韦尔、江森、西门子 | E14: 26 | F14: 台 | H14: 霍尼韦尔 | I14: O2-W2 | J14: 工作温度 -20~50℃ 工作湿度 5~95% RH 无冷凝 压力范围 90~110KPa 稳定性 ≤5% 信号值 / 年 响应时间 ≤10S 预热时间 ≥5 分钟 零点漂移（-20~40℃） ±0.3%Vol 重复性 ≤1% 使用寿命 ≥24 个月 量程 0~25% VOL 精度 ±2%FS 分辨率 0.1%VOL | K14: 响应 | M14: 131.84 | N14: =E14*M14 -> 3427.84 | O14: 107 | P14: =E14*O14 -> 2782 | Q14: =ROUND((M14+O14)*E14,2) -> 6209.84 | S14: 修改品牌
A15: 10 | B15: 温湿度传感器 | C15: 精度：±2%RH；湿度输出：0-10V；温度输出：NTC20K，±0.2°C @25°C；温度量程：0~50℃；继电器输出：无；LCD显示无； | D15: 霍尼韦尔、江森、西门子 | E15: 2 | F15: 台 | H15: 霍尼韦尔 | I15: HSH-RV2B | J15: 精度：±2%RH；湿度输出：0-10V；温度输出：NTC20K，±0.3°C @25°C；温度量程：-10 ℃ ~ 60 ℃℃； | K15: 响应 | M15: 131.84 | N15: =E15*M15 -> 263.68 | O15: 481.8 | P15: =E15*O15 -> 963.6 | Q15: =ROUND((M15+O15)*E15,2) -> 1227.28
A16: 11 | B16: 管道风速监测传感器 | C16: 量程：0–20 m/s（0–4000 ft/min），精度：±0.2 m/s（≤10 m/s）；±2% FS（>10 m/s），输出信号：0–10VDC（线性对应量程），供电：24VDC ±10%（BA 标准供电） 材质 / 防护：ABS 外壳，探杆 304 不锈钢；IP65 温度：-10℃~+50℃（耐高温款可达 80℃） 安装：法兰开孔插入式，带密封圈，漏风小 | D16: 霍尼韦尔、江森、西门子 | E16: 89 | F16: 台 | H16: 霍尼韦尔 | I16: HSV-ADH30U | J16: 风速传感器，一体式，最大量程30m/s,0-10V/4-20mA输出，不带显示 | K16: 响应 | M16: 154.5 | N16: =E16*M16 -> 13750.5 | O16: 1074.06 | P16: =E16*O16 -> 95591.34 | Q16: =ROUND((M16+O16)*E16,2) -> 109341.84 | S16: 修改品牌
A17: 12 | B17: 继电器 | C17: 适配电磁阀信号选配 | D17: 霍尼韦尔、江森、西门子 | E17: 100 | F17: 个 | H17: 霍尼韦尔 | I17: SZR-LY4-N1 DC24V | K17: 响应 | M17: 21.63 | N17: =E17*M17 -> 2163 | O17: 198.26 | P17: =E17*O17 -> 19826 | Q17: =ROUND((M17+O17)*E17,2) -> 21989 | S17: 修改品牌
A18: 13 | B18: 交流电流变送器 | C18: 输出4-20mA三相模块RS485信号 | D18: 霍尼韦尔、江森、西门子 | E18: 168 | F18: 个 | H18: 霍尼韦尔 | I18: AC0-5A4-20mA10V | J18: 输出4-20mA三相模块RS485信号 | K18: 响应 | M18: 144.2 | N18: =E18*M18 -> 24225.6 | O18: 165.74 | P18: =E18*O18 -> 27844.32 | Q18: =ROUND((M18+O18)*E18,2) -> 52069.92 | S18: 修改品牌
A19: 14 | B19: 光纤熔接盒（含光纤熔纤） | C19: SC4芯单模满配含熔接尾纤、法兰、SC光跳线 | D19: 一舟、普天天纪、罗格朗 | E19: 129 | F19: 个 | H19: 一舟 | I19: S953-4X+ 4*S905-3+ 4*S812+ 2*S922 | J19: 含4个SC单工耦合器，4条SC单芯单模尾纤，2条SC-SC双芯单模跳纤 | K19: 响应 | M19: 98.88 | N19: =E19*M19 -> 12755.52 | O19: 111.19 | P19: =E19*O19 -> 14343.51 | Q19: =ROUND((M19+O19)*E19,2) -> 27099.03
A20: 15 | B20: 光纤收发器 | C20: 1个10/100M/1000M网口，1个1000Mbps光口（SC），工作波长：1550nm（发送）、1310nm（接收），20km。 | D20: TP-LINK、山泽、烽火 | E20: 129 | F20: 对 | H20: 普联 | I20: TL-FC311A-3 | J20: 普联（TP-LINK）TL-FC311A-3千兆单模单纤光纤收发器 光电转换器SC单芯3km（单只装） | K20: 响应 | M20: 32.96 | N20: =E20*M20 -> 4251.84 | O20: 182.53 | P20: =E20*O20 -> 23546.37 | Q20: =ROUND((M20+O20)*E20,2) -> 27798.21
A21: 16 | B21: 光纤收发器架 | C21: 14槽光纤收发器机架；标准机柜安装； | D21: TP-LINK、山泽、烽火 | E21: 34 | F21: 个 | H21: 普联 | I21: TL-FC1400 | J21: 普联（TP-LINK） TL-FC1400单模多模光纤收发器14槽机架单纤双纤光电转换器整理箱机柜2U机箱 | K21: 响应 | M21: 87.55 | N21: =E21*M21 -> 2976.7 | O21: 543.38 | P21: =E21*O21 -> 18474.92 | Q21: =ROUND((M21+O21)*E21,2) -> 21451.62
A22: 17 | B22: 室外4芯单模光缆 | C22: 1.标准：YD/T769，ISO/IEC11801，ANSI/TIA -568-C.3 2.全截面阻水结构，松套管填充纤膏，松套管和钢带之间填充缆膏，确保良好的阻水防潮性能 3.光纤规格：B1.3（OS2） 4.衰减＠20℃（dB/Km）：＠1310nm≤0.36，＠1550nm≤0.22 5.光纤芯数：4芯 6.护套：夹带钢丝的钢-聚乙烯粘结护套，MDPE，黑色 7.允许拉伸力：长期：600N，短期：1500N 8.允许压扁力：长期：300N/100mm，短期：1000N/100mm 9.最小弯曲半径：动态：20D，静态：10D | D22: 一舟、普天天纪、罗格朗 | E22: 130000 | F22: m | H22: 一舟 | I22: D173-4 | J22: 1.标准：YD/T769，ISO/IEC11801，ANSI/TIA -568-C.3 2.全截面阻水结构，松套管填充纤膏，松套管和钢带之间填充缆膏，确保良好的阻水防潮性能 3.光纤规格：B1.3（OS2） 4.衰减＠20℃（dB/Km）：＠1310nm≤0.36，＠1550nm≤0.22 5.光纤芯数：4芯 6.护套：夹带钢丝的钢-聚乙烯粘结护套，MDPE，黑色 7.允许拉伸力：长期：600N，短期：1500N 8.允许压扁力：长期：300N/100mm，短期：1000N/100mm 9.最小弯曲半径：动态：20D，静态：10D | K22: 响应 | M22: 2.68 | N22: =E22*M22 -> 348400 | O22: 1.84 | P22: =E22*O22 -> 239200 | Q22: =ROUND((M22+O22)*E22,2) -> 587600 | S22: 修改型号
A23: 18 | B23: 24口光纤配线架（含尾纤、LC双工耦合器、熔接） | C23: 1.标准：YD/T778，ISO/IEC 11801，ANSI/TIA -568-C.3 2.安装方式：19″机架式安装 3.4个光缆进线口，带固定PG头，盒内配置光缆护套固定装置，光缆加强件固定装置 4.通用型设计，可兼容：LC双工、SC单工、FC、ST适配器，一个4口支架仅需一颗螺丝，便于安装和拆卸 5.进出光纤方便灵活，有充裕的光纤盘存空间，光纤和尾纤弯曲半径不小于30mm 6.端口数量： 24口，空余端口可安装空白功能件，高度：1U 7.表面处理：静电喷塑 8.材料：优质冷扎钢板 9.表面颜色：黑色 10.含LC双工耦合器 | D23: 一舟、普天天纪、罗格朗 | E23: 24 | F23: 个 | H23: 一舟 | I23: S952-24X+ 24*S905-7-1+ 48*S813 | J23: 1.标准：YD/T778，ISO/IEC 11801，ANSI/TIA -568-C.3 2.安装方式：19″机架式安装 3.4个光缆进线口，带固定PG头，盒内配置光缆护套固定装置，光缆加强件固定装置 4.通用型设计，可兼容：LC双工、SC单工、FC、ST适配器，一个4口支架仅需一颗螺丝，便于安装和拆卸 5.进出光纤方便灵活，有充裕的光纤盘存空间，光纤和尾纤弯曲半径不小于30mm 6.端口数量： 24口，空余端口可安装空白功能件，高度：1U 7.表面处理：静电喷塑 8.材料：优质冷扎钢板 9.表面颜色：黑色 10.含LC双工耦合器 | K23: 响应 | M23: 463.5 | N23: =E23*M23 -> 11124 | O23: 503.52 | P23: =E23*O23 -> 12084.48 | Q23: =ROUND((M23+O23)*E23,2) -> 23208.48
A24: 19 | B24: 光纤跳线 | C24: 单模双芯SC-LC优质2米光纤跳线； | D24: 一舟、普天天纪、罗格朗 | E24: =E20 -> 129 | F24: 个 | H24: 一舟 | I24: S928 | J24: 单模双芯SC-LC优质2米光纤跳线； | K24: 响应 | M24: 5.51 | N24: =E24*M24 -> 710.79 | O24: 23.08 | P24: =E24*O24 -> 2977.32 | Q24: =ROUND((M24+O24)*E24,2) -> 3688.11
A25: 20 | B25: 六类非屏蔽跳线（2m） | C25: 1.标准：不低于TIA/EIA568-C.2、ISO/IEC11801、IEC60332-1、GB 50311； 2.导体规格：多股绞合，软圆铜线，4×2×23AWG； 3.护套材料：PVC，护套外径：6.3±0.3mm； 4.插头规格：RJ45，8P8C； 5.插拔次数：≥1000次； 6.最高传输频率：不小于250MHz； 7.线缆外护套上间隔印有商标、电缆编号、电缆类别、线规、防火等级、标准； 8.支持以太网供电应用（POE/POE+）； 9.描述：用于办公桌桌面跳线，长度2米 10.为了保证性能的匹配性和稳定性，综合布线光纤系统、铜缆系统应采用同一品牌。 | D25: 一舟、普天天纪、罗格朗 | E25: =E20*2 -> 258 | F25: 个 | H25: 一舟 | I25: S0200-GY | J25: 1.标准：不低于TIA/EIA568-C.2、ISO/IEC11801、IEC60332-1、GB 50311； 2.导体规格：多股绞合，软圆铜线，4×2×23AWG； 3.护套材料：PVC，护套外径：6.3±0.3mm； 4.插头规格：RJ45，8P8C； 5.插拔次数：≥1000次； 6.最高传输频率：不小于250MHz； 7.线缆外护套上间隔印有商标、电缆编号、电缆类别、线规、防火等级、标准； 8.支持以太网供电应用（POE/POE+）； 9.描述：用于办公桌桌面跳线，长度2米 10.为了保证性能的匹配性和稳定性，综合布线光纤系统、铜缆系统应采用同一品牌。 | K25: 响应 | M25: 5.51 | N25: =E25*M25 -> 1421.58 | O25: 16.78 | P25: =E25*O25 -> 4329.24 | Q25: =ROUND((M25+O25)*E25,2) -> 5750.82
A26: 21 | B26: 24口接入交换机-单电源 | C26: ★在不插板卡情况下，单设备交换容量≥336Gbps，包转发率≥120Mpps，提供≥24个千兆电接口、≥4个千兆SFP光接口 1、支持堆叠技术或者虚拟化技术 2、支持 4K 802.1Q VLAN,支持Voice VLAN及Voice VLAN中可以同时识别多厂家的OUI地址，支持端口VLAN、MAC VLAN 3、支持标准IP ACL（基于IP地址的硬件ACL）支持扩展IP ACL（基于IP地址、TCP/UDP端口号的硬件ACL） 4、支持QOS 5、支持一对一、多对一、一对多的镜像 6、支持DHCP Server、DHCP Client、DHCP Snooping、DHCP Relay、DHCP Option82 7、支持广播风暴抑制 8、支持设备登陆管理的AAA安全认证、radius认证、支持802.1x、支持ssh2.0 9、支持STP/RSTP/MSTP协议 10、支持链路聚合（支持静态、动态链路聚合、千兆口聚合） 11、有标准的或私有的邻居发现协议 12、支持VLAN虚接口 13、支持 IPv4 /ipv6静态路由 14、支持OSPFv2、OSPFv3 15、支持SNMPv1/v2/v3，WEB网管，支持命令行接口配置，Telnet，SSH，Console口配置，支持系统日志，分级告警，调试信息输出，NTP/SNTP ★16、提供真实有效的工信部入网证复印件； ★17、原厂质保≥3年 ★18、考虑设备兼容性、项目实施、交付及售后服务，采用与核心交换机同一品牌。 | D26: 华三、锐捷（非睿易） | E26: 12 | F26: 台 | H26: 锐捷 | I26: RG-S2910-24GT4SFP-L | J26: 千兆接入交换机 | 24个10/100/1000M自适应电口，4个1G SFP光口，固化交流电源和无风扇设计。 | 不支持PoE | 交换容量598Gbps/5.98Tbps | 包转发率126Mpps | 支持动态路由协议（RIP、OSPF）、VSU、802.X认证、ERPS环网保护协议、链路聚合 | 支持云管理&本地管理 | 默认三年维保 | | K26: 响应 | M26: 144.2 | N26: =E26*M26 -> 1730.4 | O26: 1265 | P26: =E26*O26 -> 15180 | Q26: =ROUND((M26+O26)*E26,2) -> 16910.4 | S26: 修改型号
A27: 22 | B27: 千兆单模光模块 | C27: LC接口，单模千兆光纤（和交换机同品牌） | D27: 华三、锐捷（非睿易） | E27: 24 | F27: 个 | H27: 锐捷 | I27: MINI-GBIC-LX-SM1310 | J27: 1000BASE-LX mini GBIC转换模块（1310nm），10km | K27: 响应 | M27: 16.48 | N27: =E27*M27 -> 395.52 | O27: 110.15 | P27: =E27*O27 -> 2643.6 | Q27: =ROUND((M27+O27)*E27,2) -> 3039.12
A28: 23 | B28: 信号线 | C28: 国标，RVV2*1.0 | D28: 一舟、普天天纪、罗格朗 | E28: 3800 | F28: m | H28: 一舟 | I28: RVV2*1.0 | J28: 国标，RVV2*1.0 | K28: 响应 | M28: 2.06 | N28: =E28*M28 -> 7828 | O28: 3.04 | P28: =E28*O28 -> 11552 | Q28: =ROUND((M28+O28)*E28,2) -> 19380
A29: 24 | B29: 信号线 | C29: 国标，RVVP2*1.0 | D29: 一舟、普天天纪、罗格朗 | E29: 7200 | F29: m | H29: 一舟 | I29: RVVP2*1.0 | J29: 国标，RVVP2*1.0 | K29: 响应 | M29: 2.06 | N29: =E29*M29 -> 14832 | O29: 5.72 | P29: =E29*O29 -> 41184 | Q29: =ROUND((M29+O29)*E29,2) -> 56016
A30: 25 | B30: 信号线 | C30: 国标，RVVP4*1.0 | D30: 一舟、普天天纪、罗格朗 | E30: 5000 | F30: m | H30: 一舟 | I30: RVVP4*1.0 | J30: 国标，RVVP4*1.0 | K30: 响应 | M30: 2.52 | N30: =E30*M30 -> 12600 | O30: 8.97 | P30: =E30*O30 -> 44850 | Q30: =ROUND((M30+O30)*E30,2) -> 57450
A31: 26 | B31: 信号线 | C31: 国标，RVVP6*1.0 | D31: 一舟、普天天纪、罗格朗 | E31: 154 | F31: m | H31: 一舟 | I31: RVVP6*1.0 | J31: 国标，RVVP6*1.0 | K31: 响应 | M31: 2.52 | N31: =E31*M31 -> 388.08 | O31: 12.48 | P31: =E31*O31 -> 1921.92 | Q31: =ROUND((M31+O31)*E31,2) -> 2310
A32: 27 | B32: JDG20管 | C32: JDG管，壁厚不小于1.0MM,φ20；含主材、接头、固定扣件（含钢结构扣件）等辅材 | D32: 国产 | E32: 25000 | F32: m | H32: 国产 | I32: JDG20 | J32: JDG管，壁厚不小于1.0MM,φ20；含主材、接头、固定扣件（含钢结构扣件）等辅材 | K32: 响应 | M32: 9.79 | N32: =E32*M32 -> 244750 | O32: 3.67 | P32: =E32*O32 -> 91750 | Q32: =ROUND((M32+O32)*E32,2) -> 336500
A33: 28 | B33: 辅材 | C33: 设备安装配套辅材，水晶头，扎带等 | D33: 国产 | E33: 1 | F33: 项 | K33: 响应 | M33: 6180 | N33: =E33*M33 -> 6180 | O33: 10490 | P33: =E33*O33 -> 10490 | Q33: =ROUND((M33+O33)*E33,2) -> 16670
B34: 二、智慧安防系统 | N34: =E34*M34 -> 0 | P34: =E34*O34 -> 0
B35: 2.1、视频监控系统 | N35: =E35*M35 -> 0 | P35: =E35*O35 -> 0
A36: 1 | B36: 抗振防抖场景专用摄像机 | C36: 1.设备采用金属机身，主要接口：1个M12航空头网络接口、1个CVBS接口、1个音频输入接口，1个音频输出接口、1个RS485接口、1个报警输入接口、1个报警输出接口、1个SD卡卡槽（内置） 2.内置1/1.8英寸，400万像素CMOS传感器；最大亮度鉴别等级试验≥11级；最大帧率60fps；延时试验小于200ms；照度适应范围不小于140dB 3.外壳防护等级IP66/IP68 4.机身部分碰撞防护等级IK10 5.摄像机应能在额定电源电压DC9V-DC36V范围内正常工作，支持POE供电 6.设备支持红外和暖光补光灯，可通过IE浏览器或客户端切换补光灯类型 7.最低照度试验：彩色：0.0005 lx，黑白：0.0001 lx 8.支持开启、关闭畸变矫正功能 9.防抖功能检查：在水平X轴方向随机抖动频率范围5Hz-62Hz，加速度有效值：5.6m/s²，最大振幅3.39mm；相机配置：2560X1440，最大焦距，座装安装，镜头方向朝下；在图像中指定4个像素点，最大偏移应不超过±1%。 10.防抖功能检查：在水平Y轴方向随机抖动频率范围5Hz-62Hz，加速度有效值：5.6m/s²，最大振幅3.39mm；相机配置：2560X1440，最大焦距，座装安装，镜头方向朝下；在图像中指定4个像素点，最大偏移应不超过±1%。 11.防抖功能检查：在垂直Z轴方向随机抖动频率范围5Hz-26Hz，加速度有效值：5.6m/s²，最大振幅3.39mm；相机配置：2560X1440，最大焦距，座装安装，镜头方向朝下；在图像中指定4个像素点，最大偏移应不超过±1.5%。 12.在彩色模式下，当照度降低至一定值时，设备可自动开启白光灯补光，设备在白天、夜晚均可输出彩色视频图像 13.可通过扫描预览界面上生产的二维码获取设备资料。 14.当移动侦测、进入区域、离开区域、越界区域或区域入侵报警类型设置为人和/或车时，仅当检测区域中出现对应的人和/或车时，才触发报警；当报警产生时，可触发联动白光灯闪烁，白光灯闪烁的时间和频率可设置 15.设备具有APP管理功能，支持在线导入APP、删除APP、加载运行APP、配置APP操作，APP管理操作无需重启设备，操作期间预览画面无中断。 16.设备支持用户自定义最多16个AI算法库，可设置当前生效的算法库和显示当前算法库的运行状态，并支持修改、删除算法库及自定义算法库名称。 17.设备具有良好的环境适应性，工作温度范围可达-40℃～60℃。 | D36: 海康 | E36: 6 | F36: 台 | H36: 海康 | I36: DS-2XC7245/KZ | J36: 400万抗振防抖摄像机 产品具备抗振动及图像防抖能力，支持起重机械场景使用 内置大模型移动周界功能，支持AI开放平台及HEOP功能，支持自定义算法训练及三方算法集成 最高分辨率可达2560 × 1440，并在此分辨率下可输出最大60 fps实时图像 支持低延时，相机解码延时低至100 ms 采用双光阵列灯，低功耗，红外照射距离最远达80 m（2.8~12 mm红外支持50 m），白光照射距离最远达50 m（2.8~12 mm白光支持30 m） 支持DC9 V~36 V宽压和PoE at供电 支持除雾，防止设备内部起雾 支持雨刷 支持加热 彩色：0.0005 Lux @（F1.2，AGC ON）；黑白：0.0001 Lux @（F1.2，AGC ON）；0 Lux with IR 支持宽动态范围达120 dB，适合逆光环境监控 支持三码流技术，每路码流可独立配置分辨率及帧率 支持1路音频输入和1路音频输出、1路报警输入和1路报警输出、1路RS-485 、1路模拟视频输出 千兆自适应以太网口，M12航空头（8芯），标配防水对插头 支持防雷、防浪涌、防静电，IP68防护等级 C5-M、NEMA 4X、WF2防腐蚀标准，有效避免酸性、中性盐雾腐蚀 传感器类型：1/1.8" Progressive Scan CMOS 最低照度：彩色：0.0005 Lux @（F1.2, AGC ON），0 Lux with Light 黑白：0.0001 Lux @（F1.2, AGC ON），0 Lux with IR 调节角度：水平: -15°~15°；垂直: -120°~45° 焦距&视场角：2.8~12 mm：水平视场角：99.6°~39.8°，垂直视场角：52.3°~22.4°，对角视场角：119.9°~45.7° 8~32 mm：水平视场角：40.3°~14.5°，垂直视场角：22.1°~8.2°，对角视场角：46.9°~16.5° 补光灯类型：红外模式：红外灯 白光模式：白光灯 补光距离：2.8~12 mm：红外50米，白光30米 8~32 mm：红外80米，白光50米 最大分辨率：2560 × 1440 视频压缩标准：主码流：H.265/H.264 子码流：H.265/H.264/MJPEG 第三码流：H.265/H.264 宽动态：120dB 视频输出：1 Vp-p复合输出（75 Ω/CVBS） 网络：千兆自适应以太网口，M12航空头（8芯），标配防水对插头 SD卡扩展：内置MicroSD插槽，最大支持512 GB 音频：1路输入（Line in）（terminal block）（最大输入幅值：3.3 Vpp，输入阻抗：1 kΩ，接口类型：非平衡） 1路输出（Line out）（terminal block）（最大输出幅值：3.3 Vpp，输出阻抗：100 Ω，接口类型：非平衡） 报警：1路输入，1路输出（报警输出最大支持DC12 V，30mA） RS-485：支持1个RS-485 外壳材质：316L不锈钢 产品尺寸：199.7 × 201.9 × 209.2 mm 包装尺寸：340 × 298 × 290 mm 设备重量：5.6 kg 带包装重量：6.6 kg 启动和工作温湿度：-40 °C~60 °C，湿度小于95%（无凝结） 雨刷：支持 电流及功耗：DC：9~36 V，2.65~0.65 A，24 W Max PoE：802.3at，42.5 V~57 V，0.56 A~0.42 A，24 W Max 供电方式：DC：9 V~36 V，支持防反接保护；PoE：802.3at，Class 4 电源接口类型：2芯绿头 安装方式：壁装，座装 防腐蚀：WF2，C5，NEMA 4X 恢复出厂设置：支持 在线升级：支持 文件系统双备份：支持 | K36: 响应 | M36: 175.1 | N36: =E36*M36 -> 1050.6 | O36: 2989.65 | P36: =E36*O36 -> 17937.9 | Q36: =ROUND((M36+O36)*E36,2) -> 18988.5
A37: 2 | B37: 400万变焦筒型网络摄像机 | C37: 1.支持输出图像分辨率不低于2560x1440 2.最低照度彩色：0.005 lx，最大亮度鉴别等级不小于11级 3.补光距离：红外不低于50 m，白光不低于30 m 4.支持电动变焦 5.具备区域入侵、越界、进入区域、离开区域、人员聚集、快速移动、徘徊、物品移除、物品遗留、停车智能分析功能，当以上智能分析行为达到设定的阈值时，可通过客户端软件或IE浏览器给出报警提示 6.同一场景相同图像质量下设备在H.264或H265编码方式时，开启智能编码功能和不开启智能编码相比，码率节约80% 7.靶面尺寸为1/2.7英寸，内置1个麦克风，具有1个RJ45 网络接口，1路音频输入、1路音频输出、1路报警输入、1路报警输出、1 个复位按钮、1个 SD 卡槽、1个 DC12V 电压输出接口 8.支持H.264、H.265视频编码格式，且具有High Profile编码能力 9.支持电源电源在DC12V±25%范围内变化时正常工作，支持POE 10.IP67防护等级 | D37: 海康 | E37: 68 | F37: 台 | H37: 海康 | I37: DS-2CD2645V3-FD | J37: 最高分辨率可达400万像素（2688 × 1520），并在此分辨率下可输出30 fps实时图像 室外消防通道占用：可检测汽车是否占用区域，可根据停留时间上报信息，可支持车牌号识别 室内消防通道占道：可检测杂物堆放导致通道被长时间占用 支持smart事件，人脸抓拍，比对建模，车辆监控算法切换使用 支持室内通道占用与人脸抓拍并行运行 支持室内通道占用与smart事件并行运行 可支持AI开放平台训练模型包导入运行 支持电动变焦，方便远程调节图像，保证算法效果 内置2个内置麦克风，1个内置扬声器，支持远程对讲与智能联动语音 外部接口丰富：1路报警IO输入，1路报警IO输出；1路音频LINE IN输入，1路音频输出LINE OUT；1路485接口；1路DC12V电源反送 最大支持512GB MicroSD/MicroSDHC/MicroSDXC卡存储； 传感器类型：1/2.7" 逐行扫描 CMOS 最低照度：彩色：0.005 Lux @（F1.2，AGC ON），0 Lux with Light； 黑白：0.001 Lux @（F1.2，AGC ON），0 Lux with IR 焦距&视场角：2.7~13.5 mm：水平视场角：30.1°~99°，垂直视场角：17°~52.9°，对角视场角：34.6°~117.8° 补光灯类型：反射式补光，双光 (红外850nm+白光) 补光距离：红外最远可达50m，暖白最远可达30m 主码流帧率分辨率：50 Hz:25 fps(2688 × 1520,2560 × 1440,1920 × 1080,1280 × 720) 60 Hz:30 fps(2688 × 1520,2560 × 1440,1920 × 1080,1280 × 720) 视频压缩标准：主码流：H.265/H.265+/H.264/H.264 子码流：H.265/H.264/MJPEG 第三码流：H.265/H.264 网络传输类型：有线 宽动态：120 dB 连接方式：甩线式接口，线缆长度约35cm； 音频：1路输入（Line in），1路输出（Line out），2个内置麦克风，1个内置扬声器 报警：1路输入，湿接点，支持3.3 V~5 V范围电位 1路输出，三极管输出，电平量，湿接点，最大支持DC 12V，30 mA RS-485：1路RS-485接口，采用半双工模式，支持自适应HIKVISION，PELCO-P和PELCO-D协议 电源输出：1路DC12V输出，最大电流100mA。备注：为保证设备正常工作，电源输出外接延长线请控制在10米以内。 尺寸：设备尺寸：180.3 × 99.2 × 93 mm 包装尺寸：315 × 137 × 141 mm 重量：设备重量：1.0kg 带包装重量：1.3kg 存储温湿度：-30 °C~60 °C，湿度小于95%（无凝结） 启动和工作温湿度：-30 °C~60 °C，湿度小于95%（无凝结） 物理防护：防水防尘：IP67 电源：1、 电源输入类型：2芯接口 2、 电流及功耗： DC：12 V，1.2 A，最大功耗：14.4W PoE：PoE(IEEE 802.3at class 4)，最大功耗：16W | K37: 响应 | M37: 175.1 | N37: =E37*M37 -> 11906.8 | O37: 519.26 | P37: =E37*O37 -> 35309.68 | Q37: =ROUND((M37+O37)*E37,2) -> 47216.48
A38: 3 | B38: 热成像摄像机 | C38: ★热成像：分辨率：256×192；焦距：焦距可选：3/7/10mm； 可见光：分辨率：2688*1520，400万；焦距：焦距可选：4mm/8mm/12.4mm； 支持1路音频输入，1路音频输出； 支持2路报警输入，2路报警输出； 外壳防护等级：IP67； 电源电压在DC12V±20%范围内变化时，能正常工作； 可通过IE浏览器在热成像画面中设置点、线段、区域测温规则； 点测温、线测温、区域测温中存在高于或者低于报警或预报警温度时，可在客户端显示不同的报警颜色进行报警提示，联动报警输出，联动录像及联动抓拍； 支持声音联动报警功能。可对智能行为、温度超过阈值、出现高温点等行为进行检测并报警，报警声音可设置，同时支持自定义； ★噪声等效温差为8mk，最小可分辨温差为200mk（（公京检第2401130038号第100条） 热成像视频图像具有白热、黑热、融合1、融合2、彩虹1、铁红2、深褐色等42种显示模式 含安装支架 | D38: 海康 | E38: 199 | F38: 台 | H38: 海康 | I38: HM-TD2628-XX/T1A | J38: 双光谱筒型摄像机 【功能特性】 热成像像素256 × 192，像元大小12um，NETD ≤ 35 mK (25°C, F1.0) 支持区域入侵探测、越界探测、进入区域探测、离开区域探测、音频异常探测、高温物体检测等功能 支持测温功能:支持普通测温，专家测温检测；可以画最多10个点，1条线，10个区域检测。测温范围：-20 °C~300 °C，测温精度：±8 °C或者读数的±8%（取最大值） 支持吸烟检测、火点检测、烟雾检测 支持联动白光报警、支持联动声音报警，内置白光灯和扬声器 支持AI开放平台 智能功能资源配置：测温、周界功能支持同时开启。测温、火点检测、烟雾检测支持同时开启。测温、AI开放平台支持同时开启。周界功能不支持与火点、吸烟、烟雾检测两两同时开启。 支持线性、直方图、自适应等热成像AGC模式，支持DDE、3D DNR。 支持叉车去误报功能 【应用场景】 可通过外接温湿度传感器，在样机OSD界面显示传感器信息 周界防范：石油石化、电力系统、工商企业、政府大院、铁路沿线、机场、文博、学校、医院等； 烟火检测：物流仓储、博物馆、实验室、数据机房、配电房等； 吸烟检测：加油站、景区、博物馆、校园、医院、生产车间等； 热成像传感器类型：氧化钒非制冷型探测器 热成像像元尺寸：12 μm 热成像响应波段：8~14 μm 热成像分辨率：256 × 192 热成像焦距：10 mm 热成像视场角：18°×13.5° 热成像最大光圈值：F1.0 热成像数字变倍：×2,×4 热成像帧频：50 Hz: 25 fps 热成像近摄距：3.5m 噪声等效温差NETD：≤ 35 mk(@25 °C,F#=1.0) 空间分辨率MRAD：1.24 伪彩：白热、黑热、融合1、彩虹、融合2、铁红1、铁红2、深褐色、色彩1、色彩2、冰火、雨、红热、绿热、深蓝等15种 温度异常功能：全屏测温 专家模式：10个点，10个框，1条线总计21个测温规则 测温范围：测温范围：-20 °C~300 °C 测温精度：测温精度：±8 °C或者读数的±8%（取最大值） 人员最远报警距离（以1.8米*0.5米为准）：100m 车辆最远报警距离（以4米*1.4米为准）：300m 吸烟检测最远报警距离：15m 防火最远报警距离（以0.05㎡高温源或0.1㎡火焰为准）：70m 最远测温距离（满足测温精度，以0.1m*0.1m目标物为准）：15m 可见光传感器类型：400万星光级1/2.7" Progressive Scan CMOS 可见光焦距&视场角：12.4mm,24.6°×14° 烟雾最远报警距离（以1㎡烟雾为准）：70m 可见光分辨率：2688 × 1520 最低照度：0.0089Lux @(F1.6,AGC ON) ,0 Lux with IR 可见光补光功能：补光最远可达30米 可见光光圈值：F1.6 报警联动：内置混合补光灯（支持红外和白光补光）、内置扬声器，支持联动白光报警、支持联动声音报警 周界防范检测：热成像通道（默认）：越界侦探测,区域入侵探测,进入/离开区域探测 可见光通道：越界探测,区域入侵探测,进入/离开区域探测 防火应用检测：支持火点检测、烟雾检测、吸烟检测 最大预览路数：20路 视频压缩标准：H.265/H.264/MJPEG 音频压缩标准：G.711/G.722.1/G.726/MP2L2/PCM 客户端：iVMS-4200/萤石/HIK-CONNCET 浏览器：IE10+,Chrome 57+,Mozilla Firefox 52+,Mac Safari 12 报警输入：支持2路DC 0~5 V报警输入 报警输出：支持2路常开型继电器输出，报警类型可设置 音频输入：1路3.5 mm Mic in/Line in interface. Line input: 2-2.4 V[p-p] 音频输出：1路3.5mm Impedance: 600Ω 复位键：1个复位键 RS485控制接口：1路 网口：1路RJ45接口10/100 M自适应以太网口 SD卡存储：1个内置SD卡卡槽,最大支持内存256G 尺寸：312.1 mm × 105 mm × 104.9 mm 电源输入：12 VDC ± 25%，PoE (802.3at, class 4) 备注：需单独购买DC 12V电源适配器 功率：12 VDC ± 25%: 1.2A to 2A, max. 18W PoE (802.3at, class 4): 42.5 V to 57 V, 0.32 A to 0.43A, max. 18W 工作温度和湿度：-40°C~70°C，＜95% RH 测温环境温度：-20°C~50°C 防护等级：IP67 重量：1.53 kg 藏线盒：需单独购买 | K38: 响应 | M38: 195.7 | N38: =E38*M38 -> 38944.3 | O38: 2040.31 | P38: =E38*O38 -> 406021.69 | Q38: =ROUND((M38+O38)*E38,2) -> 444965.99
A39: 4 | B39: 高空球型鹰眼 | C39: 1.全景通道最高分辨率不小于6072 x 2640，细节通道最高分辨率不小于3840x2160。 2.全景通道内置4个镜头、靶面尺寸不小于1/1.8英寸的CMOS传感器，细节通道内置1个镜头，靶面尺寸不小于1/1.2英寸的CMOS传感器。 3.设备在全景拼接模式下，垂直视场角不小于110°，水平视场角不小于180°。可将4个全景视频图像进行拼接，实现不小于180°拼接画面显示，并抓拍拼接后的图片。 4.细节通道内置镜头支持不小于45倍光学变倍，镜头最大焦距不小于320mm。 5.设备具有光学防抖功能，将镜头倍率设置为最大，快门设置为1/25s，在振动台振幅不大于0.3°，振动频率不大于10Hz情况下，设备视场角应无明显变化，视频图像在振动过程中应保持稳定清晰 6.设备内置2个雨刷器，雨刷器1可清洁全景通道镜头表面玻璃，雨刷器2可清洁细节通道镜头表面玻璃。 7.设备细节通道水平手控最大速度不小于500°/s，垂直手控最大速度不小于350°/s。 8.设备具备双安装接口，一个为快速旋转安装接口，一个为多孔稳定安装接口。 9.支持不小于300个预置位，支持预置位冻结功能。 10.内置不少于3个GPU芯片。 11.支持智能行为分析功能，智能分析行为类型为区域入侵、越界入侵、进入区域、离开区域等，支持行为分析触发后联动聚焦、联动目标跟踪、报警上传等多种报警触发方式。 12.设备在全景视频图像中点击或框选移动目标至设备开始转动的时间小于0.3s，全景图像检测到且框选出移动目标至设备开始转动时间小于0.3s。 13.设备全景通道支持人员密度检测功能，可开启、关闭人员密度检测功能，最多可设置8个多边形（3～10条边）人员密度检测区域。每个区域的名称、人员数量报警阈值等级（低、中、高等级）可自定义。 14.设备全景通道车辆拥堵检测功能，开启车辆拥堵检测功能后，当设置区域内的车辆滞留时间超过设定值时，可通过IE浏览器给出报警提示。 15.设备可切换智能模式，当更换当前智能模式时设备不需重启，新智能模式即可生效。 16.设备全景通道具有默认拼接、手动拼接、自动拼接3种拼接模式；自动拼接模式下设备可自动获取特征并进行拼接。 17.设备具有AI-ISP图像质量提升功能，在低照度环境下，可自动调节预览场景视频画面中人脸、人体、车辆等目标及预览场景视频画面的区域曝光、亮度、色彩饱和度、对比度、锐度等。 18.设备具有不少于1个RJ45网络接口、1个光纤接口、7路报警输入、2路报警输出、1路音频输入、1路音频输出。内置的北斗定位模块，具有定位功能，可自动获取设备所在位置经纬度信息。 19.防护等级不低于IP67。 | D39: 海康 | E39: 3 | F39: 台 | H39: 海康 | I39: DS-2DP1618XS-LD | J39: 1600万180°AR鹰眼_800万45倍_雨刷_卫星定位_5G 1600万180° 无盲区球型5G AR鹰眼，全景采用4个F1.0大光圈全彩镜头拼接而成，可输出180°大场景拼接画面 全景画面可支持关注区域畸变矫正，细节内置45倍变焦光学防抖镜头 支持基于行业平台实现AR立体防控，可添加500个标签，结合前端多维感知设备和业务系统数据，将高点范围内的人、车、地、事、物叠加到实时视频画面中进行展示和联动，通过多维联动、全景回溯、移动标签、标记标绘等应用，为用户掌握重点区域的实时动向、及时响应指挥调度提供新方式 全景智能：Smart事件、人员密度、车辆拥堵；细节智能：全结构化、Smart事件；更好助力平安城市公共安全管理 适用于城市高点、机场车站、城管市政、水利枢纽、企业园区、景区、校园等重点场所 全景摄像机 4个1/1.8＂ 4MP Progressive Scan CMOS，最高分辨率及帧率可达6072x2640@30fps 视场角：水平180°，垂直110° 细节摄像机 1/1.2＂ 8MP Progressive Scan CMOS，最高分辨率及帧率可达3840x2160@30fps 45倍光学变倍，16倍数字变倍 【全景】支持区域入侵侦测、越界侦测、进入区域、离开区域事件侦测功能 【全景】支持人员密度检测功能，检测覆盖范围半径100米 【全景】支持车辆拥堵检测功能，检测覆盖范围半径150米，推荐：在封闭式道路中可以做拥堵事件检测，推荐在高速、环线、快速路或者主干线 【细节】支持区域入侵侦测、越界侦测、进入区域、离开区域事件侦测功能 【细节】支持全结构化：支持细节路混合目标检测，对检测区域内的人、非机动车、车进行同时抓拍上传，人脸人体关联输出，并实现对人脸、人体、车辆结构化属性特征信息提取 支持GB35114A级安全加密 AI-ISP：细节球机采用去噪卷积神经网络将深度结构、学习算法用于图像去噪，最终使画面成像更新清晰，噪点更小图像更干净 支持北斗卫星定位 支持光学防抖、光学透雾 支持雨刷，环动式双雨刷设计，可对全景4个镜头、细节球机镜头进行清洁 移动通信类型： 5G/4G/3G 传感器类型：【全景】1/1.8＂ progressive scan CMOS,【细节】1/1.2＂ progressive scan CMOS 最低照度：【全景】0.0005Lux/F1.0（彩色），0.0001Lux/F1.0（黑白）；【细节】星光级超低照度，0.0005Lux/F1.5（彩色），0.0001Lux/F1.5（黑白），0 Lux with IR 宽动态：全景不支持，细节支持120dB超宽动态 光学变倍：45倍 焦距：【全景】2 mm；【细节】7.2~320 mm 视场角：水平视场角61.0~1.8度（广角~望远） 垂直视场角35.9~1.1度（广角~望远） 对角线视场角68.5~2.1度（广角~望远） 红外照射距离：500m 防补光过曝：支持 水平范围：360° 垂直范围：-15°-90°(自动翻转) 水平速度：水平键控速度：0.1°-500°/s,速度可设;水平预置点速度：500°/s 垂直速度：垂直键控速度：0.1°-350°/s,速度可设;垂直预置点速度：350°/s 主码流帧率分辨率：全景：50Hz: 25fps (6072x2640,5520×2400, 4096×1800,3840×1680, 2784×1200) 60Hz: 30fps (6072x2640，5520×2400, 4096×1800，3840×1680, 2784×1200) 细节：50Hz:25fps (3840×2160,2560×1440,1920×1080,1280×960,1280×720) 60Hz:30fps(3840×2160,2560×1440,1920×1080,1280×960,1280×720) 视频压缩标准：主码流：H.264/H.265+/H.265/H.264+ 子码流：H.264/H.265/MJPEG 第三码流：H.264/H.265/MJPEG 移动通信类型：同时支持5G/4G/3G 无线频段：5G NR/LTE-FDD/LTE-TDD/WCDMA 无线制式：5G NR：n1/n5/n8/n28/n41/n78/n79 LTE-FDD：B1/B3/B5/B8 LTE-TDD：B34/B38/39/B40/B41 WCDMA：B1/B5/B8 无线传输速率：NR(SA)：DL 2 Gbps；UL 766 Mbps EN-DC：DL 2.2 Gbps；UL 458 Mbps LTE：DL 487 Mbps; UL 150 Mbps WCDMA：DL 42 Mbps; UL 11 Mbps SIM卡：nano SIM 卫星定位：支持北斗卫星定位 陀螺仪：支持 电子罗盘：支持 网络接口：RJ45网口;自适应10M/100M/1000M网络数据 光纤接口：FC接口;内置光纤模块;波长TX1310/RX1550nm;20km传输距离;单模单纤;1000M网络数据 SD卡扩展：内置Micro SD卡插槽，支持Micro SD/Micro SDHC/Micro SDXC卡（最大支持512G） 报警：7路报警输入，2路报警输出 音频：1路音频输入，1路音频输出 RS485接口：采用半双工模式，支持自适应HIKVISION，PELCO-P和PELCO-D(可添加)协议 供电方式：DC36V； 整机平均功耗85w.最大功耗 120w 工作温湿度：-40℃-70℃;湿度小于90% 恢复出厂设置：支持 雨刷：支持 除雾：支持 尺寸：Φ427.6x425.9mm 重量：净重 14.6kg 防护：IP67; 6000V 防雷、防浪涌、防突波，符合GB/T17626.2/3/4/5/6四级标准 | K39: 响应 | M39: 309 | N39: =E39*M39 -> 927 | O39: 28323 | P39: =E39*O39 -> 84969 | Q39: =ROUND((M39+O39)*E39,2) -> 85896
A40: 5 | B40: 人脸识别布控球 | C40: 1.单北斗5G双摄便携球套装 2.支持双摄：40倍光学变倍机芯，最大分辨率2560*1440，图像清晰、细腻，低照度，彩色0.0001Lux；全景镜头8M，分辨率2160×3840 3.支持自动彩转黑功能，实现昼夜监控 4.支持人脸比对，可存储30W张人脸名单（含一张1TB TF卡） 5.支持车辆检测及抓拍 6.支持抽烟、佩戴安全帽、玩手机、未穿工作服检测 7.支持3D-DNR 8.支持双TF卡存储 9.支持5G模块（天线内置），可额外扩展1个4G模块 10.配置可拆卸电池，单电池可支持8-9小时连续工作 11.支持双MIC、双扬声器，可选配支持LINE IN\LINE OUT 12.支持自定义语音导入，可关联智能分析报警 13.自带2.4寸LCD显示屏，可支持视频预览，云台控制等，可显示当前电池电量、定位状态、3G/4G/5G状态、录像状态、存储容量、蓝牙状态、平台连接状态、Wi-Fi状态、智能算法模式等 14.底部配置高吸力磁铁，安装便捷 | D40: 海康 | E40: 5 | F40: 台 | H40: 海康 | I40: iDS-MCD402-MF/40X+TF-P1/1T/TAY | J40: 5G双摄便携球套装 支持双摄：40倍光学变倍机芯，最大分辨率2560*1440，图像清晰、细腻，低照度，彩色0.0001Lux；全景镜头8M，分辨率2160×3840； 支持自动彩转黑功能，实现昼夜监控 支持人脸比对，可存储30W张人脸名单（需配TF卡） 支持车辆检测及抓拍 支持抽烟、佩戴安全帽、玩手机、未穿工作服检测 支持3D-DNR 支持双TF卡存储 支持5G模块（天线内置），可额外扩展1个4G模块 配置可拆卸电池，单电池可支持8-9小时连续工作 支持双MIC、双扬声器，可选配支持LINE IN\LINE OUT 支持自定义语音导入，可关联智能分析报警 自带2.4寸LCD显示屏，可支持视频预览，云台控制等，可显示当前电池电量、GPS状态、3G/4G/5G状态、录像状态、存储容量、蓝牙状态、平台连接状态、Wi-Fi状态、智能算法模式等 底部配置高吸力磁铁，安装便捷 传感器类型：变焦机芯：1/1.8" Progressive Scan CMOS 全景相机8M：1/1.8" Progressive Scan CMOS 彩色最低照度：变焦机芯：0.0001Lux @ (F1.6，AGC ON) 黑白最低照度：变焦机芯：0.00005Lux @(F1.6，AGC ON) 屏幕尺寸：2.4英寸 分辨率：240*320 材质：TFT 触摸屏：电容屏 镜头焦距：5.8-232mm 镜头光圈：F1.3-F4.6 光学变倍：40倍 水平视场角：59-2度(广角-望远) 子码流压缩码率：2Mbps 视频压缩标准：H.264;H.265;MJPEG 码率控制：定码率;变码率 录像格式：MP4 录像分辨率：变焦机芯：2560×1440 全景相机8M：3840×2160 图片分辨率：1920*1080;2560*1440 图片格式：JPEG 音频压缩标准：G.722.1;G.711alaw;G.711ulaw 人脸比对：支持 车辆抓拍：支持 车牌识别：支持 车辆特征识别：支持车牌、车身颜色、车型、车辆品牌、车辆子品牌识别 车辆黑名单：支持车辆黑名单 安全帽佩戴检测：支持未佩戴安全帽检测 目标抓拍：支持 支持人脸库个数：10个(需配置TF卡) 支持的人脸数量：300000张(需配置TF卡) 支持屏蔽区域设置 拨号：GSM/GPRS/EDGE：900/1800MHz WCDMA：B1/5/8 LTE：B1/3/5/8/34/38/39/40/41 5G：N1/5/8/28/41/77/78/79 定位：北斗 蓝牙：4.0 语音对讲：支持 指示灯：充电指示灯,工作指示灯 系统功耗：10W~30W 产品重量：带电池4.35kg~4.5kg 产品尺寸：高262mm，直径175mm 防护等级：IP66 供电方式：电池供电;外接电源 工作温度：-10℃~55℃ 工作湿度：湿度小于95% 材质：镁合金 水平旋转角度：360° 垂直旋转角度：-20°~90° 预置点：256个 巡航扫描：8条 花样扫描：4条 断电记忆：支持 红外：支持 红外补光距离：100m看清人体轮廓 扩展存储个数：2 扩展存储介质：TF 扩展存储容量：默认不含TF卡，最大支持1TB存储卡 充电接口：6芯航空头 外部接口：电源输出接口;RJ45;RS-232;RS-485;line-in;line-out;Alarm-in;Alarm-out 扬声器：支持 MIC：支持 存储卡卡槽：2 电源输出接口：5V 电池可拆卸：支持 电池容量：13400mAh 待机时间：8-9小时 关机充电时间：＜4小时 电池类型：锂离子电池 | K40: 响应 | M40: 412 | N40: =E40*M40 -> 2060 | O40: 17833 | P40: =E40*O40 -> 89165 | Q40: =ROUND((M40+O40)*E40,2) -> 91225
...

Sheet 附录五硬件场景需求表
A1: 项目范围 | B1: 系统 | C1: 序号 | D1: 设施设备 | E1: 数量 | F1: 涉及硬件类型
A2: 智慧消防系统 | B2: 消防水系统 | C2: 1 | D2: 消防水池 | E2: 水池数量 | F2: 水位仪传感器7个（包括电动力1个）
C3: 2 | D3: 消防水箱 | E3: 水箱数量 | F3: 水位仪传感器6个（包括电动力1个）、出水管流量传感器12个（包括电动力2个）
C4: 3 | D4: 消防泵/喷淋泵 | E4: 泵数量 | F4: 电气监控28个（包括电动力4个）
C5: 4 | D5: 稳压泵 | E5: 泵数量 | F5: 电气监控、启停状态/次数监测28个（包括电动力4个）
C6: 5 | D6: 隔膜气压罐 | E6: 罐体数量 | F6: 14个（包括电动力2个）
C7: 6 | D7: 配电柜 | E7: 柜体数量 | F7: 电气监控9个（包括电动力2个）
C8: 7 | D8: 控制柜 | E8: 柜体数量 | F8: 电气监控、远程手自动变更28个（包括电动力4个）
C9: 8 | D9: 消防测试栓 | E9: 屋面测试栓数量 | F9: 压力传感器 30
C10: 9 | D10: 末端测试 | E10: 末端数量 | F10: 压力传感器 200
C11: 10 | D11: 消防泵房 | E11: 泵房数量 | F11: 9个（包括电动力2个消防泵房/稳压泵房）
C12: 11 | D12: 进水阀 | E12: 水池、水箱水量 | F12: 流量计、压力传感器13个（包括电动力2个）
C13: 12 | D13: 关键管路（进出水主管） | E13: 进出水管数量 | F13: 阀门启闭状态检测、压力传感器、流量监测（50个阀门启闭状态、压力传感器、流量监测）
C14: 13 | D14: 湿式报警阀\预作用阀 | E14: 报警阀数量 | F14: 上下腔压力监测、判断，水力警铃传感69个报警阀、69个水力警铃
... C16: 15 | D16: 消防水炮主机 | E16: 水炮数量 | F16: 电磁阀启动信号 2
B17: 全淹没气灭 | C17: 16 | D17: 环境检测 | E17: 全淹没房间数量 | F17: 氧浓度监测接入消防平台 33个
C18: 17 | D18: 电磁阀、泄压口 | E18: 瓶体数量 | F18: 压力传感器/电磁阀启动监测（100个）
B19: 排烟系统 | C19: 18 | D19: 排烟风机 | E19: 风机数量 | F19: 排烟风速计量（含风向）110
C20: 19 | D20: 电动挡烟垂壁 | E20: / | F20: 释放状态
B21: 防火卷帘 | F21: 释放状态
B22: 排水系统 | C22: 20 | D22: 雨水截止阀 | F22: 自动灭火后联动对应雨水截止阀关闭
C23: 21 | D23: 关键机房、泵房排水泵 | E23: 水泵数量 | F23: 启闭监测 24个（6个消防泵房）
C24: 22 | D24: 关键机房、泵房 | F24: 防水浸监测（10个）
B25: 可燃气体 | C25: 23 | D25: 可燃气体报警主机 | E25: 主机数量 | F25: 可燃气体报警主机接入消防平台 8个
C26: 24 | D26: 可燃气体管路 | E26: 燃气管道数量 | F26: 燃气、压缩空气等管道加装可联动电磁阀 （2个）
B27: 电气火灾监控 | F27: 在线电压、剩余电流检测、电缆温度检测 数量太多400+
B28: 视频监控系统 | C28: 25 | D28: 自动报警系统 | F28: 自动报警系统联动范围摄像头、算法判断 数量太多1000+
C29: 26 | D29: 安全出口堵塞 | F29: 摄像头算法判断安全出口、疏散通道 150+
C30: 27 | D30: 屋面光伏摄像头 | F30: 烟雾、火焰摄像头 （60+）
D31: 电动自行车充电区 | F31: 40+
D32: 电动叉车充电区 | F32: 8
D33: AGV充电区 | F33: 15
D34: 电动汽车充电区 | F34: 60+
D35: 厨房灶台 | F35: 15+
B36: 关键岗位通讯设备 | C36: 28 | D36: 手持设备 | F36: 关键岗位用于设备点检、救援联动、保修维修等功能(12-15台）
A37: 智慧安防系统 | B37: 周界防护 | C37: 29 | D37: 震动光纤 | F37: 光纤、接收器等（4000米周长）
C38: 30 | D38: 周界监控 | F38: 基于算法和震动光纤提示报警（40台摄像机）
C39: 31 | D39: 红外对射报警 | F39: 对车辆道闸下口、窄小区域提示报警（11）
B40: 全面监控 | C40: 32 | D40: 屋面 | F40: 鹰眼相机 提供园区概状视频监控3-4台
C41: 33 | D41: 车道相机 | F41: 对违停、逆行等行为进行算法判断20台
...
