Workbook

Sheet 报价汇总
A1: 东明石化集团 非生产区域视频监控智能化改造项目 报价汇总表
A3: 序号 | B3: 项目 / 分部分项 | C3: 合价（元） | D3: 备注
A4: 一 | B4: 前端采集设备 | C4: =SUM(价格清单!H5:H8) -> 0 | D4: 摄像机（周界/重点/门岗/更换）
A5: 二 | B5: 智能分析设备 | C5: =SUM(价格清单!H11:H13) -> 0 | D5: AI边缘服务器及算法授权
A6: 三 | B6: 平台与软件 | C6: =SUM(价格清单!H15:H17) -> 0 | D6: 平台服务器、≥3000路授权、时钟服务器
A7: 四 | B7: 存储设备 | C7: =SUM(价格清单!H19:H20) -> 0 | D7: 32/64路NVR（≥90天）
A8: 五 | B8: 网络传输设备 | C8: =SUM(价格清单!H23:H30) -> 0 | D8: 华为交换机、光缆、奇安信防火墙
A9: 六 | B9: 监控中心及大屏 | C9: =SUM(价格清单!H32:H37) -> 0 | D9: 46寸无边框LCD拼接3×6（18块）及配套
A10: 七 | B10: 辅材与施工 | C10: =SUM(价格清单!H39:H42) -> 0 | D10: 支架立杆、综合布线、安装调试
A11: 八 | B11: 服务 | C11: =SUM(价格清单!H44:H47) -> 0 | D11: IP规划、联调验收、培训、质保运维
A12: 小计（不含税） | C12: =SUM(C4:C11) -> 0
A13: 增值税（9%） | C13: =ROUND(C12*0.09,2) -> 0
A14: 合计（固定总价，含税9%） | C14: =ROUND(C12*1.09,2) -> 0
A15: 人民币（大写）

Sheet 价格清单
A1: 东明石化集团 非生产区域视频监控智能化改造项目价格清单
A3: 序号 | B3: 设备/材料名称 | C3: 品牌/型号 | D3: 主要技术参数 / 规格 | E3: 单位 | F3: 数量 | G3: 单价(元) | H3: 合价(元) | I3: 备注
A4: 一、前端采集设备
A5: 1 | B5: 网络高清枪型摄像机（周界补盲） | C5: 海康威视 DS-2CD2T4HJX-SZBZ | D5: 400万定焦智能筒型网络摄像机，深度学习算法 支持越界/区域入侵/进入/离开侦测，联动声光报警 最高分辨率 2688×1520@25fps 支持背光补偿、强光抑制、3D 数字降噪 星光级低照度，日夜臻全彩成像 内置麦克风&扬声器，支持语音对讲 红外/白光补光，防护等级 IP67 支持 H.265+ 智能编码，支持 Smart 事件 | E5: 台 | F5: 58 | H5: =IFERROR(F5*G5,"") -> 0 | I5: 华汪围墙周界补盲
A6: 2 | B6: 网络高清枪型摄像机（重点部位补盲） | C6: 海康威视 DS-2CD2T4HJX-SZBZ | D6: 400万定焦智能筒型网络摄像机，深度学习算法 支持越界/区域入侵/进入/离开侦测，联动声光报警 最高分辨率 2688×1520@25fps 支持背光补偿、强光抑制、3D 数字降噪 星光级低照度，日夜臻全彩成像 内置麦克风&扬声器，支持语音对讲 红外/白光补光，防护等级 IP67 支持 H.265+ 智能编码，支持 Smart 事件 | E6: 台 | F6: 3 | H6: =IFERROR(F6*G6,"") -> 0 | I6: 东明港运围墙/重点设备
A7: 3 | B7: 宽动态卡口/枪型摄像机（门岗补盲） | C7: 海康威视 DS-2CD224HJX-SZBZ | D7: 轻智能筒型网络摄像机，鳞镜补光、F1.0 大光圈镜头 1/1.8″背照式传感器，日夜臻全彩成像 最高分辨率 2560×1440@25fps 支持智能资源模式：人脸/人体/车辆结构化 AI-ISP 图像处理，夜视效果场景自适应 支持越界/区域入侵等行为侦测与联动 内置麦克风&扬声器，支持语音对讲 防护等级 IP67，支持 H.265+ 智能编码 | E7: 台 | F7: 41 | H7: =IFERROR(F7*G7,"") -> 0 | I7: 润华实业各门岗
A8: 4 | B8: 宽动态卡口/枪型摄像机（门岗补盲） | C8: 海康威视 DS-2CD224HJX-SZBZ | D8: 轻智能筒型网络摄像机，鳞镜补光、F1.0 大光圈镜头 1/1.8″背照式传感器，日夜臻全彩成像 最高分辨率 2560×1440@25fps 支持智能资源模式：人脸/人体/车辆结构化 AI-ISP 图像处理，夜视效果场景自适应 支持越界/区域入侵等行为侦测与联动 内置麦克风&扬声器，支持语音对讲 防护等级 IP67，支持 H.265+ 智能编码 | E8: 台 | F8: 44 | H8: =IFERROR(F8*G8,"") -> 0 | I8: 各区域老旧点位更换
A9: 前端摄像机小计 | E9: 台 | F9: =F5+F6+F7+F8 -> 146
A10: 二、智能分析设备
A11: 5 | B11: AI边缘算力分析服务器 | C11: 海康威视 iDS-8664NX-I9/X | D11: 2U机架9盘位存算一体边缘计算主机，内置2颗AI引擎 存储：9×SATA（可满配16TB），支持热插拔及RAID0/1/5/6/10+全局热备 网络2×千兆RJ45；视频2×HDMI+2×VGA；报警16入4出；RS-232/485 接入64路H.264/H.265，最大解码32×1080P，输入带宽384Mbps 智能模式6选1：目标识别/周界防范/周界大模型二次分析/视频结构化/以图搜图/高空抛物 智能文搜：开放式语义检索、秒级响应 周界防范：单引擎12路2MP，支持大模型二次分析 视频结构化：人/车/非机动车抓拍、车牌识别与车牌库报警 | E11: 台 | F11: 1 | H11: =IFERROR(F11*G11,"") -> 0 | I11: 承载193路AI分析，按24路/台配置含20%余量 | J11: 原来9台
B12: AI边缘算力分析服务器 | C12: iDS-96256NX-H24R | D12: 4U标准机架式24盘位边缘计算主机，整机采用无线缆模块化设计，1+1冗余电源，1+1冗余风扇，支持前置硬盘热插拔，网络接口：4个10M/100M/1000M/2.5Gbps网口，输入带宽：1Gbps 输出带宽：768Mbps 接入能力：256路H.264、H.265格式高清码流接入 解码能力：最大支持32×1080P 存储接口：24个SATA口，支持满配20TB硬盘（总容量可达480TB) 智能模式6选1：目标识别/周界防范/周界大模型二次分析/视频结构化/以图搜图/高空抛物 智能文搜：开放式语义检索、秒级响应 周界防范：单引擎12路2MP，支持大模型二次分析 视频结构化：人/车/非机动车抓拍、车牌识别与车牌库报警 | E12: 台 | F12: 1 | H12: =IFERROR(F12*G12,"") -> 0 | J12: 原0台
A13: 6 | B13: AI行为分析算法授权 | C13: 海康威视 （随服务器/按路授权） | D13: 周界入侵、越线报警等行为分析算法，按路授权，报警统一接入平台 | E13: 路 | F13: 216 | G13: 0 | H13: =IFERROR(F13*G13,"") -> 0 | I13: 对应需AI升级摄像机193台
A14: 三、平台与软件
A15: 7 | B15: 平台服务器 | C15: 海康威视 DS-VM22R-CL/R2 | D15: 2U双路机架服务器，2颗海光C86（3350）处理器，≥8核、主频≥3.0GHz 内存64G DDR4（8插槽，最大可扩至1TB） 系统盘2×600G 10K SAS（RAID1），前置最多12×3.5"热插拔盘 配SAS_HBA阵列卡（RAID0/1/10），最多4个PCIE插槽 网口2×千兆板载+2×千兆PCIE，可选配2×万兆 550W（1+1）铂金冗余电源；1个IPMI管理口 | E15: 台 | F15: 4 | H15: =IFERROR(F15*G15,"") -> 0 | I15: ISC平台服务器3台，运维平台服务器1台（全新采购，不利旧）
A16: 8 | B16: 视频及报警接入授权 | C16: 海康威视（软件授权） | D16: 视频+报警接入授权，新增≥3000路，含扩展余量 | E16: 路 | F16: 3000 | H16: =IFERROR(F16*G16,"") -> 0 | I16: 全新采购，不利旧
A17: 9 | B17: 时钟同步服务器（NTP） | C17: 千星时频 | D17: NTP/GPS·北斗统一授时，为管理平台、NVR及前端设备提供统一时间基准，保证录像与报警时序一致， 6个千兆口，AC+DC冗余供电，主机+10米天线，满足等保要求 | E17: 台 | F17: 1 | H17: =IFERROR(F17*G17,"") -> 0 | I17: 新增，规格以深化设计为准
A18: 四、存储设备
A19: 10 | B19: 网络硬盘录像机（32路） | C19: 海康威视 DS-8632NX-K9/Pro | D19: 2U机架9盘位嵌入式NVR（可满配12TB） 接入32路H.264/H.265，最大解码24×1080P 输入带宽256Mbps/输出160Mbps 网络2×千兆，视频2×HDMI+2×VGA 内置AI，支持以文搜图/以图搜图（各32路）、目标识别 报警16入9出，RS-232/485，eSATA扩展 | E19: 台 | F19: 19 | H19: =IFERROR(F19*G19,"") -> 0 | I19: 满足90天录像，预留10%余量；已包含硬盘，（型号可能依据现场情况做少量调整）
A20: 11 | B20: 网络硬盘录像机（64路） | C20: 海康威视 DS-8664NX-I16/Pro | D20: 3U机架16盘位嵌入式NVR（可满配20TB） 接入64路H.264/H.265，最大解码48×1080P 输入带宽512Mbps（开RAID为256）/输出256Mbps 支持RAID0/1/5/6/10+全局热备（与智能应用互斥） 内置AI，支持以文搜图/以图搜图（各64路）、目标识别 网络2×千兆，视频3×HDMI+2×VGA | E20: 台 | F20: 8 | H20: =IFERROR(F20*G20,"") -> 0 | I20: 满足90天录像，预留10%余量；已包含硬盘
A21: =MAX($A$1:A20)+1 -> 12 | B21: 监控级硬盘 | C21: 海康威视 （企业级监控硬盘） | D21: 企业级监控级硬盘，配合上述NVR满足全域90天录像，配合H.265智能压缩；单盘容量以深化设计为准 | E21: 个 | F21: 175 | H21: =IFERROR(F21*G21,"") -> 0 | I21: 配套NVR，容量以勘查为准 | J21: 原来252
A22: 五、网络传输设备
A23: 12 | B23: 48口全万兆光三层网管交换机 | C23: 华为 S6730-S48X6Q-V2 | D23: S6730-S48X6Q-V2(48个万兆SFP+,6个40GE QSFP28,可选license升级到6个100GE QSFP28,含双电源) | E23: 台 | F23: 1 | H23: =IFERROR(F23*G23,"") -> 0 | I23: 集团监控专网核心，双机热备
A24: 13 | B24: 24千兆电/4万兆光交换机（园区汇聚） | C24: 华为 S5735-S24T4XE-V2 | D24: S5735-S24T4XE-V2(24个10/100/1000BASE-T以太网端口,4个万兆SFP+,2个12GE堆叠口,含双电源) | E24: 台 | F24: 20 | H24: =IFERROR(F24*G24,"") -> 0 | I24: 对应30余个独立监控室/二级单位 | J24: 原来35台
A25: 14 | B25: 4口接入交换机（POE） | C25: 海康威视 | D25: 2光4电POE接入交换机，万兆光上联，用于新增/更换前端接入及边缘设备 | E25: 台 | F25: 58 | H25: =IFERROR(F25*G25,"") -> 0
A26: 15 | B26: 无线网桥 | C26: 海康威视 | D26: 3KM无线传输网桥，用于不便布线点位 | E26: 对 | F26: 10 | H26: =IFERROR(F26*G26,"") -> 0
A27: 16 | B27: 万兆光模块（SFP+） | C27: 万兆光模块（SFP+） | D27: 光模块-SFP+-10G-单模模块(1310nm,40km,LC) | E27: 只 | F27: 160 | H27: =IFERROR(F27*G27,"") -> 0 | I27: 主干及汇聚上联
A28: 17 | B28: 室外单模光缆（GYTA/GYTS） | C28: 国产优质12芯单模 | D28: 室外铠装单模光缆，用于未联通二级公司到集团监控网的联通，复用为主、新布为辅（12芯单模） | E28: 米 | F28: 2000 | H28: =IFERROR(F28*G28,"") -> 0 | I28: 复用为主、新布为辅，以线路勘查为准 | J28: 原来8000
A29: 18 | B29: 光缆熔接/尾纤/光纤配线架 | C29: 国产优质 | D29: 含熔接、尾纤、配线架及跳纤等 | E29: 项 | F29: 1 | H29: =IFERROR(F29*G29,"") -> 0 | I29: 配合光缆联通
A30: 19 | B30: 下一代防火墙 | C30: 奇安信 NSG2000-TE40P | D30: 网络层吞吐量7G，并发连接≥350万，每秒新建连接数7万， 标准1U机箱，单电源，标准配置板载6个10/100/1000M自适应电、2个SFP插槽，另有2个扩展插槽，1个Console口， 含一年硬件维保服务。1年病毒防护特征库升级服务，1年入侵防御特征库升级服务 | E30: 台 | F30: 1 | H30: =IFERROR(F30*G30,"") -> 0 | I30: 监控平台安全边界
A31: 六、监控中心及大屏
A32: 20 | B32: 监控操作台（多联坐席） | C32: 定制 | D32: 多联监控操作台，含理线、承重与人体工学设计 | E32: 套 | F32: 1 | H32: =IFERROR(F32*G32,"") -> 0 | I32: 值班坐席，暂估6联
A33: 21 | B33: LCD无边液晶拼接单元 | C33: 海康威视 DS-D2A461LR | D33: 46寸D-LED液晶拼接单元，物理拼缝0.88mm 分辨率1920×1080@60Hz，亮度500cd/㎡，对比度1000:1 可视角178°，支持24小时连续工作 支持HDMI/DVI输入、U盘多媒体播放、背光分区调光 红外遥控/快捷面板/串口统一控制 | E33: 台 | F33: 18 | H33: =IFERROR(F33*G33,"") -> 0 | I33: 3*6，46寸超窄边(0.88mm拼缝)
A34: 22 | B34: LCD拼接屏支架 | C34: 海康威视 DP-D2X46XXX-1X1-Q1-AW-Q0.6-ZF | D34: 46寸气动前维护壁挂支架，可前维护、快速安装 优质冷轧钢SPCC，静电喷塑涂层>60μm 适合5行10列以内拼接，需承重墙且墙面平整 | E34: 台 | F34: 18 | H34: =IFERROR(F34*G34,"") -> 0 | I34: 前维护壁挂
A35: 23 | B35: 视频解码矩阵 | C35: DS-6A20UD-T | D35: 视频解码矩阵，用于大屏解码上墙，按需扩展解码板卡（支持200路以上上墙） | E35: 台 | F35: 1 | H35: =IFERROR(F35*G35,"") -> 0 | I35: 大屏上墙解码
A36: 24 | B36: 客户端工作站 | C36: 海康威视 DS-AXF142P/W10E/ShowOS | D36: 图形工作站 C/S+B/S架构，浏览器统一管理显示屏/中控/拼控/KVM/配电柜等 网页/客户端/APP（安卓/鸿蒙/iOS/Windows）三端实时同步 支持远程操控播控主机与大屏内容调度，多分辨率抓屏/编码 支持网页/程序/图片/视频/PPT/Word/Excel/PDF等窗口拖放布局 可查看播控屏分辨率、主机名、在离线及内存等状态 | E36: 台 | F36: 2 | H36: =IFERROR(F36*G36,"") -> 0 | I36: 图形工作站
A37: 25 | B37: 42U机柜 | C37: 图腾（42U 800×800mm） | D37: 42U 800×800mm 标准机柜，带竖向理线槽及理线架 | E37: 台 | F37: 0 | H37: =IFERROR(F37*G37,"") -> 0 | J37: 原来2台利旧2台
A38: 七、辅材与施工
A39: 26 | B39: 摄像机支架/立杆/防水箱/电源 | C39: 国产 | D39: 配合新增及更换点位安装的支架、立杆、防水盒、电源适配等 | E39: 套 | F39: 100 | H39: =IFERROR(F39*G39,"") -> 0 | I39: 配合146个点位
A40: 27 | B40: 综合布线 | C40: 国产优质CAT6 | D40: CAT6 | E40: 米 | F40: 12500 | H40: =IFERROR(F40*G40,"") -> 0
A41: 28 | B41: PVC管 | C41: 联塑PVC20 | D41: PVC20 穿线管及敷设 | E41: 米 | F41: 10000 | H41: =IFERROR(F41*G41,"") -> 0
...

Sheet 摄像机点位明细
A1: 摄像机点位明细表（补盲 / 更换 / AI升级 / 在建）
A3: 序号 | B3: 一级单位 | C3: 监控位置 | D3: 补盲新增/台 | E3: 老旧更换/台 | F3: AI升级/路 | G3: 在建衔接/台 | H3: 备注
A4: 1 | B4: 东明炼化公司 | C4: 前海化工 | F4: 58 | H4: AI周界/越线
A5: 2 | B5: 东明炼化公司 | C5: 洁源环保 | F5: 27 | H5: AI周界/越线
A6: 3 | B6: 东明炼化公司 | C6: 万海氯碱 | F6: 8 | H6: AI周界/越线
A7: 4 | B7: 东明炼化公司 | C7: 万海（LNG） | F7: 2 | H7: AI周界/越线
A8: 5 | B8: 公共工程公司 | C8: 园区 | G8: 70 | H8: 在建，同步纳管
A9: 6 | B9: 公共工程公司 | C9: 华汪围墙 | D9: 58 | H9: 周界补盲，带拾音喊话
A10: 7 | B10: 鲁班建安公司 | C10: 防腐厂 | F10: 46 | H10: AI周界/越线
A11: 8 | B11: 东明港运公司 | C11: 围墙/仓库/值班室/重点设备 | D11: 3 | F11: 44 | H11: 补盲3台 + AI 44路
A12: 9 | B12: PO/SM建设分公司 | C12: 围墙 | F12: 8 | H12: AI周界/越线
A13: 10 | B13: 战略采购中心 | C13: 中油仓库 | G13: 10 | H13: 在建
A14: 11 | B14: 战略采购中心 | C14: 润泽仓库 | G14: 4 | H14: 在建
A15: 12 | B15: 战略采购中心 | C15: 华汪库区 | G15: 2 | H15: 在建
A16: 13 | B16: 战略采购中心 | C16: 防腐厂惠生仓库 | G16: 6 | H16: 在建
A17: 14 | B17: 润华实业 | C17: 各门岗 | D17: 41 | H17: 门岗补盲，覆盖前后20m
A18: 15 | B18: 各区域 | C18: 老旧点位（以勘查为准） | E18: 44 | H18: 等量更换，≥400万像素
A19: 合计 | B19: 12 个一级单位 / 约 40 点位 | D19: =SUM(D4:D18) -> 102 | E19: =SUM(E4:E18) -> 44 | F19: =SUM(F4:F18) -> 193 | G19: =SUM(G4:G18) -> 92
