Workbook

Sheet 报价汇总
A1: 东明石化集团 非生产区域视频监控智能化改造项目 报价汇总表
A2: 本表各分项合价及合计由公式自动取自『价格清单』；报价为固定总价、含增值税（税率9%）。
A4: 序号 | B4: 项目 / 分部分项 | C4: 合价（元） | D4: 备注
A5: 一 | B5: 前端采集设备 | C5: =SUM(价格清单!I6:I9) -> 67649.05 | D5: 摄像机（周界/重点/门岗/更换）
A6: 二 | B6: 智能分析设备 | C6: =SUM(价格清单!I12:I13) -> 118700.46 | D6: AI边缘服务器及算法授权
A7: 三 | B7: 平台与软件 | C7: =SUM(价格清单!I15:I17) -> 252589.5 | D7: 平台服务器、≥3000路授权、时钟服务器
A8: 四 | B8: 存储设备 | C8: =SUM(价格清单!I19:I20) -> 843590.27 | D8: 32/64路NVR（≥90天）
A9: 五 | B9: 网络传输设备 | C9: =SUM(价格清单!I22:I29) -> 375286.18 | D9: 华为交换机、光缆、奇安信防火墙
A10: 六 | B10: 监控中心及大屏 | C10: =SUM(价格清单!I31:I36) -> 247334.63 | D10: 46寸无边框LCD拼接3×6（18块）及配套
A11: 七 | B11: 辅材与施工 | C11: =SUM(价格清单!I38:I41) -> 230531.98 | D11: 支架立杆、综合布线、安装调试
A12: 八 | B12: 服务 | C12: =SUM(价格清单!I43:I46) -> 43040.83 | D12: IP规划、联调验收、培训、质保运维
A13: 小计（不含税） | C13: =SUM(C5:C12) -> 2178722.9
A14: 增值税（9%） | C14: =ROUND(C13*0.09,2) -> 196085.06
A15: 合计（固定总价，含税9%） | C15: =ROUND(C13*1.09,2) -> 2374808 | D15: ↔ 与『价格清单』联动
A16: 人民币（大写） | C16: 贰佰叁拾柒万肆仟捌佰零柒元玖角陆分

Sheet 价格清单
A1: 东明石化集团 非生产区域视频监控智能化改造项目 价格清单（工程量清单）
A2: 固定总价报价（含税，税率9%）；型号/参数/数量/单价以工程量清单为准，合价=数量×单价，底部自动合计。
A4: 序号 | B4: 设备/材料名称 | C4: 品牌/型号 | D4: 主要技术参数 / 规格 | E4: 单位 | F4: 数量 | G4: 性质 | H4: 单价(元) | I4: 合价(元) | J4: 备注
A5: 一、前端采集设备
A6: 1 | B6: 网络高清枪型摄像机（周界补盲） | C6: 海康威视 DS-2CD2T4HJX-SZBZ | D6: 400万定焦智能筒型网络摄像机 采用深度学习硬件及算法，支持越界侦测，区域入侵侦测，进入区域侦测和离开区域侦测，支持联动声光报警 最高分辨率可达2688 × 1520 @25 fps，在该分辨率下可输出实时图像 支持背光补偿，强光抑制，3D数字降噪，120 dB宽动态 支持ROI感兴趣区域增强编码，支持Smart265/264编码，可根据场景情况自适应调整码率分配，有效节省存储成本 支持萤石平台，海康互联接入 1个内置麦克风，1个内置扬声器，支持双向语音对讲 支持最大256 GB MicroSD/MicroSDHC/MicroSDXC卡本地存储 支持1路报警输入，1路报警输出（报警输出最大支持AC24 V/DC24 V，1 A），1路音频输入，1路音频输出 FWDA4-LS型号支持：DC12 V，100 mA电源输出，可用于拾音器供电 支持白光/红外双补光，红外最远可达50 m，白光最远可达30 m 符合IP66防尘防水设计，可靠性高 支持对运动人脸抓拍和属性分析，支持快速抓拍和优选抓拍两种模式，支持对不同目标进行检测、抓拍，最多同时检测10张人脸 自研观澜编码Lite，省存储，画质稳 传感器类型：1/3" Progressive Scan CMOS 最低照度：彩色：0.005 Lux 宽动态：120 dB 焦距&视场角：4 mm，水平视场角：78.3°，垂直视场角：42.9°，对角视场角：91.2° 6 mm，水平视场角：49.1°，垂直视场角：26.3°，对角视场角：57.2° 8 mm，水平视场角：37.5°，垂直视场角：20.7°，对角视场角：43.3° 补光灯类型：智能补光，可切换白光灯、红外灯 补光距离：红外光最远可达50 m，白光最远可达30 m 防补光过曝：支持 最大图像尺寸：2688 × 1520 视频压缩标准：主码流：H.265/H.264 子码流：H.265/H.264/MJPEG 第三码流：H.265/H.264 网络：1个RJ45 10 M/100 M自适应以太网口 SD卡扩展：内置MicroSD/MicroSDHC/MicroSDXC 插槽，最大支持256 GB 音频：1路输入（Line in）：2芯端子，最大输入幅值：3.3 Vpp，输入阻抗：2.2 kΩ，接口类型：非平衡 1路输出（Line out）：2芯端子，最大输出幅值：3.3 Vpp，输出阻抗：100 Ω，接口类型：非平衡 1个内置麦克风，1个内置扬声器 报警：1路输入，1路输出（报警输出最大支持AC24 V/DC24 V，1 A） 复位：支持 电源输出：DC12 V，100 mA，可用于拾音器供电 智能警戒：区域入侵侦测，越界侦测，进入区域侦测，离开区域侦测（支持人形、车形检测） 产品尺寸：2.8 mm焦距段型号： 182.8 × 92.7 × 87.6 mm 其他焦距段型号： 189.4 × 92.7 × 87.6 mm 设备重量：FWDA4-LS型号：630 g FDWDA4-LS型号：610 g 包装尺寸：235 × 120 × 125 mm 带包装重量：FWDA4-LS型号：830 g FDWDA4-LS型号：810 g 启动及工作温湿度：-30 ℃~60 ℃，湿度小于95%（无凝结） 电流及功耗：DC：12v,0.87A,MAX:10.5W POE：PoE(IEEE 802.3af class 3)，MAX：12W *FWDA4-LS型号支持PoE 供电方式：DC：12 V ± 25%，支持防反接保护 PoE：802.3af，Class 3 *FWDA4-LS型号支持PoE 电源接口类型：Ø5.5 mm圆口 防护：IP66 | E6: 台 | F6: 58 | G6: 新增 | H6: 577.64 | I6: =IFERROR(F6*H6,"") -> 33503.12 | J6: 华汪围墙周界补盲
A7: 2 | B7: 网络高清枪型摄像机（重点部位补盲） | C7: 海康威视 DS-2CD2T4HJX-SZBZ | D7: 400万定焦智能筒型网络摄像机 采用深度学习硬件及算法，支持越界侦测，区域入侵侦测，进入区域侦测和离开区域侦测，支持联动声光报警 最高分辨率可达2688 × 1520 @25 fps，在该分辨率下可输出实时图像 支持背光补偿，强光抑制，3D数字降噪，120 dB宽动态 支持ROI感兴趣区域增强编码，支持Smart265/264编码，可根据场景情况自适应调整码率分配，有效节省存储成本 支持萤石平台，海康互联接入 1个内置麦克风，1个内置扬声器，支持双向语音对讲 支持最大256 GB MicroSD/MicroSDHC/MicroSDXC卡本地存储 支持1路报警输入，1路报警输出（报警输出最大支持AC24 V/DC24 V，1 A），1路音频输入，1路音频输出 FWDA4-LS型号支持：DC12 V，100 mA电源输出，可用于拾音器供电 支持白光/红外双补光，红外最远可达50 m，白光最远可达30 m 符合IP66防尘防水设计，可靠性高 支持对运动人脸抓拍和属性分析，支持快速抓拍和优选抓拍两种模式，支持对不同目标进行检测、抓拍，最多同时检测10张人脸 自研观澜编码Lite，省存储，画质稳 传感器类型：1/3" Progressive Scan CMOS 最低照度：彩色：0.005 Lux 宽动态：120 dB 焦距&视场角：4 mm，水平视场角：78.3°，垂直视场角：42.9°，对角视场角：91.2° 6 mm，水平视场角：49.1°，垂直视场角：26.3°，对角视场角：57.2° 8 mm，水平视场角：37.5°，垂直视场角：20.7°，对角视场角：43.3° 补光灯类型：智能补光，可切换白光灯、红外灯 补光距离：红外光最远可达50 m，白光最远可达30 m 防补光过曝：支持 最大图像尺寸：2688 × 1520 视频压缩标准：主码流：H.265/H.264 子码流：H.265/H.264/MJPEG 第三码流：H.265/H.264 网络：1个RJ45 10 M/100 M自适应以太网口 SD卡扩展：内置MicroSD/MicroSDHC/MicroSDXC 插槽，最大支持256 GB 音频：1路输入（Line in）：2芯端子，最大输入幅值：3.3 Vpp，输入阻抗：2.2 kΩ，接口类型：非平衡 1路输出（Line out）：2芯端子，最大输出幅值：3.3 Vpp，输出阻抗：100 Ω，接口类型：非平衡 1个内置麦克风，1个内置扬声器 报警：1路输入，1路输出（报警输出最大支持AC24 V/DC24 V，1 A） 复位：支持 电源输出：DC12 V，100 mA，可用于拾音器供电 智能警戒：区域入侵侦测，越界侦测，进入区域侦测，离开区域侦测（支持人形、车形检测） 产品尺寸：2.8 mm焦距段型号： 182.8 × 92.7 × 87.6 mm 其他焦距段型号： 189.4 × 92.7 × 87.6 mm 设备重量：FWDA4-LS型号：630 g FDWDA4-LS型号：610 g 包装尺寸：235 × 120 × 125 mm 带包装重量：FWDA4-LS型号：830 g FDWDA4-LS型号：810 g 启动及工作温湿度：-30 ℃~60 ℃，湿度小于95%（无凝结） 电流及功耗：DC：12v,0.87A,MAX:10.5W POE：PoE(IEEE 802.3af class 3)，MAX：12W *FWDA4-LS型号支持PoE 供电方式：DC：12 V ± 25%，支持防反接保护 PoE：802.3af，Class 3 *FWDA4-LS型号支持PoE 电源接口类型：Ø5.5 mm圆口 防护：IP66 | E7: 台 | F7: 3 | G7: 新增 | H7: 577.64 | I7: =IFERROR(F7*H7,"") -> 1732.92 | J7: 东明港运围墙/重点设备
A8: 3 | B8: 宽动态卡口/枪型摄像机（门岗补盲） | C8: 海康威视 DS-2CD224HJX-SZBZ | D8: 海康威视轻智能筒型网络摄像机，支持鳞镜补光、F1.0光圈镜头，夜间成像效果更出色 采用1/1.8"背照式传感器，相比传统摄像机前照式传感器，增加的进光量对图像质量有明显的改善作用，F1.0超大光圈镜头，日夜臻全彩成像 支持智能资源模式：人脸抓拍（默认），Smart事件，热度图，人数统计，道路监控，普通监控 适用于混行道路、重点出入口、园区、路口路段等需要进行人车管理的场景 鳞镜补光：采用隐藏式灯珠设计，通过鳞甲密布排列形成的镜面反射出光，见光不见灯；增加发光面积，降低聚光效果，补光柔和均匀 Smart录像：支持断网续传功能保证录像不丢失，配合Smart NVR/SD卡实现事件录像的智能后检索、分析和浓缩播放，Smart编码：支持低码率、低延时、ROI感兴趣区域增强编码、SVC自适应编码技术，支持Smart265编码 系统功能：支持开放型网络视频接口、ISAPI、GB/T28181和E-HOME协议接入；支持三码流技术，支持同时20路取流；支持萤石平台接入 宽动态：支持宽动态范围达120 dB，适合逆光环境监控 图像相关：支持400万像素 @60 fps实时帧率，图像更流畅；支持透雾，电子防抖，并具有多种白平衡模式，适合各种场景需求 安全服务：支持三级用户权限管理，支持授权的用户和密码，支持IP地址过滤 接口功能：内置MicroSD/MicroSDHC/MicroSDXC插槽，最大支持512 GB；支持10 M/100 M自适应网口；支持一对报警输入输出 支持电量检测：支持设备功耗检测，支持设备功耗报表展示，报表类型支持日报表和周报表（默认日报表，单位瓦时（Wh）） Smart事件模式：徘徊侦测，人员聚集侦测，快速运动侦测，停车侦测，物品拿取侦测，物品遗留侦测，场景变更侦测，音频陡升侦测，音频陡降侦测，音频有无侦测，虚焦侦测，支持联动声光预警 传感器类型：1/1.8" Progressive Scan CMOS 最低照度：彩色：0.0005 Lux @（F1.0，AGC ON），0 Lux with Light 宽动态：120 dB 焦距&视场角：2.8 mm：水平视场角：105.7°，垂直视场角：57.3°，对角视场角：124.9° 4 mm：水平视场角：88.7°，垂直视场角：44.7°，对角视场角：107.5° 6 mm：水平视场角：54.8°，垂直视场角：29.2°，对角视场角：64.2° 8 mm：水平视场角：40.7°，垂直视场角：22.9°，对角视场角：46.6° 补光灯类型：鳞镜补光，暖白光，4颗灯珠 补光距离：白光：普通监控：最远可达30 m，人脸抓拍/识别：最远可达5 m 防补光过曝：支持防补光过曝开启和关闭，开启下支持自动和手动，手动支持根据距离等级控制补光灯亮度 最大图像尺寸：2560 × 1440 视频压缩标准：H.265/H.264/MJPEG 网络：1个RJ45 10 M/100 M自适应以太网口 SD卡扩展：内置MicroSD/MicroSDHC/MicroSDXC 插槽，最大支持512 GB 音频：1路输入（Line in），1路输出（Line out），2个内置麦克风，1个内置扬声器 报警：1路输入，1路输出（报警输入支持开关量，报警输出最大支持DC12 V，30 mA） RS-485：1个RS-485接口，半双工模式，支持自适应HIKVISION，PELCO-P和PELCO-D协议 复位：支持 电源输出：支持DC12 V，100 mA 接口类型：外甩线 产品尺寸：180.3 × 99.2 × 94 mm 包装尺寸：315 × 137 × 141 mm 设备重量：750 g 带包装重量：1080 g 存储温湿度：-30 °C~60 °C，湿度小于95%（无凝结） 启动和工作温湿度：-30 °C~60 °C，湿度小于95%（无凝结） 电流及功耗：DC：12 V，1.1 A，最大功耗：13.2 W PoE：802.3at，42.5 V~57 V，0.35 A~0.26 A，最大功耗：14.7 W 供电方式：DC：12 V ± 20%，支持防反接保护 PoE：802.3at，Type 2，Class 4 电源接口类型：3芯电源接口 线缆长度：35 cm 防护：IP67 | E8: 台 | F8: 41 | G8: 新增 | H8: 282.05 | I8: =IFERROR(F8*H8,"") -> 11564.05 | J8: 润华实业各门岗
A9: 4 | B9: 网络摄像机（老旧更换） | C9: 海康威视 DS-2CD224HJX-SZBZ | D9: 全彩级高灵敏度传感器，F1.0超大光圈镜头，提供更清晰的视频流输入 海康自研AI ISP图像处理引擎，影像随场景自适应，夜视效果随时在线 最高分辨率可达2560 × 1440 @25 fps，在该分辨率下可输出实时图像 内置麦克风&扬声器，喊话对讲全兼顾 人/车目标分类，报警精准减打扰 支持背光补偿，强光抑制，3D数字降噪，120 dB宽动态适应不同监控环境 海康自研超级智能编码，省存储，画质稳 支持柔光灯补光，照射距离最远可达30 m 符合IP67防尘防水设计，可靠性高 在大模型的加持下，对人、机动车等高价值目标进行解析，通过ROI分割技术，分离前景目标与背景区域，前景采用常规编码保障细节完整，背景实施高效压缩降低存储占用，兼顾画质与效率 传感器类型：1/1.8" Progressive Scan CMOS 最低照度：彩色：0.0005 Lux 宽动态：120 dB 焦距&视场角：2.8 mm，水平视场角：105.7°，垂直视场角：57.2°，对角视场角：124.5° 4 mm，水平视场角：88.7°，垂直视场角：44.7°，对角视场角：107.5° 6 mm，水平视场角：55.2°，垂直视场角：29.3°，对角视场角：64.6° 8 mm，水平视场角：38.8°，垂直视场角：21.1°，对角视场角：45.2° 补光距离：最远可达30 m 防补光过曝：支持 补光灯类型：柔光灯 最大图像尺寸：2560 × 1440 视频压缩标准：主码流：H.265/H.264，支持超级智能编码 子码流：H.265/H.264/MJPEG 第三码流：H.265/H.264 音频：支持1个内置麦克风 支持1个内置扬声器 网络：1个RJ45 10 M/100 M自适应以太网口 恢复出厂设置：支持客户端或浏览器恢复 启动和工作温湿度：-30 °C~60 °C，湿度小于95%（无凝结） 供电方式：DC：12 V ± 25%，支持防反接保护 PoE：IEEE 802.3af，CLASS 3 电流及功耗：DC：12 V，0.75 A，最大功耗：9 W PoE：IEEE 802.3af，CLASS 3，最大功耗：10.5W 电源接口类型：Ø5.5 mm圆口 产品尺寸：2.8 mm焦距段型号： 182.8 × 92.7 × 87.6 mm 其他焦距段型号： 189.4 × 92.7 × 87.6 mm 包装尺寸：235 × 120 × 125 mm 设备重量：575 g 带包装重量：705 g 防护：IP67 | E9: 台 | F9: 44 | G9: 新增 | H9: 473.84 | I9: =IFERROR(F9*H9,"") -> 20848.96 | J9: 各区域老旧点位，以勘查为准（观澜算法）
A10: 前端摄像机小计 | E10: 台 | F10: =F6+F7+F8+F9 -> 146
A11: 二、智能分析设备
A12: 5 | B12: AI边缘算力分析服务器 | C12: 海康威视 iDS-8664NX-I9/X | D12: 2U机架9盘位存算一体边缘计算主机，内置2颗AI引擎 存储：9×SATA（可满配16TB），支持热插拔及RAID0/1/5/6/10+全局热备 网络2×千兆RJ45；视频2×HDMI+2×VGA；报警16入4出；RS-232/485 接入64路H.264/H.265，最大解码32×1080P，输入带宽384Mbps 智能模式6选1：目标识别/周界防范/周界大模型二次分析/视频结构化/以图搜图/高空抛物 智能文搜：开放式语义检索、秒级响应 周界防范：单引擎12路2MP，支持大模型二次分析 视频结构化：人/车/非机动车抓拍、车牌识别与车牌库报警 | E12: 台 | F12: 9 | G12: 新增 | H12: 13188.94 | I12: =IFERROR(F12*H12,"") -> 118700.46 | J12: 承载193路AI分析，按24路/台配置含20%余量
A13: 6 | B13: AI行为分析算法授权 | C13: 海康威视 （随服务器/按路授权） | D13: 周界入侵、越线报警等行为分析算法，按路授权，报警统一接入平台 | E13: 路 | F13: 193 | G13: 新增 | I13: =IFERROR(F13*H13,"") -> 0 | J13: 对应需AI升级摄像机193台
A14: 三、平台与软件
A15: 7 | B15: 平台服务器 | C15: 海康威视 DS-VM22R-CL/R2 | D15: 2U双路机架服务器，2颗海光C86（3350）处理器，≥8核、主频≥3.0GHz 内存64G DDR4（8插槽，最大可扩至1TB） 系统盘2×600G 10K SAS（RAID1），前置最多12×3.5"热插拔盘 配SAS_HBA阵列卡（RAID0/1/10），最多4个PCIE插槽 网口2×千兆板载+2×千兆PCIE，可选配2×万兆 550W（1+1）铂金冗余电源；1个IPMI管理口 | E15: 台 | F15: 4 | G15: 新增 | H15: 33864.05 | I15: =IFERROR(F15*H15,"") -> 135456.2 | J15: ISC平台服务器3台，运维平台服务器1台（全新采购，不利旧）
A16: 8 | B16: 视频及报警接入授权 | C16: 海康威视 （软件授权） | D16: 视频+报警接入授权，新增≥3000路，含扩展余量 | E16: 路 | F16: 3000 | G16: 新增 | H16: 36.6 | I16: =IFERROR(F16*H16,"") -> 109800 | J16: 全新采购，不利旧
A17: 9 | B17: 时钟同步服务器（NTP） | C17: （待选型） | D17: NTP/GPS·北斗统一授时，为管理平台、NVR及前端设备提供统一时间基准，保证录像与报警时序一致，满足等保要求 | E17: 台 | F17: 1 | G17: 新增 | H17: 7333.3 | I17: =IFERROR(F17*H17,"") -> 7333.3 | J17: 新增，规格以深化设计为准
A18: 四、存储设备
A19: 10 | B19: 网络硬盘录像机（32路） | C19: 海康威视 DS-8632NX-K9/Pro | D19: 2U机架9盘位嵌入式NVR（可满配12TB） 接入32路H.264/H.265，最大解码24×1080P 输入带宽256Mbps/输出160Mbps 网络2×千兆，视频2×HDMI+2×VGA 内置AI，支持以文搜图/以图搜图（各32路）、目标识别 报警16入9出，RS-232/485，eSATA扩展 | E19: 台 | F19: 19 | G19: 新增 | H19: 26411.29 | I19: =IFERROR(F19*H19,"") -> 501814.51 | J19: 满足90天录像，预留10%余量；不含硬盘
A20: 11 | B20: 网络硬盘录像机（64路） | C20: 海康威视 DS-8664NX-I16/Pro | D20: 3U机架16盘位嵌入式NVR（可满配20TB） 接入64路H.264/H.265，最大解码48×1080P 输入带宽512Mbps（开RAID为256）/输出256Mbps 支持RAID0/1/5/6/10+全局热备（与智能应用互斥） 内置AI，支持以文搜图/以图搜图（各64路）、目标识别 网络2×千兆，视频3×HDMI+2×VGA | E20: 台 | F20: 8 | G20: 新增 | H20: 42721.97 | I20: =IFERROR(F20*H20,"") -> 341775.76 | J20: 满足90天录像，预留10%余量；不含硬盘
A21: 五、网络传输设备
A22: 12 | B22: 48口全万兆光三层网管交换机 | C22: 华为 S6730-S48X6Q-V2 | D22: S6730-S48X6Q-V2(48个万兆SFP+,6个40GE QSFP28,可选license升级到6个100GE QSFP28,含双电源) | E22: 台 | F22: 2 | G22: 新增 | H22: 18248.4 | I22: =IFERROR(F22*H22,"") -> 36496.8 | J22: 集团监控专网核心，双机热备
A23: 13 | B23: 24千兆电/4万兆光交换机（园区汇聚） | C23: 华为 S5735-S24T4XE-V2 | D23: S5735-S24T4XE-V2(24个10/100/1000BASE-T以太网端口,4个万兆SFP+,2个12GE堆叠口,含双电源) | E23: 台 | F23: 35 | G23: 新增 | H23: 4784.69 | I23: =IFERROR(F23*H23,"") -> 167464.15 | J23: 对应30余个独立监控室/二级单位
A24: 14 | B24: 4口接入交换机（POE） | C24: 华为 （待选型） | D24: 2光4电POE接入交换机，万兆光上联，用于新增/更换前端接入及边缘设备 | E24: 台 | F24: 58 | G24: 新增 | H24: 733.33 | I24: =IFERROR(F24*H24,"") -> 42533.14
A25: 15 | B25: 无线网桥 | C25: （待选型） | D25: 3KM无线传输网桥，用于不便布线点位 | E25: 对 | F25: 10 | G25: 新增 | H25: 620.51 | I25: =IFERROR(F25*H25,"") -> 6205.1
A26: 16 | B26: 万兆光模块（SFP+） | C26: 海康威视 HK-SFP+-10G-10-1310-DF | D26: 光模块-SFP+-10G-单模模块(1310nm,40km,LC) | E26: 只 | F26: 160 | G26: 新增 | H26: 90.26 | I26: =IFERROR(F26*H26,"") -> 14441.6 | J26: 主干及汇聚上联
A27: 17 | B27: 室外单模光缆（GYTA/GYTS） | C27: （12芯单模） | D27: 室外铠装单模光缆，用于未联通二级公司到集团监控网的联通，复用为主、新布为辅（12芯单模） | E27: 米 | F27: 8000 | G27: 新增 | H27: 5.64 | I27: =IFERROR(F27*H27,"") -> 45120 | J27: 复用为主、新布为辅，以线路勘查为准
A28: 18 | B28: 光缆熔接/尾纤/光纤配线架 | C28: — | D28: 含熔接、尾纤、ODF配线架及跳纤等 | E28: 项 | F28: 1 | G28: 新增 | H28: 16923 | I28: =IFERROR(F28*H28,"") -> 16923 | J28: 配合光缆联通
A29: 19 | B29: 下一代防火墙 | C29: 奇安信 NSG2000-TE40P | D29: 网络层吞吐量7G，并发连接≥350万，每秒新建连接数7万， 标准1U机箱，单电源，标准配置板载6个10/100/1000M自适应电、2个SFP插槽，另有2个扩展插槽，1个Console口， 含一年硬件维保服务。1年病毒防护特征库升级服务，1年入侵防御特征库升级服务 | E29: 台 | F29: 1 | G29: 新增 | H29: 46102.39 | I29: =IFERROR(F29*H29,"") -> 46102.39 | J29: 监控平台安全边界
A30: 六、监控中心及大屏
A31: 20 | B31: 监控操作台（多联坐席） | C31: 定制 | D31: 多联监控操作台，含理线、承重与人体工学设计 | E31: 套 | F31: 1 | G31: 新增 | H31: 8100 | I31: =IFERROR(F31*H31,"") -> 8100 | J31: 值班坐席，暂估6联
A32: 21 | B32: LCD无边液晶拼接单元 | C32: 海康威视 DS-D2A461LR | D32: 46寸D-LED液晶拼接单元，物理拼缝0.88mm 分辨率1920×1080@60Hz，亮度500cd/㎡，对比度1000:1 可视角178°，支持24小时连续工作 支持HDMI/DVI输入、U盘多媒体播放、背光分区调光 红外遥控/快捷面板/串口统一控制 | E32: 台 | F32: 18 | G32: 新增 | H32: 8799.95 | I32: =IFERROR(F32*H32,"") -> 158399.1 | J32: 居中LED两侧、左右各6块，46寸超窄边(3.5mm拼缝)
A33: 22 | B33: LCD拼接屏支架 | C33: 海康威视 DP-D2X46XXX-1X1-Q1-AW-Q0.6-ZF | D33: 46寸气动前维护壁挂支架，可前维护、快速安装 优质冷轧钢SPCC，静电喷塑涂层>60μm 适合5行10列以内拼接，需承重墙且墙面平整 | E33: 台 | F33: 18 | G33: 新增 | H33: 902.56 | I33: =IFERROR(F33*H33,"") -> 16246.08 | J33: 前维护壁挂
A34: 23 | B34: 视频解码矩阵 | C34: （新增配置） | D34: 视频解码矩阵，用于大屏解码上墙，按需扩展解码板卡（支持100路以上上墙） | E34: 台 | F34: 1 | G34: 新增 | H34: 32266.51 | I34: =IFERROR(F34*H34,"") -> 32266.51 | J34: 大屏上墙解码
A35: 24 | B35: 客户端工作站 | C35: 海康威视 DS-AXF142P/W10E/ShowOS | D35: 图形工作站（参考H610标底参数），双屏 C/S+B/S架构，浏览器统一管理显示屏/中控/拼控/KVM/配电柜等 网页/客户端/APP（安卓/鸿蒙/iOS/Windows）三端实时同步 支持远程操控播控主机与大屏内容调度，多分辨率抓屏/编码 支持网页/程序/图片/视频/PPT/Word/Excel/PDF等窗口拖放布局 可查看播控屏分辨率、主机名、在离线及内存等状态 | E35: 台 | F35: 2 | G35: 新增 | H35: 13566.61 | I35: =IFERROR(F35*H35,"") -> 27133.22 | J35: 图形工作站，双屏
A36: 25 | B36: 42U机柜 | C36: （42U 800×800mm） | D36: 42U 800×800mm 标准机柜 | E36: 台 | F36: 2 | G36: 新增 | H36: 2594.86 | I36: =IFERROR(F36*H36,"") -> 5189.72
A37: 七、辅材与施工
A38: 26 | B38: 摄像机支架/立杆/防水箱/电源 | C38: — | D38: 配合新增及更换点位安装的支架、立杆、防水盒、电源适配等 | E38: 套 | F38: 100 | G38: 新增 | H38: 710.76 | I38: =IFERROR(F38*H38,"") -> 71076 | J38: 配合146个点位
A39: 27 | B39: 综合布线 | C39: （CAT6） | D39: CAT6 | E39: 米 | F39: 12500 | G39: 新增 | H39: 3.28 | I39: =IFERROR(F39*H39,"") -> 41000 | J39: 以现场为准
A40: 28 | B40: PVC管 | C40: （PVC20） | D40: PVC20 穿线管及敷设 | E40: 米 | F40: 10000 | G40: 新增 | H40: 2.82 | I40: =IFERROR(F40*H40,"") -> 28200
A41: 29 | B41: 安装、接入与系统调试 | C41: — | D41: 前端安装、平台接入级联、AI与存储调试、网络割接与联调 | E41: 项 | F41: 1 | G41: 新增 | H41: 90255.98 | I41: =IFERROR(F41*H41,"") -> 90255.98 | J41: 含分区割接、不停业务
...

Sheet 摄像机点位明细
A1: 摄像机点位明细表（补盲 / 更换 / AI升级 / 在建）
A3: 序号 | B3: 一级单位 | C3: 监控位置 | D3: 补盲新增/台 | E3: 老旧更换/台 | F3: AI升级/路 | G3: 在建衔接/台 | H3: 备注
A4: 1 | B4: 东明炼化公司 | C4: 前海化工 | F4: 58 | H4: AI周界/越线
A5: 2 | B5: 东明炼化公司 | C5: 洁源环保 | F5: 27 | H5: AI周界/越线
A6: 3 | B6: 东明炼化公司 | C6: 万海氯碱 | F6: 8 | H6: AI周界/越线
A7: 4 | B7: 东明炼化公司 | C7: 万海（LNG） | F7: 2 | H7: AI周界/越线
A8: 5 | B8: 公共工程公司 | C8: 园区 | G8: 70 | H8: 在建，同步纳管
A9: 6 | B9: 公共工程公司 | C9: 华汪围墙 | D9: 58 | H9: 周界补盲，带拾音喊话
A10: 7 | B10: 鲁班建安公司 | C10: 防腐厂 | F10: 46 | H10: AI周界/越线
A11: 8 | B11: 东明港运公司 | C11: 围墙/仓库/值班室/重点设备 | D11: 3 | F11: 44 | H11: 补盲3台 + AI 44路
A12: 9 | B12: PO/SM建设分公司 | C12: 围墙 | F12: 8 | H12: AI周界/越线
A13: 10 | B13: 战略采购中心 | C13: 中油仓库 | G13: 10 | H13: 在建
A14: 11 | B14: 战略采购中心 | C14: 润泽仓库 | G14: 4 | H14: 在建
A15: 12 | B15: 战略采购中心 | C15: 华汪库区 | G15: 2 | H15: 在建
A16: 13 | B16: 战略采购中心 | C16: 防腐厂惠生仓库 | G16: 6 | H16: 在建
A17: 14 | B17: 润华实业 | C17: 各门岗 | D17: 41 | H17: 门岗补盲，覆盖前后20m，含拾音喊话
A18: 15 | B18: 各区域 | C18: 老旧点位（以勘查为准） | E18: 44 | H18: 等量更换，≥400万像素
A19: 合计 | B19: 12 个一级单位 / 约 40 点位 | D19: =SUM(D4:D18) -> 102 | E19: =SUM(E4:E18) -> 44 | F19: =SUM(F4:F18) -> 193 | G19: =SUM(G4:G18) -> 92 | H19: 应为 102 / 44 / 193 / 92
