Workbook

Sheet 总表
A1: 总表
A2: 序号 | B2: 项目 | C2: 金额（元）
A3: 1 | B3: 1#、3#、8#、15#数据中心非管控区五方对讲 | C3: ='1#、3#、8#、15#五方对讲系统'!N7 -> 4224
A4: 2 | B4: 1#楼数据中心—柴发区域自控及弱电工程-BA系统 | C4: ='1#数据中心BA系统'!N9 -> 29549.91
A5: 3 | B5: 1#楼数据中心—柴发区域自控及弱电工程-安防门禁系统 | C5: ='1#数据中心安防门禁系统'!N39 -> 209298.03
A6: 4 | B6: 1#楼数据中心—柴发区域自控及弱电工程-综合布线系统 | C6: ='1#数据中心综合布线系统'!N35 -> 68130.3
A7: 5 | B7: 3#楼数据中心—柴发区域自控及弱电工程-BA系统 | C7: ='3#数据中心BA系统'!N11 -> 29549.91
A8: 6 | B8: 3#楼数据中心—柴发区域自控及弱电工程-安防门禁系统 | C8: ='3#数据中心安防门禁系统'!N38 -> 200431.02
A9: 7 | B9: 3#楼数据中心—柴发区域自控及弱电工程-综合布线系统 | C9: ='3#数据中心综合布线系统'!N34 -> 67681.33
A10: 8 | B10: 8#、15#、及门卫数据中心非管控区-入侵报警系统工程 | C10: ='8#、15#非管区入侵报警系统'!N56 -> 124363.36
A11: 9 | B11: 8#、15#、及门卫数据中心非管控区-时钟同步系统工程 | C11: ='8#、15#非管区时钟同步系统'!N22 -> 255533.89
A12: 10 | B12: 8#、15#、及门卫数据中心非管控区-视频监控系统工程 | C12: ='8#、15#非管区视频监控系统'!N123 -> 4735454.7
A13: 11 | B13: 8#、15#、及门卫数据中心非管控区-巡更系统工程 | C13: ='8#、15#非管区巡更系统'!N14 -> 48299.94
A14: 12 | B14: 8#、15#、及门卫数据中心非管控区-一卡通系统工程 | C14: ='8#、15#非管区一卡通系统'!N108 -> 846622.44
A15: 13 | B15: 8#、15#、及门卫数据中心非管控区园区智能化管理平台系统工程 | C15: ='8#、15#非管区园区智能化管理平台系统'!N40 -> 241713.92
A16: 14 | B16: 8#、15#、及门卫数据中心非管控区-综合布线系统工程 | C16: ='8#、15#非管区综合布线系统'!N68 -> 1674589
A17: 15 | B17: 8#、15#数据中心非管控区-BA系统工程 | C17: ='8#、15#非管区BA系统'!N124 -> 496864.29
A18: 16 | B18: 8#、15#数据中心非管控区-多媒体会议系统工程 | C18: ='8#、15#非管区多媒体系统'!N509 -> 4749832.1
A19: 17 | B19: 8#、15#数据中心非管控区-信息发布系统工程 | C19: ='8#、15#非管区信息发布系统'!N45 -> 495770.62
A20: 18 | B20: 8#楼ECC非管控区-灯光控制工程 | C20: ='8#楼ECC非管区灯光控制工程'!N42 -> 100300.06
A21: 19 | B21: 8#楼ECC非管控区-电动窗帘控制工程 | C21: ='8#楼ECC非管区电动窗帘控制工程'!N23 -> 76041.54
A22: 20 | B22: 15#楼生产综合楼-灯光控制工程 | C22: ='15#楼生产综合楼灯光控制工程'!N41 -> 106164.59
A23: 21 | B23: 15#楼生产综合楼-电动窗帘控制工程 | C23: ='15#楼生产楼电动窗帘控制工程'!N24 -> 133556.53
A24: 22 | B24: 15#生产综合楼-值班室、机房、工具间 | C24: ='15#楼生产综合楼值班室、机房、工具间'!N151 -> 568252.22
B25: 总计 | C25: =SUM(C3:C24) -> 15262224

Sheet 1#、3#、8#、15#五方对讲系统
A1: 分部分项工程和单价措施项目清单与计价表
A2: 工程名称：1#、3#、8#、15#数据中心非管控区五方对讲 | G2: 标段：兴业银行贵安新区数据中心项目（一期）室内装修及机电配套工程 | L2: 第 1 页 共 1 页
A3: 序号 | B3: 项目编码 | C3: 项目名称 | D3: 项目特征描述 | E3: 计量单位 | F3: 工程量 | G3: 金额（元）
G4: 主材/设备费 | H4: 辅材 | I4: 机械措施 | J4: 人工 | K4: 管理费 | L4: 利润 | M4: 税金 | N4: 总价
A5: 1 | B5: 030411004092 | C5: 配线 | D5: 1.名称:五方对讲线缆 2.型号:RYYSP-6*1.0 3.其它:满足完成此项工作所需要的全部工作内容，包括设计图纸、技术规范书、答疑、招标文件、现行规范、图集、验收等全部要求 | E5: m | F5: 192 | G5: 803.23 | H5: 211.38 | I5: 105.69 | J5: 591.85 | K5: 169.1 | L5: 232.51 | M5: 190.24 | N5: =SUM(G5:M5) -> 2304
A6: 2 | B6: 030411004093 | C6: 配线 | D6: 1.名称:五方对讲线缆 2.型号:RYYSP-2*1.5 3.其它:满足完成此项工作所需要的全部工作内容，包括设计图纸、技术规范书、答疑、招标文件、现行规范、图集、验收等全部要求 | E6: m | F6: 192 | G6: 669.36 | H6: 176.15 | I6: 88.07 | J6: 493.21 | K6: 140.92 | L6: 193.76 | M6: 158.53 | N6: =SUM(G6:M6) -> 1920
A7: 本页小计 | N7: =SUM(N5:N6) -> 4224
A8: 总计 | N8: =N7 -> 4224

Sheet 1#数据中心BA系统
A1: 分部分项工程和单价措施项目清单与计价表
A2: 工程名称：1#楼数据中心—柴发区域自控及弱电工程-BA系统 | G2: 标段：兴业银行贵安新区数据中心项目（一期）室内装修及机电配套工程 | L2: 第 1 页 共 1 页
A3: 序号 | B3: 项目编码 | C3: 项目名称 | D3: 项目特征描述 | E3: 计量单位 | F3: 工程量 | G3: 金额（元）
G4: 主材/设备费 | H4: 辅材 | I4: 机械措施 | J4: 人工 | K4: 管理费 | L4: 利润 | M4: 税金 | N4: 总价
A5: 1 | B5: 080901001003 | C5: 交换机 | D5: 1.名称：接入交换机 2.参数： 支持交流或直流供电,支持冗余电源; ≥48个千兆以太网电接口; ≥4端口千兆以太网光接口; 工作环境温度-5℃~45℃; 工作环境相对湿度(非凝露) 5%~95%; 电源接口:支持双电源供电; 配10G上行光模块 3.其他:满足完成此项工作所需要的全部工作内容，包括设计图纸、技术规范书、答疑、招标文件、现行规范、图集、验收等全部要求 | E5: 台 | F5: 1 | G5: 2862.39 | H5: 110.09 | I5: 36.7 | J5: 146.79 | K5: 110.09 | L5: 403.67 | M5: 330.28 | N5: =SUM(G5:M5) -> 4000.01
A6: 2 | B6: 030503003005 | C6: DDC控制器 | D6: 1.名称：DDC控制箱（含控制器等） 2.其他:满足完成此项工作所需要的全部工作内容，包括设计图纸、技术规范书、答疑、招标文件、现行规范、图集、验收等全部要求 | E6: 台 | F6: 1 | G6: 2504.59 | H6: 96.33 | I6: 32.11 | J6: 128.44 | K6: 96.33 | L6: 353.21 | M6: 288.99 | N6: =SUM(G6:M6) -> 3500
A7: 3 | B7: 030503010002 | C7: 建筑设备自控化系统试运行 | D7: 1.名称:建筑设备自控化系统试运行 2.其他:满足完成此项工作所需要的全部工作内容，包括设计图纸、技术规范书、答疑、招标文件、现行规范、图集、验收等全部要求 | E7: 系统 | F7: 1 | G7: 7059.6 | H7: 1857.8 | I7: 928.9 | J7: 5201.8 | K7: 1486.2 | L7: 2043.6 | M7: 1672 | N7: =SUM(G7:M7) -> 20249.9
A8: 4 | B8: 031301017003 | C8: 脚手架搭拆 | D8: 1.脚手架费 2.按项包干 3.其它:满足完成此项工作所需要的全部工作内容，包括设计图纸、技术规范书、答疑、招标文件、现行规范、图集、验收等全部要求 | E8: 项 | F8: 1 | G8: 627.51 | H8: 165.15 | I8: 82.56 | J8: 462.39 | K8: 132.12 | L8: 181.65 | M8: 148.62 | N8: =SUM(G8:M8) -> 1800
A9: 本页小计 | N9: =SUM(N5:N8) -> 29549.91
A10: 总计 | N10: =N9 -> 29549.91

Sheet 1#数据中心安防门禁系统
A1: 分部分项工程和单价措施项目清单与计价表
A2: 分部分项工程和单价措施项目清单与计价表
A3: 序号 | B3: 项目编码 | C3: 项目名称 | D3: 项目特征描述 | E3: 计量单位 | F3: 工程量 | G3: 金额（元）
G4: 主材/设备费 | H4: 辅材 | I4: 机械措施 | J4: 人工 | K4: 管理费 | L4: 利润 | M4: 税金 | N4: 总价
A5: 1 | B5: 030503003001 | C5: 控制器 | D5: 1.名称：D1-1门禁控制器（配套安防箱） 2.参数：详见设计图纸及技术规范书 3.其他:满足完成此项工作所需要的全部工作内容，包括设计图纸、技术规范书、答疑、招标文件、现行规范、图集、验收等全部要求 | E5: 台 | F5: 2 | G5: 1452.66 | H5: 55.87 | I5: 18.62 | J5: 74.5 | K5: 55.87 | L5: 204.86 | M5: 167.61 | N5: =SUM(G5:M5) -> 2029.99
A6: 2 | B6: 030503003002 | C6: 控制器 | D6: 1.名称：D1-2门禁控制器（配套安防箱） 2.参数：详见设计图纸及技术规范书 3.其他:满足完成此项工作所需要的全部工作内容，包括设计图纸、技术规范书、答疑、招标文件、现行规范、图集、验收等全部要求 | E6: 台 | F6: 2 | G6: 1452.66 | H6: 55.87 | I6: 18.62 | J6: 74.5 | K6: 55.87 | L6: 204.86 | M6: 167.61 | N6: =SUM(G6:M6) -> 2029.99
A7: 3 | B7: 030503003003 | C7: 控制器 | D7: 1.名称：D2-2门禁控制器（配套安防箱） 2.参数：详见设计图纸及技术规范书 3.其他:满足完成此项工作所需要的全部工作内容，包括设计图纸、技术规范书、答疑、招标文件、现行规范、图集、验收等全部要求 | E7: 台 | F7: 23 | G7: 16705.6 | H7: 642.52 | I7: 214.17 | J7: 856.7 | K7: 642.52 | L7: 2355.92 | M7: 1927.57 | N7: =SUM(G7:M7) -> 23345
A8: 4 | B8: 030503003004 | C8: 控制器 | D8: 1.名称：D3-2门禁控制器（配套安防箱） 2.参数：详见设计图纸及技术规范书 3.其他:满足完成此项工作所需要的全部工作内容，包括设计图纸、技术规范书、答疑、招标文件、现行规范、图集、验收等全部要求 | E8: 台 | F8: 2 | G8: 1452.66 | H8: 55.87 | I8: 18.62 | J8: 74.5 | K8: 55.87 | L8: 204.86 | M8: 167.61 | N8: =SUM(G8:M8) -> 2029.99
A9: 本页小计 | N9: =SUM(N5:N8) -> 29434.97
A10: 5 | B10: 030507006001 | C10: 出入口控制设备 | D10: 1.名称：门禁读卡器 2.参数：详见设计图纸及技术规范书 3.其他:满足完成此项工作所需要的全部工作内容，包括设计图纸、技术规范书、答疑、招标文件、现行规范、图集、验收等全部要求 | E10: 台 | F10: 28 | G10: 9016.51 | H10: 346.79 | I10: 115.6 | J10: 462.39 | K10: 346.79 | L10: 1271.56 | M10: 1040.37 | N10: =SUM(G10:M10) -> 12600.01
A11: 6 | B11: 030507006002 | C11: 出入口控制设备 | D11: 1.名称：出门按钮 2.参数：详见设计图纸及技术规范书 3.其他:满足完成此项工作所需要的全部工作内容，包括设计图纸、技术规范书、答疑、招标文件、现行规范、图集、验收等全部要求 | E11: 台 | F11: 3 | G11: 30.06 | H11: 1.16 | I11: 0.39 | J11: 1.54 | K11: 1.16 | L11: 4.24 | M11: 3.47 | N11: =SUM(G11:M11) -> 42.02
A12: 7 | B12: 030507006003 | C12: 出入口控制设备 | D12: 1.名称：电控锁 2.参数：详见设计图纸及技术规范书 3.其他:满足完成此项工作所需要的全部工作内容，包括设计图纸、技术规范书、答疑、招标文件、现行规范、图集、验收等全部要求 | E12: 台 | F12: 52 | G12: 5295.41 | H12: 441.28 | I12: 176.51 | J12: 1323.85 | K12: 617.8 | L12: 970.83 | M12: 794.31 | N12: =SUM(G12:M12) -> 9619.99
A13: 8 | B13: 030507006004 | C13: 出入口控制设备 | D13: 1.名称：门磁开关 2.参数：详见设计图纸及技术规范书 3.其他:满足完成此项工作所需要的全部工作内容，包括设计图纸、技术规范书、答疑、招标文件、现行规范、图集、验收等全部要求 | E13: 台 | F13: 54 | G13: 1352.48 | H13: 52.02 | I13: 17.34 | J13: 69.36 | K13: 52.02 | L13: 190.73 | M13: 156.06 | N13: =SUM(G13:M13) -> 1890.01
A14: 本页小计 | N14: =SUM(N10:N13) -> 24152.03
A15: 9 | B15: 030507006005 | C15: 出入口控制设备 | D15: 1.名称：玻璃破碎应急按钮 2.参数：详见设计图纸及技术规范书 3.其他:满足完成此项工作所需要的全部工作内容，包括设计图纸、技术规范书、答疑、招标文件、现行规范、图集、验收等全部要求 | E15: 台 | F15: 27 | G15: 2975.45 | H15: 114.44 | I15: 38.15 | J15: 152.59 | K15: 114.44 | L15: 419.61 | M15: 343.32 | N15: =SUM(G15:M15) -> 4158
A16: 10 | B16: 030507005001 | C16: 出入口目标识别设备 | D16: 1.名称：人脸识别机 2.参数：详见设计图纸及技术规范书 3.其他:满足完成此项工作所需要的全部工作内容，包括设计图纸、技术规范书、答疑、招标文件、现行规范、图集、验收等全部要求 | E16: 台 | F16: 25 | G16: 23793.58 | H16: 915.14 | I16: 305.05 | J16: 1220.18 | K16: 915.14 | L16: 3355.5 | M16: 2745.41 | N16: =SUM(G16:M16) -> 33250
A17: 11 | B17: 030411006001 | C17: 接线盒 | D17: 1.名称:接线盒 2.参数：详见设计图纸及技术规范书 3.其他:满足完成此项工作所需要的全部工作内容，包括设计图纸、技术规范书、答疑、招标文件、现行规范、图集、验收等全部要求 | E17: 个 | F17: 25 | G17: 217.89 | H17: 57.34 | I17: 28.67 | J17: 160.55 | K17: 45.87 | L17: 63.07 | M17: 51.61 | N17: =SUM(G17:M17) -> 625
A18: 12 | B18: 030411001002 | C18: 配管 | D18: 1.名称:紧定式镀锌钢导管 2.材质:JDG25 3.敷设方式:综合考虑 4.其他:满足完成此项工作所需要的全部工作内容，满足设计图纸、技术规范书、答疑、招标文件、现行规范、图集、验收等全部要求 | E18: m | F18: 300 | G18: 522.94 | H18: 137.61 | I18: 68.81 | J18: 385.32 | K18: 110.09 | L18: 151.38 | M18: 123.85 | N18: =SUM(G18:M18) -> 1500
A19: 本页小计 | N19: =SUM(N15:N18) -> 39533
A20: 13 | B20: 030411001003 | C20: 配管 | D20: 1.名称:紧定式镀锌钢导管 2.材质:JGD20 3.敷设方式:综合考虑 4.其他:满足完成此项工作所需要的全部工作内容，满足设计图纸、技术规范书、答疑、招标文件、现行规范、图集、验收等全部要求 | E20: m | F20: 300 | G20: 470.64 | H20: 123.85 | I20: 61.93 | J20: 346.79 | K20: 99.08 | L20: 136.24 | M20: 111.47 | N20: =SUM(G20:M20) -> 1350
A21: 14 | B21: 030413002002 | C21: 凿（压)槽 | D21: 1.名称:二次结构凿槽 2.规格:DN32以内 3.类型:砼、砌筑结构 4.含填补恢复 5.满足完成此项工作所需要的全部工作内容，满足设计图纸、技术规范书、答疑、招标文件、现行规范、图集、验收等全部要求 | E21: m | F21: 200 | G21: 543.85 | H21: 143.12 | I21: 71.56 | J21: 400.73 | K21: 114.5 | L21: 157.43 | M21: 128.81 | N21: =SUM(G21:M21) -> 1560
A22: 15 | B22: 030413001003 | C22: 管道支架/综合支架 | D22: 1.名称:管道支架制作安装 2.材质：热镀锌 3.其它：满足完成此项工作所需要的全部工作内容，满足设计图纸、技术规范书、答疑、招标文件、现行规范、图集、验收等全部要求 | E22: kg | F22: 120 | G22: 543.85 | H22: 143.12 | I22: 71.56 | J22: 400.73 | K22: 114.5 | L22: 157.43 | M22: 128.81 | N22: =SUM(G22:M22) -> 1560
A23: 16 | B23: 030502007002 | C23: 光缆 | D23: 1.名称:光缆 2.规格:12芯单模光纤 3.敷设方式:桥架内敷设 4.其他:满足完成此项工作所需要的全部工作内容，满足设计图纸、技术规范书、答疑、招标文件、现行规范、图集、验收等全部要求 | E23: m | F23: 2700 | G23: 7728.44 | H23: 297.25 | I23: 99.08 | J23: 396.33 | K23: 297.25 | L23: 1089.91 | M23: 891.74 | N23: =SUM(G23:M23) -> 10800
A24: 本页小计 | N24: =SUM(N20:N23) -> 15270
A25: 17 | B25: 030502005002 | C25: 双绞线缆 | D25: 1.名称:六类八芯非屏蔽对绞线 2.规格:LSZH-UTP-Cat6-4x2x0.5 3.其他:满足完成此项工作所需要的全部工作内容，满足设计图纸、技术规范书、答疑、招标文件、现行规范、图集、验收等全部要求 | E25: m | F25: 3506 | G25: 5789.72 | H25: 482.48 | I25: 192.99 | J25: 1447.43 | K25: 675.47 | L25: 1061.45 | M25: 868.46 | N25: =SUM(G25:M25) -> 10518
A26: 18 | B26: 030411004001 | C26: 配线 | D26: 1.名称:配线 2.规格:WDZA-RYY2*1.0 3.其他:满足完成此项工作所需要的全部工作内容，满足设计图纸、技术规范书、答疑、招标文件、现行规范、图集、验收等全部要求 | E26: m | F26: 2700 | G26: 4235.78 | H26: 1114.68 | I26: 557.34 | J26: 3121.1 | K26: 891.74 | L26: 1226.15 | M26: 1003.21 | N26: =SUM(G26:M26) -> 12150
A27: 19 | B27: 030411004002 | C27: 配线 | D27: 1.名称:线缆 2.规格:WDZA-RYY-4*1.0 3.其他:满足完成此项工作所需要的全部工作内容，满足设计图纸、技术规范书、答疑、招标文件、现行规范、图集、验收等全部要求 | E27: m | F27: 2700 | G27: 4706.42 | H27: 1238.53 | I27: 619.27 | J27: 3467.89 | K27: 990.83 | L27: 1362.39 | M27: 1114.68 | N27: =SUM(G27:M27) -> 13500.01
A28: 20 | B28: 030411004003 | C28: 配线 | D28: 1.名称:线缆 2.规格:WDZA-RYSP-4*1.0 3.其他:满足完成此项工作所需要的全部工作内容，满足设计图纸、技术规范书、答疑、招标文件、现行规范、图集、验收等全部要求 | E28: m | F28: 2700 | G28: 5647.71 | H28: 1486.24 | I28: 743.12 | J28: 4161.47 | K28: 1188.99 | L28: 1634.86 | M28: 1337.61 | N28: =SUM(G28:M28) -> 16200
A29: 本页小计 | N29: =SUM(N25:N28) -> 52368.01
A30: 21 | B30: 030411004004 | C30: 配线 | D30: 1.名称:线缆 2.规格:WDZA-RYSP6*1.0 3.其他:满足完成此项工作所需要的全部工作内容，满足设计图纸、技术规范书、答疑、招标文件、现行规范、图集、验收等全部要求 | E30: m | F30: 2700 | G30: 7530.28 | H30: 1981.65 | I30: 990.83 | J30: 5548.62 | K30: 1585.32 | L30: 2179.82 | M30: 1783.49 | N30: =SUM(G30:M30) -> 21600.01
A31: 22 | B31: 030411004005 | C31: 配线 | D31: 1.名称:线缆 2.规格:WDZA-RYSP8*1.0 3.其他:满足完成此项工作所需要的全部工作内容，满足设计图纸、技术规范书、答疑、招标文件、现行规范、图集、验收等全部要求 | E31: m | F31: 2700 | G31: 7530.28 | H31: 1981.65 | I31: 990.83 | J31: 5548.62 | K31: 1585.32 | L31: 2179.82 | M31: 1783.49 | N31: =SUM(G31:M31) -> 21600.01
A32: 23 | B32: 030502019002 | C32: 双绞线缆测试 | D32: 1.双绞线缆测试 2.满足完成此项工作所需要的全部工作内容，包括设计图纸、技术规范书、答疑、招标文件、现行规范、图集、验收等全部要求 | E32: 链路 | F32: 86 | G32: 239.85 | H32: 63.12 | I32: 31.56 | J32: 176.73 | K32: 50.5 | L32: 69.43 | M32: 56.81 | N32: =SUM(G32:M32) -> 688
A33: 24 | B33: 030502020002 | C33: 光纤测试 | D33: 1.光纤测试 2.满足完成此项工作所需要的全部工作内容，包括设计图纸、技术规范书、答疑、招标文件、现行规范、图集、验收等全部要求 | E33: 链路 | F33: 19 | G33: 52.99 | H33: 13.94 | I33: 6.97 | J33: 39.05 | K33: 11.16 | L33: 15.34 | M33: 12.55 | N33: =SUM(G33:M33) -> 152
A34: 25 | B34: 030507019001 | C34: 安全防范系统调试 | D34: 1.系统调试及试运行 2.满足完成此项工作所需要的全部工作内容，包括设计图纸、技术规范书、答疑、招标文件、现行规范、图集、验收等全部要求 | E34: 系统 | F34: 1 | G34: 697.25 | H34: 183.49 | I34: 91.74 | J34: 513.76 | K34: 146.79 | L34: 201.83 | M34: 165.14 | N34: =SUM(G34:M34) -> 2000
A35: 本页小计 | N35: =SUM(N30:N34) -> 46040.02
A36: 26 | B36: 03B001 | C36: 系统综合及集成 | D36: 1.清单未列项、图纸中未表示或技术规格书未做要求，但为了实现本系统各项功能必须增加的配套及辅助的材料、设备的所有工作内容及费用； 2.施工深化设计增加的实现本系统设计功能必要的配套及辅助的材料、设备所需的所有工作内容及费用； 3.实现设计功能所做的满足图纸、技术规格书要求的各项综合与集成，包括不限于各项检测、试验、调试、软件开发、联动等所有工作内容及费用 | E36: 项 | F36: 1 | G36: 697.25 | H36: 183.49 | I36: 91.74 | J36: 513.76 | K36: 146.79 | L36: 201.83 | M36: 165.14 | N36: =SUM(G36:M36) -> 2000
A37: 27 | B37: 031301017002 | C37: 脚手架搭拆 | D37: 1.脚手架费 2.按项包干 3.其它:满足完成此项工作所需要的全部工作内容，包括设计图纸、技术规范书、答疑、招标文件、现行规范、图集、验收等全部要求 | E37: 项 | F37: 1 | G37: 174.31 | H37: 45.87 | I37: 22.94 | J37: 128.44 | K37: 36.7 | L37: 50.46 | M37: 41.28 | N37: =SUM(G37:M37) -> 500
A38: 本页小计 | N38: =SUM(N36:N37) -> 2500
A39: 总计 | N39: =N9+N14+N19+N24+N29+N35+N38 -> 209298.03

Sheet 1#数据中心综合布线系统
A1: 分部分项工程和单价措施项目清单与计价表
A2: 分部分项工程和单价措施项目清单与计价表
A3: 序号 | B3: 项目编码 | C3: 项目名称 | D3: 项目特征描述 | E3: 计量单位 | F3: 工程量 | G3: 金额（元）
G4: 主材/设备费 | H4: 辅材 | I4: 机械措施 | J4: 人工 | K4: 管理费 | L4: 利润 | M4: 税金 | N4: 总价
A5: 1 | B5: 080901001001 | C5: 交换机 | D5: 1.名称：汇聚交换机 2.参数：48口,万兆，40G上行光模块 3.详见图纸设计及相关验收规范要求等 4.其他:满足完成此项工作所需要的全部工作内容，包括设计图纸、技术规范书、答疑、招标文件、现行规范、图集、验收等全部要求 | E5: 台 | F5: 2 | G5: 10733.94 | H5: 412.84 | I5: 137.61 | J5: 550.46 | K5: 412.84 | L5: 1513.76 | M5: 1238.53 | N5: =SUM(G5:M5) -> 14999.98
A6: 2 | B6: 080901001002 | C6: 交换机 | D6: 1.名称：24口接入交换机 2.主要参数：配10G上行光模块 3.其他:满足完成此项工作所需要的全部工作内容，包括设计图纸、技术规范书、答疑、招标文件、现行规范、图集、验收等全部要求 | E6: 台 | F6: 1 | G6: 2719.27 | H6: 104.59 | I6: 34.86 | J6: 139.45 | K6: 104.59 | L6: 383.49 | M6: 313.76 | N6: =SUM(G6:M6) -> 3800.01
A7: 3 | B7: 030502010001 | C7: 配线架 | D7: 1.名称：配线架24口（含耦合器、尾纤等） 2.参数：详见设计图纸及技术规范书 3.其他:满足完成此项工作所需要的全部工作内容，包括设计图纸、技术规范书、答疑、招标文件、现行规范、图集、验收等全部要求 | E7: 个 | F7: 2 | G7: 500.92 | H7: 19.27 | I7: 6.42 | J7: 25.69 | K7: 19.27 | L7: 70.64 | M7: 57.8 | N7: =SUM(G7:M7) -> 700.01
A8: 4 | B8: 030502010002 | C8: 配线架 | D8: 1.名称：RJ45配线架 24口（含理线器、模块等） 2.参数：详见设计图纸及技术规范书 3.其他:满足完成此项工作所需要的全部工作内容，包括设计图纸、技术规范书、答疑、招标文件、现行规范、图集、验收等全部要求 | E8: 个 | F8: 1 | G8: 286.24 | H8: 11.01 | I8: 3.67 | J8: 14.68 | K8: 11.01 | L8: 40.37 | M8: 33.03 | N8: =SUM(G8:M8) -> 400.01
A9: 本页小计 | N9: =SUM(N5:N8) -> 19900.01
A10: 5 | B10: 030501005001 | C10: 插箱、机柜 | D10: 1.名称：19寸标准机柜(600*800) 42U,含风扇电源 2.其他:满足完成此项工作所需要的全部工作内容，包括设计图纸、技术规范书、答疑、招标文件、现行规范、图集、验收等全部要求 | E10: 台 | F10: 5 | G10: 6440.37 | H10: 247.71 | I10: 82.57 | J10: 330.28 | K10: 247.71 | L10: 908.26 | M10: 743.12 | N10: =SUM(G10:M10) -> 9000.02
A11: 6 | B11: 030502004001 | C11: 电视、电话插座 | D11: 1.名称：双孔信息插座（含模块） 2.参数：详见设计图纸及技术规范书 3.其它:满足完成此项工作所需要的全部工作内容，包括设计图纸、技术规范书、答疑、招标文件、现行规范、图集、验收等全部要求 | E11: 个 | F11: 3 | G11: 75.14 | H11: 2.89 | I11: 0.96 | J11: 3.85 | K11: 2.89 | L11: 10.6 | M11: 8.67 | N11: =SUM(G11:M11) -> 105
A12: 7 | B12: 030502003001 | C12: 分线接线箱（盒） | D12: 1.名称：铁质接线盒 2.参数：详见设计图纸及技术规范书 3.其它:满足完成此项工作所需要的全部工作内容，包括设计图纸、技术规范书、答疑、招标文件、现行规范、图集、验收等全部要求 | E12: 个 | F12: 3 | G12: 26.15 | H12: 6.88 | I12: 3.44 | J12: 19.27 | K12: 5.5 | L12: 7.57 | M12: 6.19 | N12: =SUM(G12:M12) -> 75
A13: 8 | B13: 030502009001 | C13: 跳线 | D13: 1.名称：跳线 2.其他:满足完成此项工作所需要的全部工作内容，包括设计图纸、技术规范书、答疑、招标文件、现行规范、图集、验收等全部要求 | E13: 条 | F13: 8 | G13: 114.5 | H13: 4.4 | I13: 1.47 | J13: 5.87 | K13: 4.4 | L13: 16.15 | M13: 13.21 | N13: =SUM(G13:M13) -> 160
A14: 9 | B14: 030502009002 | C14: LC-LC单模光纤跳线（3m） | D14: 1.名称:LC-LC单模光纤跳线（3m） 2.其它:满足完成此项工作所需要的全部工作内容，包括设计图纸、技术规范书、答疑、招标文件、现行规范、图集、验收等全部要求 | E14: 条 | F14: 12 | G14: 386.42 | H14: 14.86 | I14: 4.95 | J14: 19.82 | K14: 14.86 | L14: 54.5 | M14: 44.59 | N14: =SUM(G14:M14) -> 540
A15: 本页小计 | N15: =SUM(N10:N14) -> 9880.02
A16: 10 | B16: 030502009003 | C16: LC-LC多模光纤跳线（3m） | D16: 1.名称:LC-LC多模光纤跳线（3m） 2.其它:满足完成此项工作所需要的全部工作内容，包括设计图纸、技术规范书、答疑、招标文件、现行规范、图集、验收等全部要求 | E16: 条 | F16: 12 | G16: 343.49 | H16: 13.21 | I16: 4.4 | J16: 17.61 | K16: 13.21 | L16: 48.44 | M16: 39.63 | N16: =SUM(G16:M16) -> 479.99
A17: 11 | B17: 030502009004 | C17: 六类非屏蔽跳线（3m） | D17: 1.名称:六类非屏蔽跳线（3m） 2.其它:满足完成此项工作所需要的全部工作内容，包括设计图纸、技术规范书、答疑、招标文件、现行规范、图集、验收等全部要求 | E17: 条 | F17: 6 | G17: 107.34 | H17: 4.13 | I17: 1.38 | J17: 5.5 | K17: 4.13 | L17: 15.14 | M17: 12.39 | N17: =SUM(G17:M17) -> 150.01
A18: 12 | B18: 030411003001 | C18: 桥架 | D18: 1.名称:热浸锌钢制金属线槽 2.型号：400*100 3.包含但不限于桥架、弯头、三通或四通、盖板、隔板、附件安装、接地跨接等 4.其它:满足完成此项工作所需要的全部工作内容，满足设计图纸、技术规范书、答疑、招标文件、现行规范、图集、验收等全部要求 | E18: m | F18: 125 | G18: 4025.23 | H18: 154.82 | I18: 51.61 | J18: 206.42 | K18: 154.82 | L18: 567.66 | M18: 464.45 | N18: =SUM(G18:M18) -> 5625.01
A19: 13 | B19: 030411003002 | C19: 桥架 | D19: 1.名称:热浸锌钢制金属线槽 2.型号：200*100 3.包含但不限于桥架、弯头、三通或四通、盖板、隔板、附件安装、接地跨接等 4.其它:满足完成此项工作所需要的全部工作内容，满足设计图纸、技术规范书、答疑、招标文件、现行规范、图集、验收等全部要求 | E19: m | F19: 85.28 | G19: 4576.95 | H19: 176.04 | I19: 58.68 | J19: 234.72 | K19: 176.04 | L19: 645.48 | M19: 528.12 | N19: =SUM(G19:M19) -> 6396.03
A20: 本页小计 | N20: =SUM(N16:N19) -> 12651.04
A21: 14 | B21: 030413001001 | C21: 桥架支吊架制作及安装 | D21: 1.名称:桥架支吊架制作及安装 2.规格:综合、热浸镀锌 3.其它：满足完成此项工作所需要的全部工作内容，满足设计图纸、技术规范书、答疑、招标文件、现行规范、图集、验收等全部要求 | E21: kg | F21: 126.66 | G21: 529.88 | H21: 139.44 | I21: 69.72 | J21: 390.44 | K21: 111.55 | L21: 153.39 | M21: 125.5 | N21: =SUM(G21:M21) -> 1519.92
A22: 15 | B22: 030502005001 | C22: 双绞线缆 | D22: 1.名称:超六类非屏蔽四对双绞线 2.规格:CAT.6A UTP 3.其他:满足完成此项工作所需要的全部工作内容，包括设计图纸、技术规范书、答疑、招标文件、现行规范、图集、验收等全部要求 | E22: m | F22: 111 | G22: 183.3 | H22: 15.28 | I22: 6.11 | J22: 45.83 | K22: 21.39 | L22: 33.61 | M22: 27.5 | N22: =SUM(G22:M22) -> 333.02
A23: 16 | B23: 030411001001 | C23: 配管 | D23: 1.名称:紧定式镀锌钢导管 2.材质:JGD20 3.敷设方式:综合考虑 4.其他:满足完成此项工作所需要的全部工作内容，满足设计图纸、技术规范书、答疑、招标文件、现行规范、图集、验收等全部要求 | E23: m | F23: 15 | G23: 23.53 | H23: 6.19 | I23: 3.1 | J23: 17.34 | K23: 4.95 | L23: 6.81 | M23: 5.57 | N23: =SUM(G23:M23) -> 67.49
A24: 17 | B24: 030413002001 | C24: 凿（压)槽 | D24: 1.名称:二次结构凿槽 2.规格:DN32以内 3.类型:砼、砌筑结构 4.含填补恢复 5.满足完成此项工作所需要的全部工作内容，满足设计图纸、技术规范书、答疑、招标文件、现行规范、图集、验收等全部要求 | E24: m | F24: 10.5 | G24: 25.62 | H24: 6.74 | I24: 3.37 | J24: 18.88 | K24: 5.39 | L24: 7.42 | M24: 6.07 | N24: =SUM(G24:M24) -> 73.49
A25: 本页小计 | N25: =SUM(N21:N24) -> 1993.92
A26: 18 | B26: 030413001002 | C26: 管道支架/综合支架 | D26: 1.名称:管道支架制作安装 2.材质：热镀锌 3.其它：满足完成此项工作所需要的全部工作内容，满足设计图纸、技术规范书、答疑、招标文件、现行规范、图集、验收等全部要求 | E26: kg | F26: 0.78 | G26: 3.26 | H26: 0.86 | I26: 0.43 | J26: 2.4 | K26: 0.69 | L26: 0.94 | M26: 0.77 | N26: =SUM(G26:M26) -> 9.35
A27: 19 | B27: 030502007001 | C27: 光缆 | D27: 1.名称:光缆 2.规格:12芯单模光纤OS2 3.敷设方式:桥架内敷设 3.其他:满足完成此项工作所需要的全部工作内容，包括设计图纸、技术规范书、答疑、招标文件、现行规范、图集、验收等全部要求 | E27: m | F27: 1500 | G27: 4293.58 | H27: 165.14 | I27: 55.05 | J27: 220.18 | K27: 165.14 | L27: 605.5 | M27: 495.41 | N27: =SUM(G27:M27) -> 6000
A28: 20 | B28: 030502019001 | C28: 双绞线缆测试 | D28: 1.测试内容:4对双绞线缆 2.其他:满足完成此项工作所需要的全部工作内容，包括设计图纸、技术规范书、答疑、招标文件、现行规范、图集、验收等全部要求 | E28: 链路 | F28: 6 | G28: 16.73 | H28: 4.4 | I28: 2.2 | J28: 12.33 | K28: 3.52 | L28: 4.84 | M28: 3.96 | N28: =SUM(G28:M28) -> 47.98
A29: 21 | B29: 030502020001 | C29: 光纤测试 | D29: 1.测试内容:光纤 2.其他:满足完成此项工作所需要的全部工作内容，包括设计图纸、技术规范书、答疑、招标文件、现行规范、图集、验收等全部要求 | E29: 链路 | F29: 6 | G29: 16.73 | H29: 4.4 | I29: 2.2 | J29: 12.33 | K29: 3.52 | L29: 4.84 | M29: 3.96 | N29: =SUM(G29:M29) -> 47.98
A30: 22 | B30: 030503010001 | C30: 建筑设备自控化系统试运行 | D30: 1.名称:建筑设备自控化系统试运行 2.其他:满足完成此项工作所需要的全部工作内容，包括设计图纸、技术规范书、答疑、招标文件、现行规范、图集、验收等全部要求 | E30: 系统 | F30: 1 | G30: 5229.36 | H30: 1376.16 | I30: 688.08 | J30: 3853.2 | K30: 1100.91 | L30: 1513.77 | M30: 1238.52 | N30: =SUM(G30:M30) -> 15000
A31: 本页小计 | N31: =SUM(N26:N30) -> 21105.31
A32: 23 | B32: 03B001 | C32: 系统综合及集成 | D32: 1.清单未列项、图纸中未表示或技术规格书未做要求，但为了实现本系统各项功能必须增加的配套及辅助的材料、设备的所有工作内容及费用； 2.施工深化设计增加的实现本系统设计功能必要的配套及辅助的材料、设备所需的所有工作内容及费用； 3.实现设计功能所做的满足图纸、技术规格书要求的各项综合与集成，包括不限于各项检测、试验、调试、软件开发、联动等所有工作内容及费用 | E32: 项 | F32: 1 | G32: 697.25 | H32: 183.49 | I32: 91.74 | J32: 513.76 | K32: 146.79 | L32: 201.83 | M32: 165.14 | N32: =SUM(G32:M32) -> 2000
A33: 24 | B33: 031301017001 | C33: 脚手架搭拆 | D33: 1.脚手架费 2.按项包干 3.其它:满足完成此项工作所需要的全部工作内容，包括设计图纸、技术规范书、答疑、招标文件、现行规范、图集、验收等全部要求 | E33: 项 | F33: 1 | G33: 209.17 | H33: 55.05 | I33: 27.52 | J33: 154.13 | K33: 44.04 | L33: 60.55 | M33: 49.54 | N33: =SUM(G33:M33) -> 600
A34: 本页小计 | N34: =SUM(N32:N33) -> 2600
A35: 合 计 | N35: =N9+N15+N20+N25+N31+N34 -> 68130.3

Sheet 3#数据中心BA系统
A1: 分部分项工程和单价措施项目清单与计价表
A2: 分部分项工程和单价措施项目清单与计价表
A3: 序号 | B3: 项目编码 | C3: 项目名称 | D3: 项目特征描述 | E3: 计量单位 | F3: 工程量 | G3: 金额（元）
G4: 主材/设备费 | H4: 辅材 | I4: 机械措施 | J4: 人工 | K4: 管理费 | L4: 利润 | M4: 税金 | N4: 总价
A5: 1 | B5: 080901001006 | C5: 交换机 | D5: 1.名称：接入交换机 2.参数： 支持交流或直流供电,支持冗余电源; ≥48个千兆以太网电接口; ≥4端口千兆以太网光接口; 工作环境温度-5℃~45℃; 工作环境相对湿度(非凝露) 5%~95%; 电源接口:支持双电源供电; 配10G上行光模块 3.其他:满足完成此项工作所需要的全部工作内容，包括设计图纸、技术规范书、答疑、招标文件、现行规范、图集、验收等全部要求 | E5: 台 | F5: 1 | G5: 2862.39 | H5: 110.09 | I5: 36.7 | J5: 146.79 | K5: 110.09 | L5: 403.67 | M5: 330.28 | N5: =SUM(G5:M5) -> 4000.01
A6: 2 | B6: 030503003009 | C6: DDC控制器 | D6: 1.名称：DDC控制箱（含控制器） 2.其他:满足完成此项工作所需要的全部工作内容，包括设计图纸、技术规范书、答疑、招标文件、现行规范、图集、验收等全部要求 | E6: 台 | F6: 1 | G6: 2504.59 | H6: 96.33 | I6: 32.11 | J6: 128.44 | K6: 96.33 | L6: 353.21 | M6: 288.99 | N6: =SUM(G6:M6) -> 3500
A7: 3 | B7: 030503010004 | C7: 建筑设备自控化系统试运行 | D7: 1.名称:建筑设备自控化系统试运行 2.其他:满足完成此项工作所需要的全部工作内容，包括设计图纸、技术规范书、答疑、招标文件、现行规范、图集、验收等全部要求 | E7: 系统 | F7: 1 | G7: 7059.6 | H7: 1857.8 | I7: 928.9 | J7: 5201.8 | K7: 1486.2 | L7: 2043.6 | M7: 1672 | N7: =SUM(G7:M7) -> 20249.9
A8: 本页小计 | N8: =SUM(N5:N7) -> 27749.91
A9: 4 | B9: 031301017007 | C9: 脚手架搭拆 | D9: 1.脚手架费 2.按项包干 3.其它:满足完成此项工作所需要的全部工作内容，包括设计图纸、技术规范书、答疑、招标文件、现行规范、图集、验收等全部要求 | E9: 项 | F9: 1 | G9: 627.51 | H9: 165.15 | I9: 82.56 | J9: 462.39 | K9: 132.12 | L9: 181.65 | M9: 148.62 | N9: =SUM(G9:M9) -> 1800
A10: 本页小计 | N10: =N9 -> 1800
A11: 合 计 | N11: =N8+N10 -> 29549.91

Sheet 3#数据中心安防门禁系统
A1: 分部分项工程和单价措施项目清单与计价表
A2: 分部分项工程和单价措施项目清单与计价表
A3: 序号 | B3: 项目编码 | C3: 项目名称 | D3: 项目特征描述 | E3: 计量单位 | F3: 工程量 | G3: 金额（元）
G4: 主材/设备费 | H4: 辅材 | I4: 机械措施 | J4: 人工 | K4: 管理费 | L4: 利润 | M4: 税金 | N4: 总价
A5: 1 | B5: 030503003006 | C5: 控制器 | D5: 1.名称：D1-1门禁控制器（配套安防箱） 2.参数：详见设计图纸及技术规范书 3.其他:满足完成此项工作所需要的全部工作内容，包括设计图纸、技术规范书、答疑、招标文件、现行规范、图集、验收等全部要求 | E5: 台 | F5: 2 | G5: 1452.66 | H5: 55.87 | I5: 18.62 | J5: 74.5 | K5: 55.87 | L5: 204.86 | M5: 167.61 | N5: =SUM(G5:M5) -> 2029.99
A6: 2 | B6: 030503003007 | C6: 控制器 | D6: 1.名称：D2-2门禁控制器（配套安防箱） 2.参数：详见设计图纸及技术规范书 3.其他:满足完成此项工作所需要的全部工作内容，包括设计图纸、技术规范书、答疑、招标文件、现行规范、图集、验收等全部要求 | E6: 台 | F6: 22 | G6: 15979.27 | H6: 614.59 | I6: 204.86 | J6: 819.45 | K6: 614.59 | L6: 2253.49 | M6: 1843.76 | N6: =SUM(G6:M6) -> 22330.01
A7: 3 | B7: 030503003008 | C7: 控制器 | D7: 1.名称：D3-2门禁控制器（配套安防箱） 2.参数：详见设计图纸及技术规范书 3.其他:满足完成此项工作所需要的全部工作内容，包括设计图纸、技术规范书、答疑、招标文件、现行规范、图集、验收等全部要求 | E7: 台 | F7: 4 | G7: 2905.32 | H7: 111.74 | I7: 37.25 | J7: 148.99 | K7: 111.74 | L7: 409.72 | M7: 335.23 | N7: =SUM(G7:M7) -> 4059.99
A8: 4 | B8: 030507006006 | C8: 出入口控制设备 | D8: 1.名称：门禁读卡器 2.参数：详见设计图纸及技术规范书 3.其他:满足完成此项工作所需要的全部工作内容，包括设计图纸、技术规范书、答疑、招标文件、现行规范、图集、验收等全部要求 | E8: 台 | F8: 26 | G8: 8372.48 | H8: 322.02 | I8: 107.34 | J8: 429.36 | K8: 322.02 | L8: 1180.73 | M8: 966.06 | N8: =SUM(G8:M8) -> 11700.01
A9: 本页小计 | N9: =SUM(N5:N8) -> 40120
A10: 5 | B10: 030507006007 | C10: 出入口控制设备 | D10: 1.名称：出门按钮 2.参数：详见设计图纸及技术规范书 3.其他:满足完成此项工作所需要的全部工作内容，包括设计图纸、技术规范书、答疑、招标文件、现行规范、图集、验收等全部要求 | E10: 台 | F10: 2 | G10: 20.04 | H10: 0.77 | I10: 0.26 | J10: 1.03 | K10: 0.77 | L10: 2.83 | M10: 2.31 | N10: =SUM(G10:M10) -> 28.01
A11: 6 | B11: 030507006008 | C11: 出入口控制设备 | D11: 1.名称：电控锁 2.参数：详见设计图纸及技术规范书 3.其他:满足完成此项工作所需要的全部工作内容，包括设计图纸、技术规范书、答疑、招标文件、现行规范、图集、验收等全部要求 | E11: 台 | F11: 52 | G11: 5295.41 | H11: 441.28 | I11: 176.51 | J11: 1323.85 | K11: 617.8 | L11: 970.83 | M11: 794.31 | N11: =SUM(G11:M11) -> 9619.99
A12: 7 | B12: 030507006009 | C12: 出入口控制设备 | D12: 1.名称：门磁开关 2.参数：详见设计图纸及技术规范书 3.其他:满足完成此项工作所需要的全部工作内容，包括设计图纸、技术规范书、答疑、招标文件、现行规范、图集、验收等全部要求 | E12: 台 | F12: 52 | G12: 1302.39 | H12: 50.09 | I12: 16.7 | J12: 66.79 | K12: 50.09 | L12: 183.67 | M12: 150.28 | N12: =SUM(G12:M12) -> 1820.01
A13: 8 | B13: 030507006010 | C13: 出入口控制设备 | D13: 1.名称：玻璃破碎应急按钮 2.参数：详见设计图纸及技术规范书 3.其他:满足完成此项工作所需要的全部工作内容，包括设计图纸、技术规范书、答疑、招标文件、现行规范、图集、验收等全部要求 | E13: 台 | F13: 25 | G13: 2755.05 | H13: 105.96 | I13: 35.32 | J13: 141.28 | K13: 105.96 | L13: 388.53 | M13: 317.89 | N13: =SUM(G13:M13) -> 3849.99
A14: 本页小计 | N14: =SUM(N10:N13) -> 15318
A15: 9 | B15: 030507005002 | C15: 出入口目标识别设备 | D15: 1.名称：人脸识别机 2.参数：详见设计图纸及技术规范书 3.其他:满足完成此项工作所需要的全部工作内容，包括设计图纸、技术规范书、答疑、招标文件、现行规范、图集、验收等全部要求 | E15: 台 | F15: 25 | G15: 23793.58 | H15: 915.14 | I15: 305.05 | J15: 1220.18 | K15: 915.14 | L15: 3355.5 | M15: 2745.41 | N15: =SUM(G15:M15) -> 33250
A16: 10 | B16: 030411006002 | C16: 接线盒 | D16: 1.名称:接线盒 2.参数：详见设计图纸及技术规范书 3.其他:满足完成此项工作所需要的全部工作内容，包括设计图纸、技术规范书、答疑、招标文件、现行规范、图集、验收等全部要求 | E16: 个 | F16: 25 | G16: 217.89 | H16: 57.34 | I16: 28.67 | J16: 160.55 | K16: 45.87 | L16: 63.07 | M16: 51.61 | N16: =SUM(G16:M16) -> 625
A17: 11 | B17: 030411001005 | C17: 配管 | D17: 1.名称:紧定式镀锌钢导管 2.材质:JDG25 3.敷设方式:综合考虑 4.其他:满足完成此项工作所需要的全部工作内容，满足设计图纸、技术规范书、答疑、招标文件、现行规范、图集、验收等全部要求 | E17: m | F17: 300 | G17: 522.94 | H17: 137.61 | I17: 68.81 | J17: 385.32 | K17: 110.09 | L17: 151.38 | M17: 123.85 | N17: =SUM(G17:M17) -> 1500
A18: 12 | B18: 030411001006 | C18: 配管 | D18: 1.名称:紧定式镀锌钢导管 2.材质:JGD20 3.敷设方式:综合考虑 4.其他:满足完成此项工作所需要的全部工作内容，满足设计图纸、技术规范书、答疑、招标文件、现行规范、图集、验收等全部要求 | E18: m | F18: 300 | G18: 470.64 | H18: 123.85 | I18: 61.93 | J18: 346.79 | K18: 99.08 | L18: 136.24 | M18: 111.47 | N18: =SUM(G18:M18) -> 1350
A19: 本页小计 | N19: =SUM(N15:N18) -> 36725
A20: 13 | B20: 030413002004 | C20: 凿（压)槽 | D20: 1.名称:二次结构凿槽 2.规格:DN32以内 3.类型:砼、砌筑结构 4.含填补恢复 5.满足完成此项工作所需要的全部工作内容，满足设计图纸、技术规范书、答疑、招标文件、现行规范、图集、验收等全部要求 | E20: m | F20: 200 | G20: 543.85 | H20: 143.12 | I20: 71.56 | J20: 400.73 | K20: 114.5 | L20: 157.43 | M20: 128.81 | N20: =SUM(G20:M20) -> 1560
A21: 14 | B21: 030413001006 | C21: 管道支架/综合支架 | D21: 1.名称:管道支架制作安装 2.材质：热镀锌 3.其它：满足完成此项工作所需要的全部工作内容，满足设计图纸、技术规范书、答疑、招标文件、现行规范、图集、验收等全部要求 | E21: kg | F21: 120 | G21: 543.85 | H21: 143.12 | I21: 71.56 | J21: 400.73 | K21: 114.5 | L21: 157.43 | M21: 128.81 | N21: =SUM(G21:M21) -> 1560
A22: 15 | B22: 030502007004 | C22: 光缆 | D22: 1.名称:光缆 2.规格:12芯单模光纤 3.敷设方式:桥架内敷设 4.其他:满足完成此项工作所需要的全部工作内容，满足设计图纸、技术规范书、答疑、招标文件、现行规范、图集、验收等全部要求 | E22: m | F22: 2700 | G22: 7728.44 | H22: 297.25 | I22: 99.08 | J22: 396.33 | K22: 297.25 | L22: 1089.91 | M22: 891.74 | N22: =SUM(G22:M22) -> 10800
A23: 16 | B23: 030502005004 | C23: 双绞线缆 | D23: 1.名称:六类八芯非屏蔽对绞线 2.规格:LSZH-UTP-Cat6-4x2x0.5 3.其他:满足完成此项工作所需要的全部工作内容，满足设计图纸、技术规范书、答疑、招标文件、现行规范、图集、验收等全部要求 | E23: m | F23: 3506 | G23: 5789.72 | H23: 482.48 | I23: 192.99 | J23: 1447.43 | K23: 675.47 | L23: 1061.45 | M23: 868.46 | N23: =SUM(G23:M23) -> 10518
A24: 本页小计 | N24: =SUM(N20:N23) -> 24438
A25: 17 | B25: 030411004007 | C25: 配线 | D25: 1.名称:配线 2.规格:WDZA-RYY2*1.0 3.其他:满足完成此项工作所需要的全部工作内容，满足设计图纸、技术规范书、答疑、招标文件、现行规范、图集、验收等全部要求 | E25: m | F25: 2700 | G25: 4894.68 | H25: 1288.07 | I25: 644.04 | J25: 3606.61 | K25: 1030.46 | L25: 1416.88 | M25: 1159.27 | N25: =SUM(G25:M25) -> 14040.01
A26: 18 | B26: 030411004008 | C26: 配线 | D26: 1.名称:线缆 2.规格:WDZA-RYY-4*1.0 3.其他:满足完成此项工作所需要的全部工作内容，满足设计图纸、技术规范书、答疑、招标文件、现行规范、图集、验收等全部要求 | E26: m | F26: 2700 | G26: 4235.78 | H26: 1114.68 | I26: 557.34 | J26: 3121.1 | K26: 891.74 | L26: 1226.15 | M26: 1003.21 | N26: =SUM(G26:M26) -> 12150
A27: 19 | B27: 030411004009 | C27: 配线 | D27: 1.名称:线缆 2.规格:WDZA-RYSP-4*1.0 3.其他:满足完成此项工作所需要的全部工作内容，满足设计图纸、技术规范书、答疑、招标文件、现行规范、图集、验收等全部要求 | E27: m | F27: 2700 | G27: 4706.42 | H27: 1238.53 | I27: 619.27 | J27: 3467.89 | K27: 990.83 | L27: 1362.39 | M27: 1114.68 | N27: =SUM(G27:M27) -> 13500.01
A28: 20 | B28: 030411004010 | C28: 配线 | D28: 1.名称:线缆 2.规格:WDZA-RYSP6*1.0 3.其他:满足完成此项工作所需要的全部工作内容，满足设计图纸、技术规范书、答疑、招标文件、现行规范、图集、验收等全部要求 | E28: m | F28: 2700 | G28: 5647.71 | H28: 1486.24 | I28: 743.12 | J28: 4161.47 | K28: 1188.99 | L28: 1634.86 | M28: 1337.61 | N28: =SUM(G28:M28) -> 16200
A29: 21 | B29: 030411004011 | C29: 配线 | D29: 1.名称:线缆 2.规格:WDZA-RYSP8*1.0 3.其他:满足完成此项工作所需要的全部工作内容，满足设计图纸、技术规范书、答疑、招标文件、现行规范、图集、验收等全部要求 | E29: m | F29: 2700 | G29: 7530.28 | H29: 1981.65 | I29: 990.83 | J29: 5548.62 | K29: 1585.32 | L29: 2179.82 | M29: 1783.49 | N29: =SUM(G29:M29) -> 21600.01
A30: 本页小计 | N30: =SUM(N25:N29) -> 77490.03
A31: 22 | B31: 030502019004 | C31: 双绞线缆测试 | D31: 1.双绞线缆测试 2.满足完成此项工作所需要的全部工作内容，包括设计图纸、技术规范书、答疑、招标文件、现行规范、图集、验收等全部要求 | E31: 链路 | F31: 86 | G31: 239.85 | H31: 63.12 | I31: 31.56 | J31: 176.73 | K31: 50.5 | L31: 69.43 | M31: 56.81 | N31: =SUM(G31:M31) -> 688
A32: 23 | B32: 030502020004 | C32: 光纤测试 | D32: 1.光纤测试 2.满足完成此项工作所需要的全部工作内容，包括设计图纸、技术规范书、答疑、招标文件、现行规范、图集、验收等全部要求 | E32: 链路 | F32: 19 | G32: 52.99 | H32: 13.94 | I32: 6.97 | J32: 39.05 | K32: 11.16 | L32: 15.34 | M32: 12.55 | N32: =SUM(G32:M32) -> 152
A33: 24 | B33: 030507019002 | C33: 安全防范系统调试 | D33: 1.系统调试及试运行 2.满足完成此项工作所需要的全部工作内容，包括设计图纸、技术规范书、答疑、招标文件、现行规范、图集、验收等全部要求 | E33: 系统 | F33: 1 | G33: 697.25 | H33: 183.49 | I33: 91.74 | J33: 513.76 | K33: 146.79 | L33: 201.83 | M33: 165.14 | N33: =SUM(G33:M33) -> 2000
A34: 25 | B34: 03B003 | C34: 系统综合及集成 | D34: 1.清单未列项、图纸中未表示或技术规格书未做要求，但为了实现本系统各项功能必须增加的配套及辅助的材料、设备的所有工作内容及费用； 2.施工深化设计增加的实现本系统设计功能必要的配套及辅助的材料、设备所需的所有工作内容及费用； 3.实现设计功能所做的满足图纸、技术规格书要求的各项综合与集成，包括不限于各项检测、试验、调试、软件开发、联动等所有工作内容及费用 | E34: 项 | F34: 1 | G34: 1045.87 | H34: 275.23 | I34: 137.61 | J34: 770.64 | K34: 220.18 | L34: 302.75 | M34: 247.71 | N34: =SUM(G34:M34) -> 2999.99
A35: 本页小计 | N35: =SUM(N31:N34) -> 5839.99
A36: 26 | B36: 031301017006 | C36: 脚手架搭拆 | D36: 1.脚手架费 2.按项包干 3.其它:满足完成此项工作所需要的全部工作内容，包括设计图纸、技术规范书、答疑、招标文件、现行规范、图集、验收等全部要求 | E36: 项 | F36: 1 | G36: 174.31 | H36: 45.87 | I36: 22.94 | J36: 128.44 | K36: 36.7 | L36: 50.46 | M36: 41.28 | N36: =SUM(G36:M36) -> 500
A37: 本页小计 | N37: =N36 -> 500
A38: 合 计 | N38: =N9+N14+N19+N24+N30+N35+N37 -> 200431.02

Sheet 3#数据中心综合布线系统
A1: 分部分项工程和单价措施项目清单与计价表
A2: 分部分项工程和单价措施项目清单与计价表
A3: 序号 | B3: 项目编码 | C3: 项目名称 | D3: 项目特征描述 | E3: 计量单位 | F3: 工程量 | G3: 金额（元）
G4: 主材/设备费 | H4: 辅材 | I4: 机械措施 | J4: 人工 | K4: 管理费 | L4: 利润 | M4: 税金 | N4: 总价
A5: 1 | B5: 080901001004 | C5: 交换机 | D5: 1.名称：汇聚交换机 2.参数：48口,万兆，40G上行光模块 3.其他:满足完成此项工作所需要的全部工作内容，包括设计图纸、技术规范书、答疑、招标文件、现行规范、图集、验收等全部要求 | E5: 台 | F5: 2 | G5: 10733.94 | H5: 412.84 | I5: 137.61 | J5: 550.46 | K5: 412.84 | L5: 1513.76 | M5: 1238.53 | N5: =SUM(G5:M5) -> 14999.98
A6: 2 | B6: 080901001005 | C6: 交换机 | D6: 1.名称：24口接入交换机 2.主要参数：配10G上行光模块 3.其他:满足完成此项工作所需要的全部工作内容，包括设计图纸、技术规范书、答疑、招标文件、现行规范、图集、验收等全部要求 | E6: 台 | F6: 1 | G6: 2719.27 | H6: 104.59 | I6: 34.86 | J6: 139.45 | K6: 104.59 | L6: 383.49 | M6: 313.76 | N6: =SUM(G6:M6) -> 3800.01
A7: 3 | B7: 030502010003 | C7: 配线架 | D7: 1.名称：配线架24口（含耦合器、尾纤等） 2.参数：详见设计图纸及技术规范书 3.其他:满足完成此项工作所需要的全部工作内容，包括设计图纸、技术规范书、答疑、招标文件、现行规范、图集、验收等全部要求 | E7: 个 | F7: 2 | G7: 500.92 | H7: 19.27 | I7: 6.42 | J7: 25.69 | K7: 19.27 | L7: 70.64 | M7: 57.8 | N7: =SUM(G7:M7) -> 700.01
A8: 4 | B8: 030502010004 | C8: 配线架 | D8: 1.名称：RJ45配线架 24口（含理线器、模块等） 2.参数：详见设计图纸及技术规范书 3.其他:满足完成此项工作所需要的全部工作内容，包括设计图纸、技术规范书、答疑、招标文件、现行规范、图集、验收等全部要求 | E8: 个 | F8: 1 | G8: 286.24 | H8: 11.01 | I8: 3.67 | J8: 14.68 | K8: 11.01 | L8: 40.37 | M8: 33.03 | N8: =SUM(G8:M8) -> 400.01
A9: 本页小计 | N9: =SUM(N5:N8) -> 19900.01
A10: 5 | B10: 030501005002 | C10: 插箱、机柜 | D10: 1.名称：19寸标准机柜(600*800) 42U,含风扇电源 2.其他:满足完成此项工作所需要的全部工作内容，包括设计图纸、技术规范书、答疑、招标文件、现行规范、图集、验收等全部要求 | E10: 台 | F10: 5 | G10: 10018.35 | H10: 385.32 | I10: 128.44 | J10: 513.76 | K10: 385.32 | L10: 1412.84 | M10: 1155.96 | N10: =SUM(G10:M10) -> 13999.99
A11: 6 | B11: 030502004002 | C11: 电视、电话插座 | D11: 1.名称：双孔信息插座（含模块） 2.参数：详见设计图纸及技术规范书 3.其它:满足完成此项工作所需要的全部工作内容，包括设计图纸、技术规范书、答疑、招标文件、现行规范、图集、验收等全部要求 | E11: 个 | F11: 4 | G11: 343.49 | H11: 13.21 | I11: 4.4 | J11: 17.61 | K11: 13.21 | L11: 48.44 | M11: 39.63 | N11: =SUM(G11:M11) -> 479.99
A12: 7 | B12: 030502003002 | C12: 分线接线箱（盒） | D12: 1.名称：铁质接线盒 2.参数：详见设计图纸及技术规范书 3.其它:满足完成此项工作所需要的全部工作内容，包括设计图纸、技术规范书、答疑、招标文件、现行规范、图集、验收等全部要求 | E12: 个 | F12: 4 | G12: 209.17 | H12: 55.05 | I12: 27.52 | J12: 154.13 | K12: 44.04 | L12: 60.55 | M12: 49.54 | N12: =SUM(G12:M12) -> 600
A13: 8 | B13: 030502009005 | C13: LC-LC单模光纤跳线（3m） | D13: 1.名称:LC-LC单模光纤跳线（3m） 2.其它:满足完成此项工作所需要的全部工作内容，包括设计图纸、技术规范书、答疑、招标文件、现行规范、图集、验收等全部要求 | E13: 条 | F13: 12 | G13: 386.42 | H13: 14.86 | I13: 4.95 | J13: 19.82 | K13: 14.86 | L13: 54.5 | M13: 44.59 | N13: =SUM(G13:M13) -> 540
A14: 9 | B14: 030502009006 | C14: LC-LC多模光纤跳线（3m） | D14: 1.名称:LC-LC多模光纤跳线（3m） 2.其它:满足完成此项工作所需要的全部工作内容，包括设计图纸、技术规范书、答疑、招标文件、现行规范、图集、验收等全部要求 | E14: 条 | F14: 12 | G14: 300.55 | H14: 11.56 | I14: 3.85 | J14: 15.41 | K14: 11.56 | L14: 42.39 | M14: 34.68 | N14: =SUM(G14:M14) -> 420
A15: 本页小计 | N15: =SUM(N10:N14) -> 16039.98
A16: 10 | B16: 030502009007 | C16: 六类非屏蔽跳线（3m） | D16: 1.名称:六类非屏蔽跳线（3m） 2.其它:满足完成此项工作所需要的全部工作内容，包括设计图纸、技术规范书、答疑、招标文件、现行规范、图集、验收等全部要求 | E16: 条 | F16: 6 | G16: 107.34 | H16: 4.13 | I16: 1.38 | J16: 5.5 | K16: 4.13 | L16: 15.14 | M16: 12.39 | N16: =SUM(G16:M16) -> 150.01
A17: 11 | B17: 030411003003 | C17: 桥架 | D17: 1.名称:热浸锌钢制金属线槽 2.型号：400*100 3.包含但不限于桥架、弯头、三通或四通、盖板、隔板、附件安装、接地跨接等 4.其它:满足完成此项工作所需要的全部工作内容，满足设计图纸、技术规范书、答疑、招标文件、现行规范、图集、验收等全部要求 | E17: m | F17: 125 | G17: 4025.23 | H17: 154.82 | I17: 51.61 | J17: 206.42 | K17: 154.82 | L17: 567.66 | M17: 464.45 | N17: =SUM(G17:M17) -> 5625.01
A18: 12 | B18: 030411003004 | C18: 桥架 | D18: 1.名称:热浸锌钢制金属线槽 2.型号：200*100 3.包含但不限于桥架、弯头、三通或四通、盖板、隔板、附件安装、接地跨接等 4.其它:满足完成此项工作所需要的全部工作内容，满足设计图纸、技术规范书、答疑、招标文件、现行规范、图集、验收等全部要求 | E18: m | F18: 85.28 | G18: 1525.65 | H18: 58.68 | I18: 19.56 | J18: 78.24 | K18: 58.68 | L18: 215.16 | M18: 176.04 | N18: =SUM(G18:M18) -> 2132.01
A19: 13 | B19: 030413001004 | C19: 桥架支吊架制作及安装 | D19: 1.名称:桥架支吊架制作及安装 2.规格:综合、热浸镀锌 3.其它：满足完成此项工作所需要的全部工作内容，满足设计图纸、技术规范书、答疑、招标文件、现行规范、图集、验收等全部要求 | E19: kg | F19: 126.66 | G19: 529.88 | H19: 139.44 | I19: 69.72 | J19: 390.44 | K19: 111.55 | L19: 153.39 | M19: 125.5 | N19: =SUM(G19:M19) -> 1519.92
A20: 本页小计 | N20: =SUM(N16:N19) -> 9426.95
A21: 14 | B21: 030502005003 | C21: 双绞线缆 | D21: 1.名称:超六类非屏蔽四对双绞线 2.规格:CAT.6A UTP 3.其他:满足完成此项工作所需要的全部工作内容，包括设计图纸、技术规范书、答疑、招标文件、现行规范、图集、验收等全部要求 | E21: m | F21: 176 | G21: 871.93 | H21: 72.66 | I21: 29.06 | J21: 217.98 | K21: 101.72 | L21: 159.85 | M21: 130.79 | N21: =SUM(G21:M21) -> 1583.99
A22: 15 | B22: 030411001004 | C22: 配管 | D22: 1.名称:紧定式镀锌钢导管 2.材质:JGD20 3.敷设方式:综合考虑 4.其他:满足完成此项工作所需要的全部工作内容，满足设计图纸、技术规范书、答疑、招标文件、现行规范、图集、验收等全部要求 | E22: m | F22: 20 | G22: 55.78 | H22: 14.68 | I22: 7.34 | J22: 41.1 | K22: 11.74 | L22: 16.15 | M22: 13.21 | N22: =SUM(G22:M22) -> 160
A23: 16 | B23: 030413002003 | C23: 凿（压)槽 | D23: 1.名称:二次结构凿槽 2.规格:DN32以内 3.类型:砼、砌筑结构 4.含填补恢复 5.满足完成此项工作所需要的全部工作内容，满足设计图纸、技术规范书、答疑、招标文件、现行规范、图集、验收等全部要求 | E23: m | F23: 14 | G23: 73.21 | H23: 19.27 | I23: 9.63 | J23: 53.94 | K23: 15.41 | L23: 21.19 | M23: 17.34 | N23: =SUM(G23:M23) -> 209.99
A24: 17 | B24: 030413001005 | C24: 管道支架/综合支架 | D24: 1.名称:管道支架制作安装 2.材质：热镀锌 3.其它：满足完成此项工作所需要的全部工作内容，满足设计图纸、技术规范书、答疑、招标文件、现行规范、图集、验收等全部要求 | E24: kg | F24: 1.04 | G24: 3.63 | H24: 0.95 | I24: 0.48 | J24: 2.67 | K24: 0.76 | L24: 1.05 | M24: 0.86 | N24: =SUM(G24:M24) -> 10.4
A25: 本页小计 | N25: =SUM(N21:N24) -> 1964.38
A26: 18 | B26: 030502007003 | C26: 光缆 | D26: 1.名称:光缆 2.规格:12芯多模光纤OS2 3.敷设方式:桥架内敷设 4.其他:满足完成此项工作所需要的全部工作内容，包括设计图纸、技术规范书、答疑、招标文件、现行规范、图集、验收等全部要求 | E26: m | F26: 1500 | G26: 3756.88 | H26: 144.5 | I26: 48.17 | J26: 192.66 | K26: 144.5 | L26: 529.82 | M26: 433.49 | N26: =SUM(G26:M26) -> 5250.02
A27: 19 | B27: 030502019003 | C27: 双绞线缆测试 | D27: 1.测试内容:双绞线缆 2.其他:满足完成此项工作所需要的全部工作内容，包括设计图纸、技术规范书、答疑、招标文件、现行规范、图集、验收等全部要求 | E27: 链路 | F27: 6 | G27: 313.76 | H27: 82.57 | I27: 41.28 | J27: 231.19 | K27: 66.06 | L27: 90.83 | M27: 74.31 | N27: =SUM(G27:M27) -> 900
A28: 20 | B28: 030502020003 | C28: 光纤测试 | D28: 1.测试内容:光纤 2.其他:满足完成此项工作所需要的全部工作内容，包括设计图纸、技术规范书、答疑、招标文件、现行规范、图集、验收等全部要求 | E28: 链路 | F28: 6 | G28: 418.35 | H28: 110.09 | I28: 55.05 | J28: 308.26 | K28: 88.07 | L28: 121.1 | M28: 99.08 | N28: =SUM(G28:M28) -> 1200
A29: 21 | B29: 030503010003 | C29: 建筑设备自控化系统试运行 | D29: 1.名称:建筑设备自控化系统试运行 2.其他:满足完成此项工作所需要的全部工作内容，包括设计图纸、技术规范书、答疑、招标文件、现行规范、图集、验收等全部要求 | E29: 系统 | F29: 1 | G29: 1045.87 | H29: 275.23 | I29: 137.61 | J29: 770.64 | K29: 220.18 | L29: 302.75 | M29: 247.71 | N29: =SUM(G29:M29) -> 2999.99
A30: 本页小计 | N30: =SUM(N26:N29) -> 10350.01
A31: 22 | B31: 03B001 | C31: 系统综合及集成 | D31: 1.清单未列项、图纸中未表示或技术规格书未做要求，但为了实现本系统各项功能必须增加的配套及辅助的材料、设备的所有工作内容及费用； 2.施工深化设计增加的实现本系统设计功能必要的配套及辅助的材料、设备所需的所有工作内容及费用； 3.实现设计功能所做的满足图纸、技术规格书要求的各项综合与集成，包括不限于各项检测、试验、调试、软件开发、联动等所有工作内容及费用 | E31: 项 | F31: 1 | G31: 2788.99 | H31: 733.94 | I31: 366.97 | J31: 2055.05 | K31: 587.16 | L31: 807.34 | M31: 660.55 | N31: =SUM(G31:M31) -> 8000
A32: 23 | B32: 031301017005 | C32: 脚手架搭拆 | D32: 1.脚手架费 2.按项包干 3.其它:满足完成此项工作所需要的全部工作内容，包括设计图纸、技术规范书、答疑、招标文件、现行规范、图集、验收等全部要求 | E32: 项 | F32: 1 | G32: 697.25 | H32: 183.49 | I32: 91.74 | J32: 513.76 | K32: 146.79 | L32: 201.83 | M32: 165.14 | N32: =SUM(G32:M32) -> 2000
A33: 本页小计 | N33: =SUM(N31:N32) -> 10000
A34: 合 计 | N34: =N9+N15+N20+N25+N30+N33 -> 67681.33

Sheet 8#、15#非管区入侵报警系统
A1: 分部分项工程和单价措施项目清单与计价表
A2: 分部分项工程和单价措施项目清单与计价表
A3: 序号 | B3: 项目编码 | C3: 项目名称 | D3: 项目特征描述 | E3: 计量单位 | F3: 工程量 | G3: 金额（元）
G4: 主材/设备费 | H4: 辅材 | I4: 机械措施 | J4: 人工 | K4: 管理费 | L4: 利润 | M4: 税金 | N4: 总价
A5: 1 | B5: 030507001001 | C5: 红外微波双鉴探测器 | D5: 1.名称:红外微波双鉴探测器 2.技术参数:三鉴移动探测器(红外+微波+智能芯片)，吸顶安装,探测范围:360°，直径6米(安装高度3.6米)，CCC认证，自动脉冲计数，采用多普勒(效应)+ 能量分析，全范围自动温度补偿，超强抗误报能力，工作电压: DC9-16V 3.其它:满足完成此项工作所需要的全部工作内容，包括设计图纸、技术规范书、答疑、招标文件、现行规范、图集、验收等全部要求 | E5: 套 | F5: 62 | G5: 9760.73 | H5: 375.41 | I5: 125.14 | J5: 500.55 | K5: 375.41 | L5: 1376.51 | M5: 1126.24 | N5: =SUM(G5:M5) -> 13639.99
A6: 2 | B6: 030507008014 | C6: 探测器电源 | D6: 1.名称:探测器电源 2.规格:开关电源12V 3A（探测器集中供电） 3.其它:满足完成此项工作所需要的全部工作内容，包括设计图纸、技术规范书、答疑、招标文件、现行规范、图集、验收等全部要求 | E6: 台 | F6: 2 | G6: 257.61 | H6: 9.91 | I6: 3.3 | J6: 13.21 | K6: 9.91 | L6: 36.33 | M6: 29.72 | N6: =SUM(G6:M6) -> 359.99
A7: 3 | B7: 030507001002 | C7: 玻璃破碎报警器 | D7: 1.名称:玻璃破碎报警器 2.技术参数:标准结构：选用防火材料，红色； 电气性能：最大耐用电流3A@36VDC； 适用门型：安全门、逃生门、安全系统等； 3.其它:满足完成此项工作所需要的全部工作内容，包括设计图纸、技术规范书、答疑、招标文件、现行规范、图集、验收等全部要求 | E7: 套 | F7: 62 | G7: 6655.05 | H7: 255.96 | I7: 85.32 | J7: 341.28 | K7: 255.96 | L7: 938.53 | M7: 767.89 | N7: =SUM(G7:M7) -> 9299.99
A8: 本页小计 | N8: =SUM(N5:N7) -> 23299.97
A9: 4 | B9: 030904003002 | C9: 紧急报警按钮 | D9: 1.名称:紧急报警按钮 2.安装方式:暗装,底距地1.4m 3.其它:满足完成此项工作所需要的全部工作内容，包括设计图纸、技术规范书、答疑、招标文件、现行规范、图集、验收等全部要求 | E9: 个 | F9: 14 | G9: 585.69 | H9: 154.13 | I9: 77.06 | J9: 431.56 | K9: 123.3 | L9: 169.54 | M9: 138.72 | N9: =SUM(G9:M9) -> 1680
A10: 5 | B10: 030507002002 | C10: 四防区模块 | D10: 1.名称:四防区模块（含模块箱和电源等） 2.其它:满足完成此项工作所需要的全部工作内容，包括设计图纸、技术规范书、答疑、招标文件、现行规范、图集、验收等全部要求 | E10: 套 | F10: 13 | G10: 6046.79 | H10: 232.57 | I10: 77.52 | J10: 310.09 | K10: 232.57 | L10: 852.75 | M10: 697.71 | N10: =SUM(G10:M10) -> 8450
A11: 6 | B11: 030507002003 | C11: 八防区模块 | D11: 1.名称:八防区模块（含模块箱和电源等） 2.其它:满足完成此项工作所需要的全部工作内容，包括设计图纸、技术规范书、答疑、招标文件、现行规范、图集、验收等全部要求 | E11: 套 | F11: 21 | G11: 12773.39 | H11: 491.28 | I11: 163.76 | J11: 655.05 | K11: 491.28 | L11: 1801.38 | M11: 1473.85 | N11: =SUM(G11:M11) -> 17849.99
A12: 7 | B12: 030507002004 | C12: 总线式报警主机 | D12: 1.名称:总线式报警主机（含总线延长器、软件等） 2.规格:专业级总线制网络报警主机，自带8防区，可扩展至256防区/自带4路继电器，可扩展至256路继电器输出/串口输出/电话/网络上报/8个独立子系统/总线可达2400米/8.2K 线尾组，支持本地8路防区/2线制防区防拆/支持定时撤布防/时控输出 3.其它:满足完成此项工作所需要的全部工作内容，包括设计图纸、技术规范书、答疑、招标文件、现行规范、图集、验收等全部要求 | E12: 套 | F12: 2 | G12: 8587.16 | H12: 330.28 | I12: 110.09 | J12: 440.37 | K12: 330.28 | L12: 1211.01 | M12: 990.83 | N12: =SUM(G12:M12) -> 12000.02
A13: 本页小计 | N13: =SUM(N9:N12) -> 39980.01
A14: 8 | B14: 030904016001 | C14: 主机电源 | D14: 1.名称:主机电源 2.规格:充电后备电池（12V7AH） 标准电压 12V 额定容量 7.0Ah 3.其它:满足完成此项工作所需要的全部工作内容，包括设计图纸、技术规范书、答疑、招标文件、现行规范、图集、验收等全部要求 | E14: 套 | F14: 2 | G14: 500.92 | H14: 19.27 | I14: 6.42 | J14: 25.69 | K14: 19.27 | L14: 70.64 | M14: 57.8 | N14: =SUM(G14:M14) -> 700.01
A15: 本页小计 | N15: =N14 -> 700.01
A16: 9 | B16: 030507013002 | C16: 报警控制键盘 | D16: 1.名称:报警控制键盘 2.技术参数:LCD报警键盘；连接到报警主机，可以对报警主机进行操作和编程，通过指示灯和报警音提示报警； 主机状态指示灯：系统故障（橙色），网络链接状态（绿色），报警（红色），布撤防（蓝色），配置状态（红绿双色） 功能键：8个，工程、查询，旁路，一键，火警，紧急，左键，右键； 防拆功能：支持；与主机通讯：485；键盘警情输出：蜂鸣器； 功能特性：对主机编程、撤布防、消警、旁路/旁路恢复、工程测试、子系统操作、继电器操作、主机状态查询； 支持刷卡布撤防，但刷卡不支持消警功能，卡片数量由主机限制，目前网络主机最大可添加32张卡片； 支持连接遥控器进行远程布撤防，键盘最多所能支持的无线遥控器数量由主机决定，最多支持32个遥控器； 支持双向遥控器，遥控器LED显示操作结果； 功耗：1.8W；工作温度：-10℃～＋55℃；工作湿度：10％～90％； 3.其它:满足完成此项工作所需要的全部工作内容，包括设计图纸、技术规范书、答疑、招标文件、现行规范、图集、验收等全部要求 | E16: 台 | F16: 2 | G16: 2576.15 | H16: 99.08 | I16: 33.03 | J16: 132.11 | K16: 99.08 | L16: 363.3 | M16: 297.25 | N16: =SUM(G16:M16) -> 3600
A17: 本页小计 | N17: =N16 -> 3600
A18: 10 | B18: 030904005002 | C18: 声光报警器 | D18: 1.名称:声光报警器 2.规格:声光报警器(红/白双色外观),12VDC 压电警号,防火ABS阻燃外壳,声压(VDC)：110±3 3.其它:满足完成此项工作所需要的全部工作内容，包括设计图纸、技术规范书、答疑、招标文件、现行规范、图集、验收等全部要求 | E18: 个 | F18: 5 | G18: 161.01 | H18: 6.19 | I18: 2.06 | J18: 8.26 | K18: 6.19 | L18: 22.71 | M18: 18.58 | N18: =SUM(G18:M18) -> 225
A19: 11 | B19: 030507017004 | C19: 安全防范分系统调试 | D19: 1.名称：入侵报警系统调试 2.其它:满足完成此项工作所需要的全部工作内容，包括设计图纸、技术规范书、答疑、招标文件、现行规范、图集、验收等全部要求 | E19: 系统 | F19: 1 | G19: 41.83 | H19: 11.01 | I19: 5.5 | J19: 30.83 | K19: 8.81 | L19: 12.11 | M19: 9.91 | N19: =SUM(G19:M19) -> 120
A20: 12 | B20: 03B027 | C20: 系统综合及集成 | D20: 1.清单未列项、图纸中未表示或技术规格书未做要求，但为了实现本系统各项功能必须增加的配套及辅助的材料、设备的所有工作内容及费用； 2.施工深化设计增加的实现本系统设计功能必要的配套及辅助的材料、设备所需的所有工作内容及费用； 3.实现设计功能所做的满足图纸、技术规格书要求的各项综合与集成，包括不限于各项检测、试验、调试、软件开发、联动等所有工作内容及费用 | E20: 项 | F20: 1 | G20: 1394.5 | H20: 366.97 | I20: 183.49 | J20: 1027.52 | K20: 293.58 | L20: 403.67 | M20: 330.28 | N20: =SUM(G20:M20) -> 4000.01
A21: 本页小计 | N21: =SUM(N18:N20) -> 4345.01
A22: 13 | B22: 030411001066 | C22: 配管 | D22: 1.名称：紧定式镀锌钢导管 2.规格：JDG20 3.敷设方式：明配 4.其它:满足完成此项工作所需要的全部工作内容，包括设计图纸、技术规范书、答疑、招标文件、现行规范、图集、验收等全部要求 | E22: m | F22: 284.6 | G22: 446.48 | H22: 117.5 | I22: 58.75 | J22: 328.99 | K22: 94 | L22: 129.24 | M22: 105.75 | N22: =SUM(G22:M22) -> 1280.71
A23: 14 | B23: 030411001067 | C23: 配管 | D23: 1.名称：紧定式镀锌钢导管 2.规格：JDG20 3.敷设方式：暗配 4.其它:满足完成此项工作所需要的全部工作内容，包括设计图纸、技术规范书、答疑、招标文件、现行规范、图集、验收等全部要求 | E23: m | F23: 12 | G23: 18.83 | H23: 4.95 | I23: 2.48 | J23: 13.87 | K23: 3.96 | L23: 5.45 | M23: 4.46 | N23: =SUM(G23:M23) -> 54
A24: 15 | B24: 030413002019 | C24: 凿（压)槽 | D24: 1.名称:管线剔槽及恢复 2.满足完成此项工作所需要的全部工作内容，满足设计图纸、答疑、招标文件、现行规范、图集、验收等全部要求 | E24: m | F24: 12 | G24: 51.52 | H24: 4.29 | I24: 1.72 | J24: 12.88 | K24: 6.01 | L24: 9.45 | M24: 7.73 | N24: =SUM(G24:M24) -> 93.6
A25: 16 | B25: 030413001035 | C25: 管道支架/综合支架 | D25: 1.名称:管道支架制作安装 2.材质:热镀锌 3.安装高度:综合考虑 4.满足完成此项工作所需要的全部工作内容，满足设计图纸、技术规范书、答疑、招标文件、现行规范、图集、验收等全部要求 | E25: kg | F25: 50.85 | G25: 230.46 | H25: 60.65 | I25: 30.32 | J25: 169.81 | K25: 48.52 | L25: 66.71 | M25: 54.58 | N25: =SUM(G25:M25) -> 661.05
A26: 17 | B26: 030411004060 | C26: 配线 | D26: 1.名称：配线 2.规格：RYYP-4*1.0 3.敷设方式：管内穿线 4.其它:满足完成此项工作所需要的全部工作内容，包括设计图纸、技术规范书、答疑、招标文件、现行规范、图集、验收等全部要求 | E26: m | F26: 237.4 | G26: 662.11 | H26: 174.24 | I26: 87.12 | J26: 487.87 | K26: 139.39 | L26: 191.66 | M26: 156.81 | N26: =SUM(G26:M26) -> 1899.2
A27: 本页小计 | N27: =SUM(N22:N26) -> 3988.56
A28: 18 | B28: 030411004061 | C28: 配线 | D28: 1.名称：配线 2.规格：RYYP-4*1.0 3.敷设方式：线槽配线 4.其它:满足完成此项工作所需要的全部工作内容，包括设计图纸、技术规范书、答疑、招标文件、现行规范、图集、验收等全部要求 | E28: m | F28: 775.5 | G28: 2162.86 | H28: 569.17 | I28: 284.59 | J28: 1593.69 | K28: 455.34 | L28: 626.09 | M28: 512.26 | N28: =SUM(G28:M28) -> 6204
A29: 19 | B29: 030411004062 | C29: 配线 | D29: 1.名称：配线 2.规格：RYYP-2*1.0 3.敷设方式：管内穿线 4.其它:满足完成此项工作所需要的全部工作内容，包括设计图纸、技术规范书、答疑、招标文件、现行规范、图集、验收等全部要求 | E29: m | F29: 59.2 | G29: 92.87 | H29: 24.44 | I29: 12.22 | J29: 68.43 | K29: 19.55 | L29: 26.88 | M29: 22 | N29: =SUM(G29:M29) -> 266.39
A30: 20 | B30: 030411004063 | C30: 配线 | D30: 1.名称：配线 2.规格：RYYP-2*1.0 3.敷设方式：线槽配线 4.其它:满足完成此项工作所需要的全部工作内容，包括设计图纸、技术规范书、答疑、招标文件、现行规范、图集、验收等全部要求 | E30: m | F30: 156.2 | G30: 245.05 | H30: 64.49 | I30: 32.24 | J30: 180.56 | K30: 51.59 | L30: 70.93 | M30: 58.04 | N30: =SUM(G30:M30) -> 702.9
A31: 21 | B31: 030411006018 | C31: 接线盒 | D31: 1.名称:铁接线盒 2.安装形式:满足设计及规范验收要求 3.其它:满足完成此项工作所需要的全部工作内容，包括设计图纸、技术规范书、答疑、招标文件、现行规范、图集、验收等全部要求 | E31: 个 | F31: 29 | G31: 121.32 | H31: 31.93 | I31: 15.96 | J31: 89.39 | K31: 25.54 | L31: 35.12 | M31: 28.73 | N31: =SUM(G31:M31) -> 347.99
A32: 本页小计 | N32: =SUM(N28:N31) -> 7521.28
A33: 22 | B33: 030411001068 | C33: 配管 | D33: 1.名称：紧定式镀锌钢导管 2.规格：JDG20 3.敷设方式：明配 4.其它:满足完成此项工作所需要的全部工作内容，包括设计图纸、技术规范书、答疑、招标文件、现行规范、图集、验收等全部要求 | E33: m | F33: 2.3 | G33: 3.61 | H33: 0.95 | I33: 0.47 | J33: 2.66 | K33: 0.76 | L33: 1.04 | M33: 0.85 | N33: =SUM(G33:M33) -> 10.34
A34: 23 | B34: 030411004064 | C34: 配线 | D34: 1.名称：配线 2.规格：RYYP-4*1.0 3.敷设方式：管内穿线 4.其它:满足完成此项工作所需要的全部工作内容，包括设计图纸、技术规范书、答疑、招标文件、现行规范、图集、验收等全部要求 | E34: m | F34: 2.3 | G34: 3.61 | H34: 0.95 | I34: 0.47 | J34: 2.66 | K34: 0.76 | L34: 1.04 | M34: 0.85 | N34: =SUM(G34:M34) -> 10.34
A35: 24 | B35: 030411004065 | C35: 配线 | D35: 1.名称：配线 2.规格：RYYP-4*1.0 3.敷设方式：线槽配线 4.其它:满足完成此项工作所需要的全部工作内容，包括设计图纸、技术规范书、答疑、招标文件、现行规范、图集、验收等全部要求 | E35: m | F35: 55 | G35: 86.28 | H35: 22.71 | I35: 11.35 | J35: 63.58 | K35: 18.17 | L35: 24.98 | M35: 20.44 | N35: =SUM(G35:M35) -> 247.51
A36: 25 | B36: 030411006019 | C36: 接线盒 | D36: 1.名称:铁接线盒 2.安装形式:满足设计及规范验收要求 3.其它:满足完成此项工作所需要的全部工作内容，包括设计图纸、技术规范书、答疑、招标文件、现行规范、图集、验收等全部要求 | E36: 个 | F36: 1 | G36: 4.18 | H36: 1.1 | I36: 0.55 | J36: 3.08 | K36: 0.88 | L36: 1.21 | M36: 0.99 | N36: =SUM(G36:M36) -> 11.99
A37: 本页小计 | N37: =SUM(N33:N36) -> 280.18
A38: 26 | B38: 030411001069 | C38: 配管 | D38: 1.名称：紧定式镀锌钢导管 2.规格：JDG20 3.敷设方式：明配 4.其它:满足完成此项工作所需要的全部工作内容，包括设计图纸、技术规范书、答疑、招标文件、现行规范、图集、验收等全部要求 | E38: m | F38: 533.6 | G38: 837.12 | H38: 220.29 | I38: 110.15 | J38: 616.82 | K38: 176.23 | L38: 242.32 | M38: 198.26 | N38: =SUM(G38:M38) -> 2401.19
A39: 27 | B39: 030411001070 | C39: 配管 | D39: 1.名称：紧定式镀锌钢导管 2.规格：JDG20 3.敷设方式：暗配 4.其它:满足完成此项工作所需要的全部工作内容，包括设计图纸、技术规范书、答疑、招标文件、现行规范、图集、验收等全部要求 | E39: m | F39: 60.93 | G39: 95.59 | H39: 25.15 | I39: 12.58 | J39: 70.43 | K39: 20.12 | L39: 27.67 | M39: 22.64 | N39: =SUM(G39:M39) -> 274.18
A40: 28 | B40: 030413002020 | C40: 凿（压)槽 | D40: 1.名称:管线剔槽及恢复 2.满足完成此项工作所需要的全部工作内容，满足设计图纸、答疑、招标文件、现行规范、图集、验收等全部要求 | E40: m | F40: 60 | G40: 257.61 | H40: 21.47 | I40: 8.59 | J40: 64.4 | K40: 30.06 | L40: 47.23 | M40: 38.64 | N40: =SUM(G40:M40) -> 468
...

Sheet 8#、15#非管区时钟同步系统
A1: 分部分项工程和单价措施项目清单与计价表
A2: 分部分项工程和单价措施项目清单与计价表
A3: 序号 | B3: 项目编码 | C3: 项目名称 | D3: 项目特征描述 | E3: 计量单位 | F3: 工程量 | G3: 金额（元）
G4: 主材/设备费 | H4: 辅材 | I4: 机械措施 | J4: 人工 | K4: 管理费 | L4: 利润 | M4: 税金 | N4: 总价
A5: 1 | B5: 030504001003 | C5: 时间同步服务器 | D5: 1.名称:时间同步服务器 2.技术参数：处理器：≥2颗Intel 至强 4510处理器，单颗核数≥12核， ≥2.40 GHz或以上；内存：≥128G；操作系统： 支持Microsoft Windows Server 2019、 RedHat Enterprise Linux 、 SUSE Linux Enterprise Server、 CentOS、 Ubuntu、 Vmware EXSI；内置SAS硬盘，RAID5，配备4x3TB热插拔硬盘，10000rpm以上；2个千兆以太网口；冗余电源、风扇，可以365天24小时运行；1块单口8Gb HBA卡。 3.其它:满足完成此项工作所需要的全部工作内容，包括设计图纸、技术规范书、答疑、招标文件、现行规范、图集、验收等全部要求 | E5: 台 | F5: 2 | G5: 51522.94 | H5: 1981.66 | I5: 660.56 | J5: 2642.2 | K5: 1981.66 | L5: 7266.06 | M5: 5944.96 | N5: =SUM(G5:M5) -> 72000.04
A6: 2 | B6: 030404001001 | C6: 时间母钟 | D6: 1.名称:时间母钟 2.其它:满足完成此项工作所需要的全部工作内容，包括设计图纸、技术规范书、答疑、招标文件、现行规范、图集、验收等全部要求 | E6: 台 | F6: 2 | G6: 66055.04 | H6: 5504.58 | I6: 2201.84 | J6: 16513.76 | K6: 7706.42 | L6: 12110.1 | M6: 9908.26 | N6: =SUM(G6:M6) -> 120000
A7: 3 | B7: 030404001002 | C7: 网络显示子钟 | D7: 1.名称:网络显示子钟 2.其它:满足完成此项工作所需要的全部工作内容，包括设计图纸、技术规范书、答疑、招标文件、现行规范、图集、验收等全部要求 | E7: 台 | F7: 1 | G7: 3522.94 | H7: 293.58 | I7: 117.44 | J7: 880.74 | K7: 411 | L7: 645.88 | M7: 528.44 | N7: =SUM(G7:M7) -> 6400.02
A8: 本页小计 | N8: =SUM(N5:N7) -> 198400.06
A9: 4 | B9: 031102003001 | C9: GPS天线 | D9: 1.名称:GPS天线 2.其它:满足完成此项工作所需要的全部工作内容，包括设计图纸、技术规范书、答疑、招标文件、现行规范、图集、验收等全部要求 | E9: 副 | F9: 2 | G9: 5944.95 | H9: 495.42 | I9: 198.18 | J9: 1486.23 | K9: 693.57 | L9: 1089.9 | M9: 891.75 | N9: =SUM(G9:M9) -> 10800
A10: 5 | B10: 031102004001 | C10: GPS馈线 | D10: 1.名称:GPS馈线 2.其它:满足完成此项工作所需要的全部工作内容，包括设计图纸、技术规范书、答疑、招标文件、现行规范、图集、验收等全部要求 | E10: m | F10: 500 | G10: 8256.87 | H10: 688.08 | I10: 275.22 | J10: 2064.21 | K10: 963.3 | L10: 1513.77 | M10: 1238.52 | N10: =SUM(G10:M10) -> 14999.97
A11: 6 | B11: 030505008001 | C11: GPS接收机 | D11: 1.名称:GPS接收机 2.其它:满足完成此项工作所需要的全部工作内容，包括设计图纸、技术规范书、答疑、招标文件、现行规范、图集、验收等全部要求 | E11: 台 | F11: 1 | G11: 3853.22 | H11: 321.1 | I11: 128.44 | J11: 963.3 | K11: 449.54 | L11: 706.42 | M11: 577.98 | N11: =SUM(G11:M11) -> 7000
A12: 7 | B12: 030502003006 | C12: 多路输出接口箱 | D12: 1.名称:多路输出接口箱 2.其它:满足完成此项工作所需要的全部工作内容，包括设计图纸、技术规范书、答疑、招标文件、现行规范、图集、验收等全部要求 | E12: 个 | F12: 1 | G12: 3743.12 | H12: 311.93 | I12: 124.77 | J12: 935.78 | K12: 436.7 | L12: 686.24 | M12: 561.47 | N12: =SUM(G12:M12) -> 6800.01
A13: 8 | B13: 030501012028 | C13: 24口接入交换机 | D13: 1.名称:24口接入交换机 2.其它:满足完成此项工作所需要的全部工作内容，包括设计图纸、技术规范书、答疑、招标文件、现行规范、图集、验收等全部要求 | E13: 台 | F13: 2 | G13: 3317.53 | H13: 127.6 | I13: 42.53 | J13: 170.13 | K13: 127.6 | L13: 467.86 | M13: 382.79 | N13: =SUM(G13:M13) -> 4636.04
A14: 本页小计 | N14: =SUM(N9:N13) -> 44236.02
A15: 9 | B15: 03B047 | C15: 系统综合及集成 | D15: 1.清单未列项、图纸中未表示或技术规格书未做要求，但为了实现本系统各项功能必须增加的配套及辅助的材料、设备的所有工作内容及费用； 2.施工深化设计增加的实现本系统设计功能必要的配套及辅助的材料、设备所需的所有工作内容及费用； 3.实现设计功能所做的满足图纸、技术规格书要求的各项综合与集成，包括不限于各项检测、试验、调试、软件开发、联动等所有工作内容及费用 | E15: 项 | F15: 1 | G15: 697.25 | H15: 183.49 | I15: 91.74 | J15: 513.76 | K15: 146.79 | L15: 201.83 | M15: 165.14 | N15: =SUM(G15:M15) -> 2000
A16: 10 | B16: 03B048 | C16: 平台对接 | D16: 1.平台对接 2.其它:满足完成此项工作所需要的全部工作内容，包括设计图纸、技术规范书、答疑、招标文件、现行规范、图集、验收等全部要求 | E16: 项 | F16: 1 | G16: 2752.29 | H16: 229.36 | I16: 91.74 | J16: 688.07 | K16: 321.1 | L16: 504.59 | M16: 412.84 | N16: =SUM(G16:M16) -> 4999.99
A17: 11 | B17: 03B049 | C17: 软件开发 | D17: 1.软件开发 2.其它:满足完成此项工作所需要的全部工作内容，包括设计图纸、技术规范书、答疑、招标文件、现行规范、图集、验收等全部要求 | E17: 项 | F17: 1 | G17: 2752.29 | H17: 229.36 | I17: 91.74 | J17: 688.07 | K17: 321.1 | L17: 504.59 | M17: 412.84 | N17: =SUM(G17:M17) -> 4999.99
A18: 12 | B18: 031301017029 | C18: 脚手架搭拆 | D18: 1.综合考虑项目脚手架搭拆或其他替代措施项目 2.场内外材料搬运 3.拆除脚手架后材料的堆放 4.满足完成此项工作所需要的全部工作内容，满足设计图纸、答疑、招标文件、现行规范、图集、验收等全部要求 | E18: 项 | F18: 1 | G18: 45.58 | H18: 12 | I18: 6 | J18: 33.59 | K18: 9.6 | L18: 13.19 | M18: 10.8 | N18: =SUM(G18:M18) -> 130.76
A19: 本页小计 | N19: =SUM(N15:N18) -> 12130.74
A20: 13 | B20: 03B050 | C20: 超高费 | E20: 项 | F20: 1 | G20: 422.24 | H20: 35.19 | I20: 14.07 | J20: 105.56 | K20: 49.26 | L20: 77.41 | M20: 63.34 | N20: =SUM(G20:M20) -> 767.07
A21: 本页小计 | N21: =N20 -> 767.07
A22: 合 计 | N22: =N8+N14+N19+N21 -> 255533.89

Sheet 8#、15#非管区视频监控系统
A1: 分部分项工程和单价措施项目清单与计价表
A2: 分部分项工程和单价措施项目清单与计价表
A3: 序号 | B3: 项目编码 | C3: 项目名称 | D3: 项目特征描述 | E3: 计量单位 | F3: 工程量 | G3: 金额（元）
G4: 主材/设备费 | H4: 辅材 | I4: 机械措施 | J4: 人工 | K4: 管理费 | L4: 利润 | M4: 税金 | N4: 总价
A5: 1 | B5: 030507008001 | C5: 高清彩色半球摄像机 | D5: 1.名称:高清彩色半球摄像机 2.技术参数:详见技术规范书及图纸，含电源 3.安装方式:吸顶安装 4.其它:满足完成此项工作所需要的全部工作内容，包括设计图纸、技术规范书、答疑、招标文件、现行规范、图集、验收等全部要求 | E5: 台 | F5: 366 | G5: 125715.96 | H5: 4835.23 | I5: 1611.74 | J5: 6446.97 | K5: 4835.23 | L5: 17729.17 | M5: 14505.69 | N5: =SUM(G5:M5) -> 175679.99
A6: 2 | B6: 030507008002 | C6: 高清彩色枪式摄像机 | D6: 1.名称:高清彩色枪式摄像机 2.技术参数:详见技术规范书及图纸，含电源 3.安装方式:支架安装 4.其它:满足完成此项工作所需要的全部工作内容，包括设计图纸、技术规范书、答疑、招标文件、现行规范、图集、验收等全部要求 | E6: 台 | F6: 90 | G6: 32201.83 | H6: 1238.53 | I6: 412.84 | J6: 1651.38 | K6: 1238.53 | L6: 4541.28 | M6: 3715.6 | N6: =SUM(G6:M6) -> 44999.99
A7: 3 | B7: 030507008003 | C7: 室外高清彩色枪式摄像机 | D7: 1.名称:室外高清彩色枪式摄像机2160P 2.技术参数:详见技术规范书及图纸，含电源 3.安装方式:支架安装 | E7: 台 | F7: 37 | G7: 12708.99 | H7: 488.81 | I7: 162.94 | J7: 651.74 | K7: 488.81 | L7: 1792.29 | M7: 1466.42 | N7: =SUM(G7:M7) -> 17760
A8: 4 | B8: 030507008004 | C8: 枪式摄像机支架 | D8: 1.名称:枪式摄像机支架 2.材质:白色、铝合金 3.安装方式:壁装支架 4.其它:满足完成此项工作所需要的全部工作内容，包括设计图纸、技术规范书、答疑、招标文件、现行规范、图集、验收等全部要求 | E8: 台 | F8: 127 | G8: 885.5 | H8: 233.03 | I8: 116.51 | J8: 652.48 | K8: 186.42 | L8: 256.33 | M8: 209.72 | N8: =SUM(G8:M8) -> 2539.99
A9: 本页小计 | N9: =SUM(N5:N8) -> 240979.97
A10: 5 | B10: 030507008005 | C10: 电梯轿厢内暗装彩色广角摄像机 | D10: 1.名称:电梯轿厢内暗装彩色广角摄像机（含楼层叠加器） 2.技术参数详见技术规范书及图纸，含电源 3.安装方式:吸顶安装 4.其它:满足完成此项工作所需要的全部工作内容，包括设计图纸、技术规范书、答疑、招标文件、现行规范、图集、验收等全部要求 | E10: 台 | F10: 10 | G10: 3577.98 | H10: 137.61 | I10: 45.87 | J10: 183.49 | K10: 137.61 | L10: 504.59 | M10: 412.84 | N10: =SUM(G10:M10) -> 4999.99
A11: 6 | B11: 030507008006 | C11: 室外云台摄像机 | D11: 1.名称:室外云台摄像机，技术参数详见技术规范书及图纸，含电源 2.安装方式:支架安装 3.其它:满足完成此项工作所需要的全部工作内容，包括设计图纸、技术规范书、答疑、招标文件、现行规范、图集、验收等全部要求 | E11: 台 | F11: 9 | G11: 30913.76 | H11: 1188.99 | I11: 396.33 | J11: 1585.32 | K11: 1188.99 | L11: 4359.63 | M11: 3566.97 | N11: =SUM(G11:M11) -> 43199.99
A12: 7 | B12: 030502009008 | C12: HDMI线缆 | D12: 1.名称:HDMI线缆 2.规格:9根15m 3.其它:满足完成此项工作所需要的全部工作内容，包括设计图纸、技术规范书、答疑、招标文件、现行规范、图集、验收等全部要求 | E12: 项 | F12: 1 | G12: 990.83 | H12: 82.57 | I12: 33.03 | J12: 247.71 | K12: 115.6 | L12: 181.65 | M12: 148.62 | N12: =SUM(G12:M12) -> 1800.01
A13: 8 | B13: 030501012001 | C13: 24口接入交换机 | D13: 1.名称:24口接入交换机 2.技术参数:接入交换机 2.技术参数:非POE交换机，24个10/100/1000M自适应电口，4个1G/10G SFP+光口，含光模块 3.其它:满足完成此项工作所需要的全部工作内容，包括设计图纸、技术规范书、答疑、招标文件、现行规范、图集、验收等全部要求 | E13: 台 | F13: 35 | G13: 60110.09 | H13: 2311.93 | I13: 770.64 | J13: 3082.57 | K13: 2311.93 | L13: 8477.06 | M13: 6935.78 | N13: =SUM(G13:M13) -> 84000
A14: 本页小计 | N14: =SUM(N10:N13) -> 133999.99
A15: 9 | B15: 030502001008 | C15: 弱电机柜 | D15: 1.名称:弱电机柜 2.技术参数:800*800*2000，电池后备1小时，提供柜内电池监控，含2个PDU，详见技术规范书及图纸，含电源 3.安装方式:落地安装 4.其它:满足完成此项工作所需要的全部工作内容，包括设计图纸、技术规范书、答疑、招标文件、现行规范、图集、验收等全部要求 | E15: 台 | F15: 14 | G15: 18033.03 | H15: 693.58 | I15: 231.19 | J15: 924.77 | K15: 693.58 | L15: 2543.12 | M15: 2080.73 | N15: =SUM(G15:M15) -> 25200
A16: 10 | B16: 030502001009 | C16: 弱电机柜 | D16: 1.名称:弱电机柜 2.技术参数:600*1200*2000，含2个PDU 3.安装方式:落地安装 4.其它:满足完成此项工作所需要的全部工作内容，包括设计图纸、技术规范书、答疑、招标文件、现行规范、图集、验收等全部要求 | E16: 台 | F16: 3 | G16: 6011.01 | H16: 231.19 | I16: 77.06 | J16: 308.26 | K16: 231.19 | L16: 847.71 | M16: 693.58 | N16: =SUM(G16:M16) -> 8400
A17: 11 | B17: 030502003003 | C17: 弱电设备箱 | D17: 1.名称:弱电设备箱 2.规格:600x800x200 3.其它:满足完成此项工作所需要的全部工作内容，包括设计图纸、技术规范书、答疑、招标文件、现行规范、图集、验收等全部要求 | E17: 个 | F17: 5 | G17: 963.3 | H17: 80.28 | I17: 32.11 | J17: 240.83 | K17: 112.39 | L17: 176.61 | M17: 144.5 | N17: =SUM(G17:M17) -> 1750.02
A18: 本页小计 | N18: =SUM(N15:N17) -> 35350.02
A19: 12 | B19: 030904008005 | C19: 摄像机防雷模块 | D19: 1.名称:摄像机防雷模块 2.规格:In=10KA Imax=20KA 静态门槛电压 1.5Un 动态电压 2Un 插入损耗 ＜0.2dB 传输速率 10Mbps 响应时间 ＜1ns 3.其它:满足完成此项工作所需要的全部工作内容，包括设计图纸、技术规范书、答疑、招标文件、现行规范、图集、验收等全部要求 | E19: 个 | F19: 56 | G19: 7413.58 | H19: 285.14 | I19: 95.05 | J19: 380.18 | K19: 285.14 | L19: 1045.5 | M19: 855.41 | N19: =SUM(G19:M19) -> 10360
A20: 13 | B20: 030502007007 | C20: 12芯单模光缆 | D20: 1.名称：12芯单模光缆 2.敷设方式：桥架敷设 3.其它:满足完成此项工作所需要的全部工作内容，包括设计图纸、技术规范书、答疑、招标文件、现行规范、图集、验收等全部要求 | E20: m | F20: 4756.07 | G20: 13613.7 | H20: 523.6 | I20: 174.53 | J20: 698.14 | K20: 523.6 | L20: 1919.88 | M20: 1570.81 | N20: =SUM(G20:M20) -> 19024.26
A21: 14 | B21: 030502014001 | C21: 光纤连接 | D21: 1.名称：单模光纤熔接 2.其它:满足完成此项工作所需要的全部工作内容，包括设计图纸、技术规范书、答疑、招标文件、现行规范、图集、验收等全部要求 | E21: 芯 | F21: 480 | G21: 5152.29 | H21: 198.17 | I21: 66.06 | J21: 264.22 | K21: 198.17 | L21: 726.61 | M21: 594.5 | N21: =SUM(G21:M21) -> 7200.02
A22: 15 | B22: 030411003011 | C22: 桥架 | D22: 1.名称：弱电热镀锌桥架 2.规格：400*100 3.其它:满足完成此项工作所需要的全部工作内容，包括设计图纸、技术规范书、答疑、招标文件、现行规范、图集、验收等全部要求 | E22: m | F22: 1433.39 | G22: 49234.97 | H22: 1893.65 | I22: 631.22 | J22: 2524.87 | K22: 1893.65 | L22: 6943.39 | M22: 5680.96 | N22: =SUM(G22:M22) -> 68802.71
A23: 本页小计 | N23: =SUM(N19:N22) -> 105386.99
A24: 16 | B24: 030411003012 | C24: 桥架 | D24: 1.名称：弱电热镀锌桥架 2.规格：300*100 3.其它:满足完成此项工作所需要的全部工作内容，包括设计图纸、技术规范书、答疑、招标文件、现行规范、图集、验收等全部要求 | E24: m | F24: 63.67 | G24: 2050.29 | H24: 78.86 | I24: 26.29 | J24: 105.14 | K24: 78.86 | L24: 289.14 | M24: 236.57 | N24: =SUM(G24:M24) -> 2865.15
A25: 17 | B25: 030411003013 | C25: 桥架 | D25: 1.名称：弱电热镀锌桥架 2.规格：200*100 3.其它:满足完成此项工作所需要的全部工作内容，包括设计图纸、技术规范书、答疑、招标文件、现行规范、图集、验收等全部要求 | E25: m | F25: 1240.94 | G25: 33744.46 | H25: 1297.86 | I25: 432.62 | J25: 1730.49 | K25: 1297.86 | L25: 4758.83 | M25: 3893.59 | N25: =SUM(G25:M25) -> 47155.71
A26: 18 | B26: 030411003014 | C26: 桥架 | D26: 1.名称：弱电热镀锌桥架 2.规格：100*100 3.其它:满足完成此项工作所需要的全部工作内容，包括设计图纸、技术规范书、答疑、招标文件、现行规范、图集、验收等全部要求 | E26: m | F26: 64.94 | G26: 1301.18 | H26: 50.05 | I26: 16.68 | J26: 66.73 | K26: 50.05 | L26: 183.5 | M26: 150.14 | N26: =SUM(G26:M26) -> 1818.33
A27: 19 | B27: 030411003015 | C27: 桥架 | D27: 1.名称：弱电热镀锌桥架 2.规格：600*80 3.其它:满足完成此项工作所需要的全部工作内容，包括设计图纸、技术规范书、答疑、招标文件、现行规范、图集、验收等全部要求 | E27: m | F27: 78.59 | G27: 2699.46 | H27: 103.83 | I27: 34.61 | J27: 138.43 | K27: 103.83 | L27: 380.69 | M27: 311.48 | N27: =SUM(G27:M27) -> 3772.33
A28: 20 | B28: 030411003016 | C28: 桥架 | D28: 1.名称：弱电热镀锌桥架 2.规格：400*80 3.其它:满足完成此项工作所需要的全部工作内容，包括设计图纸、技术规范书、答疑、招标文件、现行规范、图集、验收等全部要求 | E28: m | F28: 191.89 | G28: 6591.16 | H28: 253.51 | I28: 84.5 | J28: 338.01 | K28: 253.51 | L28: 929.52 | M28: 760.52 | N28: =SUM(G28:M28) -> 9210.73
A29: 本页小计 | N29: =SUM(N24:N28) -> 64822.25
A30: 21 | B30: 030411003017 | C30: 桥架 | D30: 1.名称：弱电热镀锌桥架 2.规格：200*80 3.其它:满足完成此项工作所需要的全部工作内容，包括设计图纸、技术规范书、答疑、招标文件、现行规范、图集、验收等全部要求 | E30: m | F30: 636.77 | G30: 12758.77 | H30: 490.72 | I30: 163.57 | J30: 654.3 | K30: 490.72 | L30: 1799.31 | M30: 1472.17 | N30: =SUM(G30:M30) -> 17829.56
A31: 22 | B31: 030411003018 | C31: 桥架 | D31: 1.名称：弱电热镀锌桥架 2.规格：100*80 3.其它:满足完成此项工作所需要的全部工作内容，包括设计图纸、技术规范书、答疑、招标文件、现行规范、图集、验收等全部要求 | E31: m | F31: 387.65 | G31: 7212.42 | H31: 277.4 | I31: 92.47 | J31: 369.87 | K31: 277.4 | L31: 1017.14 | M31: 832.2 | N31: =SUM(G31:M31) -> 10078.9
A32: 23 | B32: 030413001026 | C32: 铁构件 | D32: 1.名称:桥架等支吊架制作与安装 2.规格:综合 3.材质：热镀锌 4.其它:满足完成此项工作所需要的全部工作内容，包括设计图纸、技术规范书、答疑、招标文件、现行规范、图集、验收等全部要求 | E32: kg | F32: 4240.1 | G32: 19216.6 | H32: 5057 | I32: 2528.5 | J32: 14159.6 | K32: 4045.6 | L32: 5562.7 | M32: 4551.3 | N32: =SUM(G32:M32) -> 55121.3
A33: 24 | B33: 030411001047 | C33: 配管 | D33: 1.名称：紧定式镀锌钢导管 2.规格：JDG20 3.敷设方式：明配 4.其它:满足完成此项工作所需要的全部工作内容，包括设计图纸、技术规范书、答疑、招标文件、现行规范、图集、验收等全部要求 | E33: m | F33: 1679.89 | G33: 2635.42 | H33: 693.53 | I33: 346.77 | J33: 1941.89 | K33: 554.83 | L33: 762.89 | M33: 624.18 | N33: =SUM(G33:M33) -> 7559.51
A34: 本页小计 | N34: =SUM(N30:N33) -> 90589.27
A35: 25 | B35: 030411001048 | C35: 配管 | D35: 1.名称：紧定式镀锌钢导管 2.规格：JDG20 3.敷设方式：暗配 4.其它:满足完成此项工作所需要的全部工作内容，包括设计图纸、技术规范书、答疑、招标文件、现行规范、图集、验收等全部要求 | E35: m | F35: 248.85 | G35: 390.4 | H35: 102.74 | I35: 51.37 | J35: 287.66 | K35: 82.19 | L35: 113.01 | M35: 92.46 | N35: =SUM(G35:M35) -> 1119.83
A36: 26 | B36: 030411001049 | C36: 配管 | D36: 1.名称：可挠金属套管 2.规格：DN20 3.敷设方式：明配 4.其它:满足完成此项工作所需要的全部工作内容，包括设计图纸、技术规范书、答疑、招标文件、现行规范、图集、验收等全部要求 | E36: m | F36: 155.05 | G36: 243.24 | H36: 64.01 | I36: 32.01 | J36: 179.23 | K36: 51.21 | L36: 70.41 | M36: 57.61 | N36: =SUM(G36:M36) -> 697.72
A37: 27 | B37: 030413002013 | C37: 凿（压)槽 | D37: 1.名称:管线剔槽及恢复 2.满足完成此项工作所需要的全部工作内容，满足设计图纸、答疑、招标文件、现行规范、图集、验收等全部要求 | E37: m | F37: 150 | G37: 577.98 | H37: 48.17 | I37: 19.27 | J37: 144.5 | K37: 67.43 | L37: 105.96 | M37: 86.7 | N37: =SUM(G37:M37) -> 1050.01
A38: 28 | B38: 030413001027 | C38: 管道支架/综合支架 | D38: 1.名称:管道支架制作安装 2.材质:热镀锌 3.安装高度:综合考虑 4.满足完成此项工作所需要的全部工作内容，满足设计图纸、技术规范书、答疑、招标文件、现行规范、图集、验收等全部要求 | E38: kg | F38: 461.99 | G38: 773.09 | H38: 203.45 | I38: 101.72 | J38: 569.65 | K38: 162.76 | L38: 223.79 | M38: 183.1 | N38: =SUM(G38:M38) -> 2217.56
A39: 29 | B39: 030502005008 | C39: 双绞线缆 | D39: 1.名称：六类网线 2.规格： Cat.6 UTP 3.敷设方式：桥架敷设 4.其它:满足完成此项工作所需要的全部工作内容，包括设计图纸、技术规范书、答疑、招标文件、现行规范、图集、验收等全部要求 | E39: m | F39: 31930.62 | G39: 33395.33 | H39: 8788.24 | I39: 4394.12 | J39: 24607.08 | K39: 7030.6 | L39: 9667.07 | M39: 7909.42 | N39: =SUM(G39:M39) -> 95791.86
A40: 本页小计 | N40: =SUM(N35:N39) -> 100876.98
...

Sheet 8#、15#非管区巡更系统
A1: 分部分项工程和单价措施项目清单与计价表
A2: 分部分项工程和单价措施项目清单与计价表
A3: 序号 | B3: 项目编码 | C3: 项目名称 | D3: 项目特征描述 | E3: 计量单位 | F3: 工程量 | G3: 金额（元）
G4: 主材/设备费 | H4: 辅材 | I4: 机械措施 | J4: 人工 | K4: 管理费 | L4: 利润 | M4: 税金 | N4: 总价
A5: 1 | B5: 030507005007 | C5: 巡逻终端 | D5: 1.名称:巡逻终端（含数据采集底座、充电器、巡更软件等） 2.其它:满足完成此项工作所需要的全部工作内容，包括设计图纸、技术规范书、答疑、招标文件、现行规范、图集、验收等全部要求 | E5: 台 | F5: 10 | G5: 9660.54 | H5: 371.55 | I5: 123.84 | J5: 495.42 | K5: 371.55 | L5: 1362.39 | M5: 1114.68 | N5: =SUM(G5:M5) -> 13499.97
A6: 2 | B6: 03B031 | C6: 巡更标签 | D6: 1.名称:巡更标签 2.其它:满足完成此项工作所需要的全部工作内容，包括设计图纸、技术规范书、答疑、招标文件、现行规范、图集、验收等全部要求 | E6: 张 | F6: 1000 | G6: 21467.88 | H6: 825.69 | I6: 275.22 | J6: 1100.91 | K6: 825.69 | L6: 3027.51 | M6: 2477.07 | N6: =SUM(G6:M6) -> 29999.97
A7: 3 | B7: 030507017005 | C7: 安全防范分系统调试 | D7: 1.名称：电子巡更系统调试 2.其它:满足完成此项工作所需要的全部工作内容，包括设计图纸、技术规范书、答疑、招标文件、现行规范、图集、验收等全部要求 | E7: 系统 | F7: 1 | G7: 522.93 | H7: 137.61 | I7: 68.82 | J7: 385.32 | K7: 110.1 | L7: 151.38 | M7: 123.84 | N7: =SUM(G7:M7) -> 1500
A8: 4 | B8: 03B032 | C8: 系统综合及集成 | D8: 1.清单未列项、图纸中未表示或技术规格书未做要求，但为了实现本系统各项功能必须增加的配套及辅助的材料、设备的所有工作内容及费用； 2.施工深化设计增加的实现本系统设计功能必要的配套及辅助的材料、设备所需的所有工作内容及费用； 3.实现设计功能所做的满足图纸、技术规格书要求的各项综合与集成，包括不限于各项检测、试验、调试、软件开发、联动等所有工作内容及费用 | E8: 项 | F8: 1 | G8: 836.7 | H8: 220.17 | I8: 110.1 | J8: 616.5 | K8: 176.16 | L8: 242.19 | M8: 198.18 | N8: =SUM(G8:M8) -> 2400
A9: 本页小计 | N9: =SUM(N5:N8) -> 47399.94
